Workbook

Sheet Productos
A1: Producto | B1: Cantidad | C1: Cantidad de entrega | D1: Cantidad Facturada | E1: Cantidad a facturar | F1: Unidad | G1: Precio unitario | H1: Total de impuestos | I1: Subtotal
A2: Servilleta con bordado 5cm | B2: 5 | C2: 0 | D2: 0 | E2: 0 | F2: Unidades | G2: 34.69 | H2: 36.42 | I2: 173.45
A3: Servilleta con bordado 5cm | B3: 10 | C3: 10 | D3: 0 | E3: 10 | F3: Unidades | G3: 4 | H3: 8.4 | I3: 40
A4: Servilleta con bordado 5cm | B4: 10 | C4: 0 | D4: 0 | E4: 10 | F4: Unidades | G4: 4 | H4: 8.4 | I4: 40
A5: Servilleta con bordado 5cm | B5: 10 | C5: 0 | D5: 0 | E5: 10 | F5: Unidades | G5: 4 | H5: 8.4 | I5: 40
A6: Servilleta con bordado 5cm | B6: 10 | C6: 0 | D6: 0 | E6: 10 | F6: Unidades | G6: 4 | H6: 8.4 | I6: 40
A7: Servilleta con bordado 5cm | B7: 10 | C7: 0 | D7: 0 | E7: 10 | F7: Unidades | G7: 4 | H7: 8.4 | I7: 40
A8: Servilleta con bordado 5cm | B8: 10 | C8: 0 | D8: 0 | E8: 10 | F8: Unidades | G8: 4 | H8: 8.4 | I8: 40
A9: Servilleta con bordado 5cm | B9: 10 | C9: 0 | D9: 0 | E9: 10 | F9: Unidades | G9: 4 | H9: 8.4 | I9: 40
A10: Servilleta con bordado 5cm | B10: 10 | C10: 0 | D10: 0 | E10: 10 | F10: Unidades | G10: 4 | H10: 8.4 | I10: 40
A11: Servilleta con bordado 5cm | B11: 10 | C11: 0 | D11: 0 | E11: 10 | F11: Unidades | G11: 4 | H11: 8.4 | I11: 40
A12: Servilleta con bordado 5cm | B12: 12 | C12: 0 | D12: 0 | E12: 12 | F12: Unidades | G12: 4 | H12: 10.08 | I12: 48
A13: Servilleta con bordado 5cm | B13: 10 | C13: 0 | D13: 0 | E13: 10 | F13: Unidades | G13: 4 | H13: 8.4 | I13: 40
... A38: [MESA-001] Camino de mesa | B38: 0 | C38: 0 | D38: 0 | E38: 0 | F38: Unidades | G38: 1 | H38: 0 | I38: 0

Sheet PRESUPUESTO
A1: Producto | B1: Cantidad | C1: Cantidad de entrega | D1: Cantidad Facturada | E1: Cantidad a facturar | F1: Unidad | G1: Precio unitario | H1: Total de impuestos | I1: Subtotal | J1: Mesa | K1: Tejido | L1: Color | M1: Medida De Uso | N1: Dobladillo | O1: Medida de corte
A2: Servilleta con bordado 5cm | B2: 5 | C2: 0 | D2: 0 | E2: 0 | F2: Unidades | G2: 34.69 | H2: 36.42 | I2: 173.45 | J2: 90*80*75 | K2: Saten Liso Nacional | L2: 1 | M2: 230 * 230 PR | N2: 1.5 | O2: 241 * 244
A3: Servilleta con bordado 5cm | B3: 10 | C3: 10 | D3: 0 | E3: 10 | F3: Unidades | G3: 4 | H3: 8.4 | I3: 40 | AP3: PRESUPUESTO: | AR3: 110125
A4: Servilleta con bordado 5cm | B4: 10 | C4: 0 | D4: 0 | E4: 10 | F4: Unidades | G4: 4 | H4: 8.4 | I4: 40 | AP4: CLIENTE: | AR4: Hotel de Las Palmeras
A5: Servilleta con bordado 5cm | B5: 10 | C5: 0 | D5: 0 | E5: 10 | F5: Unidades | G5: 4 | H5: 8.4 | I5: 40 | AP5: Con Fecha: | AR5: 46155 | AT5: COMERCIAL: | AU5: Diego
A6: Servilleta con bordado 5cm | B6: 10 | C6: 0 | D6: 0 | E6: 10 | F6: Unidades | G6: 4 | H6: 8.4 | I6: 40 | AP6: Validez hasta: | AR6: 46165 | AT6: REFERENCIA:
A7: Servilleta con bordado 5cm | B7: 10 | C7: 0 | D7: 0 | E7: 10 | F7: Unidades | G7: 4 | H7: 8.4 | I7: 40
A8: Servilleta con bordado 5cm | B8: 10 | C8: 0 | D8: 0 | E8: 10 | F8: Unidades | G8: 4 | H8: 8.4 | I8: 40 | S8: MEDIDA TERMINADA | V8: DOBLADILLO | W8: MEDIDA CON DOBLAD. | Y8: ENCOG. (1/0) | Z8: MEDIDA CORTE | AB8: REDONDO (1/2) | AC8: EMPALME | AD8: REF. EMPALME | AE8: NUM. EMPALM | AF8: NUM. EMPALM. | AG8: CONFECCIÓN | AH8: COBRA SOBRANTE | AI8: TEJIDO | AJ8: FESTÓN (1/2) | AK8: PRECIO | AL8: COLOR | AM8: PICOS REDOND
A9: Servilleta con bordado 5cm | B9: 10 | C9: 0 | D9: 0 | E9: 10 | F9: Unidades | G9: 4 | H9: 8.4 | I9: 40 | P9: ALTO DE LA MESA | Q9: AÑADIR LARGO | R9: CAIDA MANTEL | S9: MEDIDA MESA | T9: ANCHO | U9: LARGO | V9: (1) Sencillo o Medida | W9: ANCHO | X9: LARGO | Y9: (1) Si (0) No | Z9: ANCHO | AA9: LARGO | AB9: (1) Si (2) No | AC9: (1) Si (2) No | AF9: SOLO SIN SON MENOS | AH9: (1) Si (2) No | AJ9: (1) Si (2) No | AK9: FESTÓN | AL9: FESTÓN | AM9: (1) Si (2) No | AP9: CINTA | AQ9: MESA | AR9: ARTICULO | AS9: MEDIDA USO | AT9: DESCRIPCION ARTICULO | AU9: COLOR | AV9: DOBLADILLO | AX9: MEDIDA DE CORTE | AY9: PRECIO UNITARIO | AZ9: CANTIDAD | BA9: TOTAL
A10: Servilleta con bordado 5cm | B10: 10 | C10: 0 | D10: 0 | E10: 10 | F10: Unidades | G10: 4 | H10: 8.4 | I10: 40 | P10: 0 | Q10: 0 | T10: 0 | U10: 0 | W10: 0 | X10: 0 | Y10: 0 | Z10: 0 | AA10: 0 | AB10: 2 | AG10: #N/D | AI10: #N/D | AJ10: 2 | AK10: 0 | AM10: 2
A11: Servilleta con bordado 5cm | B11: 10 | C11: 0 | D11: 0 | E11: 10 | F11: Unidades | G11: 4 | H11: 8.4 | I11: 40 | P11: 75 | Q11: 0 | S11: 80*80*75 | T11: 230 | U11: 230 | V11: 1.5 | W11: 236 | X11: 236 | Y11: 1 | Z11: 241 | AA11: 244 | AB11: 2 | AG11: 2.24 | AI11: 32.45 | AJ11: 2 | AK11: 0 | AM11: 1 | AQ11: 80*80*75 | AR11: Mantel | AS11: 230 * 230 PR | AT11: Saten Liso Nacional | AU11: c/ 1 Blanco | AV11: Dobl. 1,5 cm. | AW11: SI | AX11: 241 * 244 | AY11: 34.69 | AZ11: 1 | BA11: 34.69
A12: Servilleta con bordado 5cm | B12: 12 | C12: 0 | D12: 0 | E12: 12 | F12: Unidades | G12: 4 | H12: 10.08 | I12: 48 | P12: 25 | Q12: 0 | S12: 80*80*25 | T12: 130 | U12: 130 | V12: 1.5 | W12: 136 | X12: 136 | Y12: 1 | Z12: 139 | AA12: 140 | AB12: 2 | AG12: 1.49 | AI12: 17.78 | AJ12: 2 | AK12: 0 | AM12: 2 | AQ12: 80*80*25 | AR12: Cubre | AS12: 130 * 130 | AT12: Fenicia | AU12: c/ 1 Todos los colores | AV12: Dobl. 1,5 cm. | AW12: SI | AX12: 139 * 140 | AY12: 19.27 | AZ12: 1 | BA12: 19.27
A13: Servilleta con bordado 5cm | B13: 10 | C13: 0 | D13: 0 | E13: 10 | F13: Unidades | G13: 4 | H13: 8.4 | I13: 40 | P13: 0 | Q13: 0 | T13: 40 | U13: 120 | V13: 1.5 | W13: 46 | X13: 126 | Y13: 1 | Z13: 46 | AA13: 126 | AB13: 2 | AG13: 1.08 | AI13: 7.18 | AJ13: 2 | AK13: 0 | AM13: 2 | AR13: Camino de mesa | AS13: 40 * 120 | AT13: Baroja | AU13: c/ 1 Crudo | AV13: Dobl. 1,5 cm. | AW13: SI | AX13: 46 * 126 | AY13: 8.26 | AZ13: 1 | BA13: 8.26
A14: Servilleta con bordado 5cm | B14: 10 | C14: 10 | D14: 0 | E14: 10 | F14: Unidades | G14: 4 | H14: 8.4 | I14: 40 | P14: 75 | Q14: 0 | S14: (/)180*75 | T14: 330 | U14: 330 | V14: 1.5 | W14: 336 | X14: 336 | Y14: 1 | Z14: 336 | AA14: 336 | AB14: 1 | AC14: 1 | AD14: 325336 | AE14: 10 | AG14: 8.94 | AI14: 67.17 | AJ14: 2 | AK14: 0 | AM14: 2 | AQ14: (/)180*75 | AR14: Mantel | AS14: 330 * 330 | AT14: Saten Pes100 | AU14: c/ 2 Palido | AV14: Dobl. 1,5 cm. | AW14: SI | AX14: Redondo 336 * 336 | AY14: 76.11 | AZ14: 1 | BA14: 76.11
A15: Servilleta con bordado 5cm | B15: 10 | C15: 0 | D15: 0 | E15: 10 | F15: Unidades | G15: 4 | H15: 8.4 | I15: 40 | P15: 0 | Q15: 0 | T15: 50 | U15: 50 | V15: 2 | W15: 58 | X15: 58 | Y15: 1 | Z15: 60 | AA15: 60 | AB15: 2 | AG15: 0.75 | AI15: 1.6 | AJ15: 2 | AK15: 0 | AM15: 2 | AR15: Servilleta | AS15: 50 * 50 | AT15: Saten Liso Nacional | AU15: c/ 1 Blanco | AV15: Dobl. 2 cm. | AW15: SI | AX15: 60 * 60 | AY15: 2.35 | AZ15: 1 | BA15: 2.35
A16: Servilleta con bordado 5cm | B16: 10 | C16: 0 | D16: 0 | E16: 10 | F16: Unidades | G16: 4 | H16: 8.4 | I16: 40 | P16: 0 | Q16: 0 | T16: 50 | U16: 50 | V16: 2 | W16: 58 | X16: 58 | Y16: 1 | Z16: 60 | AA16: 60 | AB16: 2 | AG16: 0.75 | AI16: 2.2 | AJ16: 1 | AK16: 1.8 | AL16: Blanco | AM16: 2 | AR16: Servilleta | AS16: 50 * 50 | AT16: Saten Liso Nacional | AU16: c/ 58 Azul | AV16: Dobl. 2 cm. | AW16: SI | AX16: 60 * 60 | AY16: 4.75 | AZ16: 1 | BA16: 4.75
A17: Servilleta con bordado 5cm | B17: 10 | C17: 0 | D17: 0 | E17: 10 | F17: Unidades | G17: 4 | H17: 8.4 | I17: 40 | P17: 0 | Q17: 0 | T17: 80 | U17: 80 | V17: 3 | W17: 92 | X17: 92 | Y17: 1 | Z17: 92 | AA17: 92 | AB17: 2 | AG17: 1.12 | AI17: 5.76 | AJ17: 2 | AK17: 0 | AM17: 2 | AR17: Muleton | AS17: 80 * 80 | AT17: Muleton | AU17: c/ 1 Blanco | AV17: Dobl. 3 cm. | AW17: SI | AX17: 92 * 92 | AY17: 6.88 | AZ17: 1 | BA17: 6.88
A18: Servilleta con bordado 5cm | B18: 10 | C18: 0 | D18: 0 | E18: 10 | F18: Unidades | G18: 4 | H18: 8.4 | I18: 40 | P18: 0 | Q18: 0 | T18: 45 | U18: 70 | V18: 1 | W18: 50 | X18: 75 | Y18: 1 | Z18: 51 | AA18: 78 | AB18: 2 | AG18: 0.56 | AI18: 1.73 | AJ18: 2 | AK18: 0 | AM18: 2 | AR18: Lito | AS18: 45 * 70 | AT18: Saten Liso Nacional | AU18: c/ 1 Blanco | AV18: Dobl. Sencillo | AW18: SI | AX18: 51 * 78 | AY18: 2.29 | AZ18: 1 | BA18: 2.29
A19: Servilleta con bordado 5cm | B19: 10 | C19: 0 | D19: 0 | E19: 10 | F19: Unidades | G19: 4 | H19: 8.4 | I19: 40 | P19: 0 | Q19: 0 | T19: 35 | U19: 50 | V19: 6 | W19: 59 | X19: 74 | Y19: 1 | Z19: 61 | AA19: 77 | AB19: 2 | AG19: 1.12 | AI19: 2.05 | AJ19: 1 | AK19: 2.07 | AL19: Crudo | AM19: 2 | AR19: Individual | AS19: 35 * 50 | AT19: Saten Liso Nacional | AU19: c/ 1 Blanco | AV19: Dobl. 6 cm. | AW19: SI | AX19: 61 * 77 | AY19: 5.24 | AZ19: 1 | BA19: 5.24
A20: Servilleta con bordado 5cm | B20: 10 | C20: 0 | D20: 0 | E20: 10 | F20: Unidades | G20: 4 | H20: 8.4 | I20: 40 | P20: 0 | Q20: 0 | T20: 0 | U20: 0 | W20: 0 | X20: 0 | Y20: 0 | Z20: 0 | AA20: 0 | AB20: 2 | AG20: #N/D | AI20: #N/D | AJ20: 2 | AK20: 0 | AM20: 2 | AZ20: TOTAL | BA20: {=SUM(BA10:BA19)}
A21: Servilleta con bordado 5cm | B21: 1 | C21: 0 | D21: 0 | E21: 1 | F21: Unidades | G21: 10 | H21: 2.1 | I21: 10 | P21: 0 | Q21: 0 | T21: 0 | U21: 0 | W21: 0 | X21: 0 | Y21: 0 | Z21: 0 | AA21: 0 | AB21: 2 | AG21: #N/D | AI21: #N/D | AJ21: 2 | AK21: 0 | AM21: 2
A22: Mantel (Blanco) | B22: 5 | C22: 0 | D22: 0 | E22: 0 | F22: Unidades | G22: 34.69 | H22: 36.42 | I22: 173.45 | J22: 80*80*75 | K22: Saten Liso Nacional | L22: 1 | M22: 230 * 230 PR | N22: 1.5 | O22: 241 * 244 | P22: 0 | Q22: 0 | T22: 0 | U22: 0 | W22: 0 | X22: 0 | Y22: 0 | Z22: 0 | AA22: 0 | AB22: 2 | AG22: #N/D | AI22: #N/D | AJ22: 2 | AK22: 0 | AM22: 2
A23: Cubre 3 | B23: 10 | C23: 0 | D23: 0 | E23: 0 | F23: Unidades | G23: 19.28 | H23: 40.49 | I23: 192.8 | J23: 80*80*25 | K23: Fenicia | L23: 1 | M23: 130 * 130 | N23: 1.5 | O23: 139 * 140 | P23: 0 | Q23: 0 | T23: 0 | U23: 0 | W23: 0 | X23: 0 | Y23: 0 | Z23: 0 | AA23: 0 | AB23: 2 | AG23: #N/D | AI23: #N/D | AJ23: 2 | AK23: 0 | AM23: 2
A24: Cubre 2 | B24: 5 | C24: 0 | D24: 0 | E24: 0 | F24: Unidades | G24: 8.26 | H24: 8.67 | I24: 41.3 | K24: Baroja | L24: 1 | M24: 40 * 120 | N24: 1.5 | O24: 46 * 126 | P24: 0 | Q24: 0 | T24: 0 | U24: 0 | W24: 0 | X24: 0 | Y24: 0 | Z24: 0 | AA24: 0 | AB24: 2 | AG24: #N/D | AI24: #N/D | AJ24: 2 | AK24: 0 | AM24: 2
A25: Cubre 2 | B25: 5 | C25: 0 | D25: 0 | E25: 0 | F25: Unidades | G25: 34.69 | H25: 36.42 | I25: 173.45 | J25: 80*80*75 | K25: Saten Liso Nacional | L25: 1 | M25: 230 * 230 PR | N25: 1.5 | O25: 241 * 244 | P25: 0 | Q25: 0 | T25: 0 | U25: 0 | W25: 0 | X25: 0 | Y25: 0 | Z25: 0 | AA25: 0 | AB25: 2 | AG25: #N/D | AI25: #N/D | AJ25: 2 | AK25: 0 | AM25: 2
A26: Mantel (Blanco) | B26: 10 | C26: 0 | D26: 0 | E26: 0 | F26: Unidades | G26: 19.28 | H26: 40.49 | I26: 192.8 | J26: 80*80*25 | K26: Fenicia | L26: 1 | M26: 130 * 130 | N26: 1.5 | O26: 139 * 140 | P26: 0 | Q26: 0 | T26: 0 | U26: 0 | W26: 0 | X26: 0 | Y26: 0 | Z26: 0 | AA26: 0 | AB26: 2 | AG26: #N/D | AI26: #N/D | AJ26: 2 | AK26: 0 | AM26: 2
A27: Mantel (Blanco) | B27: 3 | C27: 0 | D27: 0 | E27: 0 | F27: Unidades | G27: 34.87 | H27: 21.97 | I27: 104.61 | J27: 80*80*75 | K27: Saten Liso Nacional | L27: 1 | M27: 230 * 230 PR | N27: 1.5 | O27: 251 * 244 | P27: 0 | Q27: 0 | T27: 0 | U27: 0 | W27: 0 | X27: 0 | Y27: 0 | Z27: 0 | AA27: 0 | AB27: 2 | AG27: #N/D | AI27: #N/D | AJ27: 2 | AK27: 0 | AM27: 2
A28: Cubre Sub | B28: 5 | C28: 0 | D28: 0 | E28: 0 | F28: Unidades | G28: 19.28 | H28: 20.24 | I28: 96.4 | J28: 80*80*25 | K28: Fenicia | L28: 1 | M28: 130 * 130 | N28: 1.5 | O28: 139 * 140 | P28: 0 | Q28: 0 | T28: 0 | U28: 0 | W28: 0 | X28: 0 | Y28: 0 | Z28: 0 | AA28: 0 | AB28: 2 | AG28: #N/D | AI28: #N/D | AJ28: 2 | AK28: 0 | AM28: 2
A29: [MESA-001] Camino de mesa | B29: 0 | C29: 0 | D29: 0 | E29: 0 | F29: Unidades | G29: 8.26 | H29: 0 | I29: 0 | K29: Baroja | L29: 1 | M29: 40 * 120 | N29: 1.5 | O29: 46 * 126 | P29: 0 | Q29: 0 | T29: 0 | U29: 0 | W29: 0 | X29: 0 | Y29: 0 | Z29: 0 | AA29: 0 | AB29: 2 | AG29: #N/D | AI29: #N/D | AJ29: 2 | AK29: 0 | AM29: 2
A30: Mantel (Palido) | B30: 0 | C30: 0 | D30: 0 | E30: 0 | F30: Unidades | G30: 71.37 | H30: 0 | I30: 0 | J30: (/)180*75 | K30: Saten Pes100 | L30: 2 | M30: 330 * 330 | N30: 1.5 | O30: 336 * 336 | AX30: TOTAL PRESUPUESTO | BA30: 159.84
A31: Servilleta (Blanco) | B31: 0 | C31: 0 | D31: 0 | E31: 0 | F31: Unidades | G31: 2.72 | H31: 0 | I31: 0 | K31: Saten Liso Nacional | L31: 1 | M31: 50 * 50 | N31: 2 | O31: 58 * 60
AP32: Todas las prendas, seran identificadas con etiquerta color, según medida.
AP33: Estos precios no incluyen I.V.A.
AP34: Considerado encogimiento.
AP35: Confección a Capet
AP36: F. Pago : 50% a la aceptacion de presupuesto.
AP37: Resto a la entrega de mercancia
AP38: La cantidad de prendas, puede variar en un + - 10%

Sheet COLORES
A1: FILA | B1: REF. 1 | C1: REF. 2 | D1: Artículo | E1: REF. 3 | F1: COLOR | H1: COSTE | I1: ANCHO | J1: COMPOSICION
A2: 1 | B2: 1 | C2: 1TVR | D2: Saten 50/50 | E2: 1TVR1 | F2: 1 | G2: Blanco | H2: 8.41 | I2: 3.2 | J2: 50% Alg./50%Pes.
A3: 2 | B3: 1 | C3: 1TVR | D3: Saten 50/50 | E3: 1TVR2 | F3: 2 | G3: Palido | H3: 11.06 | I3: 3.2 | J3: 50% Alg./50%Pes.
A4: 3 | B4: 1 | C4: 1TVR | D4: Saten 50/50 | E4: 1TVR3 | F4: 3 | G4: Medio | H4: 12.2 | I4: 3.2 | J4: 50% Alg./50%Pes.
A5: 4 | B5: 1 | C5: 1TVR | D5: Saten 50/50 | E5: 1TVR4 | F5: 4 | G5: Intenso | H5: 13.46 | I5: 3.2 | J5: 50% Alg./50%Pes.
A6: 5 | B6: 1 | C6: 1TVR | D6: Saten 50/50 | E6: 1TVR5 | F6: 5 | G6: Intenso Especial | H6: 14.55 | I6: 3.2 | J6: 50% Alg./50%Pes.
A7: 6 | B7: 2 | C7: 2TVR | D7: Saten Pes100 | E7: 2TVR1 | F7: 1 | G7: Blanco | H7: 7.8 | I7: 3.25 | J7: 100% Poliester
A8: 7 | B8: 2 | C8: 2TVR | D8: Saten Pes100 | E8: 2TVR2 | F8: 2 | G8: Palido | H8: 9.29 | I8: 3.25 | J8: 100% Poliester
A9: 8 | B9: 2 | C9: 2TVR | D9: Saten Pes100 | E9: 2TVR3 | F9: 3 | G9: Medio | H9: 9.87 | I9: 3.25 | J9: 100% Poliester
A10: 9 | B10: 2 | C10: 2TVR | D10: Saten Pes100 | E10: 2TVR4 | F10: 4 | G10: Intenso | H10: 11.4 | I10: 3.25 | J10: 100% Poliester
A11: 10 | B11: 3 | C11: 3TVR | D11: Saten London | E11: 3TVR1 | F11: 1 | G11: Blanco | H11: 9.93 | I11: 3.4 | J11: 100% Poliester
A12: 11 | B12: 3 | C12: 3TVR | D12: Saten London | E12: 3TVR2 | F12: 2 | G12: Palido | H12: 11.29 | I12: 3.4 | J12: 100% Poliester
A13: 12 | B13: 3 | C13: 3TVR | D13: Saten London | E13: 3TVR3 | F13: 3 | G13: Medio | H13: 11.44 | I13: 3.4 | J13: 100% Poliester
... A44: 43 | B44: 36 | C44: 36GCU | D44: Saten Liso Poliester H | E44: 36GCU11 | F44: 11 | G44: Negro | H44: 8.3 | I44: 3.3 | J44: 100% Poliester
A45: 44 | B45: 19 | C45: 19GCU | D45: Saten Liso Nacional | E45: 19GCU53 | F45: 53 | H45: 8.71 | I45: 3.3 | J45: 50% Alg./50%Pes.
A46: 45 | B46: 19 | C46: 19GCU | D46: Saten Liso Nacional | E46: 19GCU59 | F46: 59 | H46: 8.86 | I46: 3.3 | J46: 50% Alg./50%Pes.
A47: 46 | B47: 28 | C47: 28YEB | D47: Fenicia | E47: 28YEB1 | F47: 1 | G47: Todos los colores | H47: 12.7 | I47: 2.8 | J47: 70%Visc./30% Lino
A48: 47 | B48: 17 | C48: 17GCU | D48: LinoPoliester | E48: 17GCU4 | F48: 4 | G48: Ocre | H48: 13.41 | I48: 3.3 | J48: 50% Lino/50%Pes.
A49: 48 | B49: 29 | C49: 29TVR | D49: Mahon | E49: 29TVR1 | F49: 1 | G49: Blanco | H49: 4.36 | I49: 2.8 | J49: 50% Alg./50%Pes.
A50: 49 | B50: 30 | C50: 30BTX | D50: Gouble | E50: 30BTX1 | F50: 1 | G50: Crudo | H50: 6.76 | I50: 2.8 | J50: 50% Alg./50%Pes.
A51: 50 | B51: 31 | C51: 31BTX | D51: Trivial | E51: 31BTX6 | F51: 6 | G51: Crudo | H51: 6.76 | I51: 2.8 | J51: 50% Alg./50%Pes.
A52: 51 | B52: 36 | C52: 36GCU | D52: Saten Liso Poliester H | E52: 36GCU1 | F52: 1 | G52: Blanco | H52: 5.96 | I52: 3.3 | J52: 100% Poliester
A53: 52 | B53: 19 | C53: 19GCU | D53: Saten Liso Nacional | E53: 19GCU69 | F53: 69 | G53: Cuerda | H53: 8.71 | I53: 3.3 | J53: 50% Alg./50%Pes.
A54: 53 | B54: 9 | C54: 9TVR | D54: Santorini | E54: 9TVR1 | F54: 1 | G54: Todos los colores | H54: 11.64 | I54: 3.5 | J54: 100% Poliester
A55: 54 | B55: 43 | C55: 43COM | D55: Aeris | E55: 43COM1 | F55: 1 | G55: Todos los colores | H55: 12.56 | I55: 2.8 | J55: 100% Poliester
A56: 55 | B56: 19 | C56: 19GCU | D56: Saten Liso Nacional | E56: 19GCU58 | F56: 58 | G56: Azul | H56: 9.16 | I56: 3.3 | J56: 50% Alg./50%Pes.
A57: 56 | B57: 17 | C57: 17GCU | D57: LinoPoliester | E57: 17GCU1 | F57: 1 | G57: Blanco | H57: 12.26 | I57: 3.3
A58: 57 | B58: 44 | C58: 44GRT | D58: Recy Line | E58: 44GRT1 | F58: 1 | G58: Blanco | H58: 10.82 | I58: 3.4 | J58: 50% Alg./50%Pes.
A59: 58 | B59: 44 | C59: 44GRT | D59: Recy Line | E59: 44GRT2 | F59: 2 | G59: Nature | H59: 11 | I59: 3.4 | J59: 50% Alg./50%Pes.
A60: 59 | B60: 44 | C60: 44GRT | D60: Recy Line | E60: 44GRT3 | F60: 3 | G60: Caliza | H60: 11.32 | I60: 3.4 | J60: 50% Alg./50%Pes.
A61: 60 | B61: 44 | C61: 44GRT | D61: Recy Line | E61: 44GRT4 | F61: 4 | G61: Gris Titanio | H61: 11.32 | I61: 3.4 | J61: 50% Alg./50%Pes.
A62: 61 | B62: 44 | C62: 44GRT | D62: Recy Line | E62: 44GRT5 | F62: 5 | G62: Salvaje | H62: 11.65 | I62: 3.4 | J62: 50% Alg./50%Pes.
A63: 62 | B63: 44 | C63: 44GRT | D63: Recy Line | E63: 44GRT6 | F63: 6 | G63: Gris Marengo | H63: 11.65 | I63: 3.4 | J63: 50% Alg./50%Pes.
A64: 63 | B64: 12 | C64: 12GRT | D64: Nilo Rustico | E64: 12GRT6 | F64: 6 | G64: Gris Marengo | H64: 17.35 | I64: 3.4 | J64: 50%Lin./50%Pes.
A65: 64 | B65: 12 | C65: 12GRT | D65: Nilo Rustico | E65: 12GRT5 | F65: 5 | G65: Salvaje | H65: 17.35 | I65: 3.4 | J65: 50%Lin./50%Pes.
A66: 65 | B66: 12 | C66: 12GRT | D66: Nilo Rustico | E66: 12GRT4 | F66: 4 | G66: Caliza | H66: 17.35 | I66: 3.4 | J66: 50%Lin./50%Pes.
A67: 66 | B67: 12 | C67: 12GRT | D67: Nilo Rustico | E67: 12GRT3 | F67: 3 | G67: Nature | H67: 17.35 | I67: 3.4 | J67: 50%Lin./50%Pes.
A68: 67 | B68: 12 | C68: 12GRT | D68: Nilo Rustico | E68: 12GRT2 | F68: 2 | G68: Blanco Quimico | H68: 16.53 | I68: 3.4 | J68: 50%Lin./50%Pes.
A69: 68 | B69: 12 | C69: 12GRT | D69: Nilo Rustico | E69: 12GRT1 | F69: 1 | G69: Blanco | H69: 16.53 | I69: 3.4 | J69: 50%Lin./50%Pes.
... A81: 80 | B81: 31 | C81: 31BTX | D81: Trivial | E81: 31BTX1 | F81: 1 | G81: Granate | H81: 8.7 | I81: 2.8 | J81: 62%CO 38%PES
...

Sheet CONFECCION
B1: METROS | C1: 0.5 | D1: 1 | E1: 1.5 | F1: 2 | G1: 2.5 | H1: 3 | I1: 3.5 | J1: 4 | K1: 4.5 | L1: 5 | M1: 5.5 | N1: 6 | O1: 6.5 | P1: 7
B2: 0.5 | C2: 0.37 | D2: 0.47 | E2: 0.56 | F2: 0.65 | G2: 0.75 | H2: 0.84 | I2: 0.93 | J2: 1.04 | K2: 1.12 | L2: 1.21 | M2: 1.3 | N2: 1.4 | O2: 1.49 | P2: 1.58
B3: 1 | C3: 0.47 | D3: 0.56 | E3: 0.65 | F3: 0.75 | G3: 0.84 | H3: 0.93 | I3: 1.04 | J3: 1.12 | K3: 1.21 | L3: 1.3 | M3: 1.4 | N3: 1.49 | O3: 1.58 | P3: 1.68
B4: 1.5 | C4: 0.56 | D4: 0.65 | E4: 0.75 | F4: 0.84 | G4: 0.93 | H4: 1.04 | I4: 1.12 | J4: 1.21 | K4: 1.3 | L4: 1.4 | M4: 1.49 | N4: 1.58 | O4: 1.68 | P4: 1.77
B5: 2 | C5: 0.65 | D5: 0.75 | E5: 0.84 | F5: 0.93 | G5: 1.04 | H5: 1.12 | I5: 1.21 | J5: 1.3 | K5: 1.4 | L5: 1.49 | M5: 1.58 | N5: 1.68 | O5: 1.77 | P5: 1.86
B6: 2.5 | C6: 0.75 | D6: 0.84 | E6: 0.93 | F6: 1.04 | G6: 1.12 | H6: 1.21 | I6: 1.3 | J6: 1.4 | K6: 1.49 | L6: 1.58 | M6: 1.68 | N6: 1.77 | O6: 1.86 | P6: 1.96
B7: 3 | C7: 0.84 | D7: 0.93 | E7: 1.04 | F7: 1.12 | G7: 1.21 | H7: 1.3 | I7: 1.4 | J7: 1.49 | K7: 1.58 | L7: 1.68 | M7: 1.77 | N7: 1.86 | O7: 1.96 | P7: 2.05
B8: 3.5 | C8: 0.93 | D8: 1.04 | E8: 1.12 | F8: 1.21 | G8: 1.3 | H8: 1.4 | I8: 1.49 | J8: 1.58 | K8: 1.68 | L8: 1.77 | M8: 1.86 | N8: 1.96 | O8: 2.05 | P8: 2.14
B9: 4 | C9: 1.04 | D9: 1.12 | E9: 1.21 | F9: 1.3 | G9: 1.4 | H9: 1.49 | I9: 1.58 | J9: 1.68 | K9: 1.77 | L9: 1.86 | M9: 1.96 | N9: 2.05 | O9: 2.14 | P9: 2.24
B12: Los precios de la confección con dobladillo a dos centímetros, son los anteriores multiplicados por dos
B14: Nº Fila | C14: 1 | D14: 50 | E14: 51 | F14: 100 | G14: 101 | H14: 150 | I14: 151 | J14: 200 | K14: 201 | L14: 250 | M14: 251 | N14: 300 | O14: 301 | P14: 350 | Q14: 351 | R14: 400 | S14: 401 | T14: 450 | U14: 451 | V14: 500 | W14: 501 | X14: 550 | Y14: 551 | Z14: 600 | AA14: 601 | AB14: 650 | AC14: 651 | AD14: 700
A15: 1 | B15: 18 | C15: 0.37 | D15: 0.37 | E15: 0.47 | F15: 0.47 | G15: 0.54 | H15: 0.56 | I15: 0.65 | J15: 0.65 | K15: 0.75 | L15: 0.75 | M15: 0.84 | N15: 0.84 | O15: 0.93 | P15: 0.93 | Q15: 1.04 | R15: 1.04 | S15: 1.12 | T15: 1.12 | U15: 1.21 | V15: 1.21 | W15: 1.3 | X15: 1.3 | Y15: 1.4 | Z15: 1.4 | AA15: 1.49 | AB15: 1.49 | AC15: 1.58 | AD15: 1.58
A16: 50 | B16: 19 | C16: 0.37 | D16: 0.37 | E16: 0.47 | F16: 0.47 | G16: 0.56 | H16: 0.56 | I16: 0.65 | J16: 0.65 | K16: 0.75 | L16: 0.75 | M16: 0.84 | N16: 0.84 | O16: 0.93 | P16: 0.93 | Q16: 1.04 | R16: 1.04 | S16: 1.12 | T16: 1.12 | U16: 1.21 | V16: 1.21 | W16: 1.3 | X16: 1.3 | Y16: 1.4 | Z16: 1.4 | AA16: 1.49 | AB16: 1.49 | AC16: 1.58 | AD16: 1.58
A17: 51 | B17: 20 | C17: 0.47 | D17: 0.47 | E17: 0.56 | F17: 0.56 | G17: 0.65 | H17: 0.65 | I17: 0.75 | J17: 0.75 | K17: 0.84 | L17: 0.84 | M17: 0.93 | N17: 0.93 | O17: 1.04 | P17: 1.04 | Q17: 1.12 | R17: 1.12 | S17: 1.21 | T17: 1.21 | U17: 1.3 | V17: 1.3 | W17: 1.4 | X17: 1.4 | Y17: 1.49 | Z17: 1.49 | AA17: 1.58 | AB17: 1.58 | AC17: 1.68 | AD17: 1.68
A18: 100 | B18: 21 | C18: 0.47 | D18: 0.47 | E18: 0.56 | F18: 0.56 | G18: 0.65 | H18: 0.65 | I18: 0.75 | J18: 0.75 | K18: 0.84 | L18: 0.84 | M18: 0.93 | N18: 0.93 | O18: 1.04 | P18: 1.04 | Q18: 1.12 | R18: 1.12 | S18: 1.21 | T18: 1.21 | U18: 1.3 | V18: 1.3 | W18: 1.4 | X18: 1.4 | Y18: 1.49 | Z18: 1.49 | AA18: 1.58 | AB18: 1.58 | AC18: 1.68 | AD18: 1.68
A19: 101 | B19: 22 | C19: 0.56 | D19: 0.56 | E19: 0.65 | F19: 0.65 | G19: 0.75 | H19: 0.75 | I19: 0.84 | J19: 0.84 | K19: 0.93 | L19: 0.93 | M19: 1.04 | N19: 1.04 | O19: 1.12 | P19: 1.12 | Q19: 1.21 | R19: 1.21 | S19: 1.3 | T19: 1.3 | U19: 1.4 | V19: 1.4 | W19: 1.49 | X19: 1.49 | Y19: 1.58 | Z19: 1.58 | AA19: 1.68 | AB19: 1.68 | AC19: 1.77 | AD19: 1.77
A20: 150 | B20: 23 | C20: 0.56 | D20: 0.56 | E20: 0.65 | F20: 0.65 | G20: 0.75 | H20: 0.75 | I20: 0.84 | J20: 0.84 | K20: 0.93 | L20: 0.93 | M20: 1.04 | N20: 1.04 | O20: 1.12 | P20: 1.12 | Q20: 1.21 | R20: 1.21 | S20: 1.3 | T20: 1.3 | U20: 1.4 | V20: 1.4 | W20: 1.49 | X20: 1.49 | Y20: 1.58 | Z20: 1.58 | AA20: 1.68 | AB20: 1.68 | AC20: 1.77 | AD20: 1.77
A21: 151 | B21: 24 | C21: 0.65 | D21: 0.65 | E21: 0.75 | F21: 0.75 | G21: 0.84 | H21: 0.84 | I21: 0.93 | J21: 0.93 | K21: 1.04 | L21: 1.04 | M21: 1.12 | N21: 1.12 | O21: 1.21 | P21: 1.21 | Q21: 1.3 | R21: 1.3 | S21: 1.4 | T21: 1.4 | U21: 1.49 | V21: 1.49 | W21: 1.58 | X21: 1.58 | Y21: 1.68 | Z21: 1.68 | AA21: 1.77 | AB21: 1.77 | AC21: 1.86 | AD21: 1.86
A22: 200 | B22: 25 | C22: 0.65 | D22: 0.65 | E22: 0.75 | F22: 0.75 | G22: 0.84 | H22: 0.84 | I22: 0.93 | J22: 0.93 | K22: 1.04 | L22: 1.04 | M22: 1.12 | N22: 1.12 | O22: 1.21 | P22: 1.21 | Q22: 1.3 | R22: 1.3 | S22: 1.4 | T22: 1.4 | U22: 1.49 | V22: 1.49 | W22: 1.58 | X22: 1.58 | Y22: 1.68 | Z22: 1.68 | AA22: 1.77 | AB22: 1.77 | AC22: 1.86 | AD22: 1.86
A23: 201 | B23: 26 | C23: 0.75 | D23: 0.75 | E23: 0.84 | F23: 0.84 | G23: 0.93 | H23: 0.93 | I23: 1.04 | J23: 1.04 | K23: 1.12 | L23: 1.12 | M23: 1.21 | N23: 1.21 | O23: 1.3 | P23: 1.3 | Q23: 1.4 | R23: 1.4 | S23: 1.49 | T23: 1.49 | U23: 1.58 | V23: 1.58 | W23: 1.68 | X23: 1.68 | Y23: 1.77 | Z23: 1.77 | AA23: 1.86 | AB23: 1.86 | AC23: 1.96 | AD23: 1.96
A24: 250 | B24: 27 | C24: 0.75 | D24: 0.75 | E24: 0.84 | F24: 0.84 | G24: 0.93 | H24: 0.93 | I24: 1.04 | J24: 1.04 | K24: 1.12 | L24: 1.12 | M24: 1.21 | N24: 1.21 | O24: 1.3 | P24: 1.3 | Q24: 1.4 | R24: 1.4 | S24: 1.49 | T24: 1.49 | U24: 1.58 | V24: 1.58 | W24: 1.68 | X24: 1.68 | Y24: 1.77 | Z24: 1.77 | AA24: 1.86 | AB24: 1.86 | AC24: 1.96 | AD24: 1.96
A25: 251 | B25: 28 | C25: 0.84 | D25: 0.84 | E25: 0.93 | F25: 0.93 | G25: 1.04 | H25: 1.04 | I25: 1.12 | J25: 1.12 | K25: 1.21 | L25: 1.21 | M25: 1.3 | N25: 1.3 | O25: 1.4 | P25: 1.4 | Q25: 1.49 | R25: 1.49 | S25: 1.58 | T25: 1.58 | U25: 1.68 | V25: 1.68 | W25: 1.77 | X25: 1.77 | Y25: 1.86 | Z25: 1.86 | AA25: 1.96 | AB25: 1.96 | AC25: 2.05 | AD25: 2.05
A26: 300 | B26: 29 | C26: 0.84 | D26: 0.84 | E26: 0.93 | F26: 0.93 | G26: 1.04 | H26: 1.04 | I26: 1.12 | J26: 1.12 | K26: 1.21 | L26: 1.21 | M26: 1.3 | N26: 1.3 | O26: 1.4 | P26: 1.4 | Q26: 1.49 | R26: 1.49 | S26: 1.58 | T26: 1.58 | U26: 1.68 | V26: 1.68 | W26: 1.77 | X26: 1.77 | Y26: 1.86 | Z26: 1.86 | AA26: 1.96 | AB26: 1.96 | AC26: 2.05 | AD26: 2.05
... A30: 400 | B30: 33 | C30: 1.04 | D30: 1.04 | E30: 1.12 | F30: 1.12 | G30: 1.21 | H30: 1.21 | I30: 1.3 | J30: 1.3 | K30: 1.4 | L30: 1.4 | M30: 1.49 | N30: 1.49 | O30: 1.58 | P30: 1.58 | Q30: 1.68 | R30: 1.68 | S30: 1.77 | T30: 1.77 | U30: 1.86 | V30: 1.86 | W30: 1.96 | X30: 1.96 | Y30: 2.05 | Z30: 2.05 | AA30: 2.14 | AB30: 2.14 | AC30: 2.24 | AD30: 2.24
A32: FESTÓN | B32: 0.75 | C32: €/Mt.

Sheet CORTE
A1: PEDIDO Nº | B1: 110125 | C1: CLIENTE: | D1: CLIENTE
C3: F. ENTREGA:
C4: F. TEJIDO:
C5: F. OK PEDIDO:
A7: CINTA | B7: MEDIDA MESA | C7: ARTICULO | D7: MEDIDA USO | E7: TEJIDO | F7: COLOR | G7: DOBLADILLO | H7: CORTE | I7: CANTIDAD
A10: 0
A11: 0 | B11: 80*80*75 | C11: Mantel | D11: 230 * 230 PR | E11: Saten Liso Nacional | F11: c/ 1 Blanco | G11: Dobl. 1,5 cm. | H11: 241 * 244 | I11: 1
A12: #¡REF! | B12: #¡REF! | C12: #¡REF! | D12: #¡REF! | E12: #¡REF! | F12: #¡REF! | G12: #¡REF! | H12: #¡REF! | I12: #¡REF!
A13: 0 | B13: 80*80*25 | C13: Cubre | D13: 130 * 130 | E13: Fenicia | F13: c/ 1 Todos los colores | G13: Dobl. 1,5 cm. | H13: 139 * 140 | I13: 1
A14: 0 | C14: Camino de mesa | D14: 40 * 120 | E14: Baroja | F14: c/ 1 Crudo | G14: Dobl. 1,5 cm. | H14: 46 * 126 | I14: 1
A15: 0 | B15: (/)180*75 | C15: Mantel | D15: 330 * 330 | E15: Saten Pes100 | F15: c/ 2 Palido | G15: Dobl. 1,5 cm. | H15: Redondo 336 * 336 | I15: 1
A16: 0 | C16: Servilleta | D16: 50 * 50 | E16: Saten Liso Nacional | F16: c/ 1 Blanco | G16: Dobl. 2 cm. | H16: 60 * 60 | I16: 1
A17: 0 | C17: Servilleta | D17: 50 * 50 | E17: Saten Liso Nacional | F17: c/ 58 Azul | G17: Dobl. 2 cm. | H17: 60 * 60 | I17: 1
A18: 0
A19: 0
A20: 0
A21: 0
A22: 0
A23: 0
A24: #¡REF! | B24: #¡REF! | C24: #¡REF! | D24: #¡REF! | E24: #¡REF! | F24: #¡REF! | G24: #¡REF! | H24: #¡REF! | I24: #¡REF!
A25: 0 | B25: 80*80*25 | G25: Dobl. 1,5 cm.
A26: TEJIDO: | E26: ANOTACIONES:

Sheet EMPALME
A1: ANCHO DEL TEJIDO | B1: ANCHO DEL MANTEL | C1: REF. EMPALME | D1: LARGO EMPALME | E1: ANCHO EMPALME | F1: AL ANCHO SALEN
A2: 280 | B2: 300 | C2: 280300 | D2: 110 | E2: 22 | F2: 12
A3: 280 | B3: 305 | C3: 280305 | D3: 160 | E3: 27 | F3: 10
A4: 280 | B4: 310 | C4: 280310 | D4: 170 | E4: 32 | F4: 8
A5: 280 | B5: 315 | C5: 280315 | D5: 190 | E5: 37 | F5: 7
A6: 280 | B6: 320 | C6: 280320 | D6: 200 | E6: 42 | F6: 6
A7: 280 | B7: 325 | C7: 280325 | D7: 230 | E7: 47 | F7: 5
A8: 280 | B8: 330 | C8: 280330 | D8: 245 | E8: 52 | F8: 5
A9: 280 | B9: 335 | C9: 280335 | D9: 260 | E9: 57 | F9: 4
A10: 280 | B10: 340 | C10: 280340 | D10: 265 | E10: 62 | F10: 4
A11: 280 | B11: 345 | C11: 280345 | D11: 290 | E11: 67 | F11: 4
A12: 280 | B12: 350 | C12: 280350 | D12: 295 | E12: 72 | F12: 3
A13: 280 | B13: 360 | C13: 280360 | D13: 300 | E13: 82 | F13: 3
... A33: 330 | B33: 350 | C33: 330350 | D33: 275 | E33: 22 | F33: 15

Sheet ARTICULOS
D1: ¡¡¡¡NO PONGAS ACENTOS !!!!!!
A3: PRODUCTO | D3: ARTICULO
D4: REF. 1 | G4: Encogimiento LargoU | H4: Encogimiento AnchoT | I4: REF. 2
A5: 1 | B5: Mantel | D5: 1 | E5: TVR | F5: Saten 50/50 | G5: 0.03 | H5: 0.02 | I5: 1TVR
A6: 2 | B6: Cubre | D6: 2 | E6: TVR | F6: Saten Pes100 | G6: 0 | H6: 0 | I6: 2TVR
A7: 3 | B7: Servilleta | D7: 3 | E7: TVR | F7: Saten London | G7: 0 | H7: 0 | I7: 3TVR
A8: 4 | B8: Camino de mesa | C8: Triana | D8: 4 | E8: TVR | F8: Triunfo | G8: 0.03 | H8: 0.02 | I8: 4TVR
A9: 5 | B9: Muleton | C9: Triana Imitacion | D9: 5 | E9: TVR | F9: Triunfo Lino | G9: 0.03 | H9: 0.02 | I9: 5TVR
A10: 6 | B10: Gueridon | D10: 6 | E10: TVR | F10: Granito | G10: 0 | H10: 0 | I10: 6TVR
A11: 7 | B11: Lito | D11: 7 | E11: TVR | F11: Tevere | G11: 0.03 | H11: 0.02 | I11: 7TVR
A12: 8 | B12: Individual | D12: 8 | E12: TVR | F12: Tagore Pes100 | G12: 0 | H12: 0 | I12: 8TVR
A13: 9 | D13: 9 | E13: TVR | F13: Santorini | G13: 0 | H13: 0 | I13: 9TVR
A14: 10 | B14: Funda | C14: Jara | D14: 10 | E14: TVR | F14: Lino Jazmin | G14: 0.03 | H14: 0.05 | I14: 10TVR
D15: 11 | E15: TVR | F15: Damasco Alhambra | G15: 0.03 | H15: 0.02 | I15: 11TVR
D16: 12 | E16: GRT | F16: Nilo Rustico | G16: 0.045 | H16: 0.035 | I16: 12GRT | J16: 2024
D17: 13 | E17: GRT | F17: Lino Grt | G17: 0.05 | H17: 0.05 | I17: 13GRT | J17: 2024 | K17: al/lin/pol
D18: 14 | E18: RMR | F18: Acrisol Liso 160 | G18: 0 | H18: 0 | I18: 14RMR
D19: 15 | E19: RMR | F19: Acrisol Liso 320 | G19: 0 | H19: 0 | I19: 15RMR
D20: 16 | E20: RMR | F20: Acrisol 7 Calles 160 | G20: 0 | H20: 0 | I20: 16RMR
D21: 17 | E21: GCU | F21: LinoPoliester | G21: 0.03 | H21: 0.02 | I21: 17GCU
D22: 18 | E22: TVR | F22: Saten London | G22: 0 | H22: 0 | I22: 18TVR
D23: 19 | E23: GCU | F23: Saten Liso Nacional | G23: 0.03 | H23: 0.02 | I23: 19GCU
D24: 20 | E24: TVR | F24: Saten Liso Importacion | G24: 0.03 | H24: 0.02 | I24: 20TVR
D25: 21 | E25: TVR | F25: Chambery | G25: 0.03 | H25: 0.02 | I25: 21TVR | J25: ojo modificado según lavado miguel 2025
D26: 22 | E26: TVR | F26: Rabat | G26: 0.06 | H26: 0.04 | I26: 22TVR
D27: 23 | E27: ANG | F27: Lino 100% For. | G27: 0.067 | H27: 0.055 | I27: 23ANG
D28: 24 | E28: GRT | F28: Muleton | G28: 0 | H28: 0 | I28: 24GRT
D29: 25 | E29: TVR | F29: Col. Rustico T. | G29: 0 | H29: 0 | I29: 25TVR
D30: 26 | E30: BTX | F30: Clio | G30: 0.02 | H30: 0.02 | I30: 26BTX
D31: 27 | E31: GCU | F31: Nilo Cuadro | G31: 0.035 | H31: 0.03 | I31: 27GCU
D32: 28 | E32: YEB | F32: Fenicia | G32: 0.025 | H32: 0.02 | I32: 28YEB
D33: 29 | E33: TVR | F33: Mahon | G33: 0.02 | H33: 0.02 | I33: 29TVR
D34: 30 | E34: BTX | F34: Gouble | G34: 0.02 | H34: 0.02 | I34: 30BTX
D35: 31 | E35: BTX | F35: Trivial | G35: 0.02 | H35: 0.02 | I35: 31BTX
D36: 32 | E36: GCU | F36: Resite Antimanchas | G36: 0 | H36: 0 | I36: 32GCU
D37: 33 | E37: TVR | F37: Saten Antimanchas | G37: 0.01 | H37: 0.01 | I37: 33TVR
... D46: 42 | E46: TVR | F46: Santorini | G46: 0.01 | H46: 0.01 | I46: 42TVR
D47: 43 | E47: COM | F47: Aeris | I47: 43COM
D48: 44 | E48: GRT | F48: Recy Linen | G48: 0.055 | H48: 0.035 | I48: 44GRT | J48: 2024
D49: 45 | E49: YEB | F49: Bellini | G49: 0 | H49: 0 | I49: 45YEB
...

Sheet CALCULO
A1: CINTA | B1: MESA | C1: ARTICULO | D1: MEDIDA USO | E1: TEJIDO | F1: REF TEJIDO | G1: NUM COLOR | H1: DOBLADILLO | I1: REDONDO | J1: ANCHO MESA | K1: LARGO MESA | L1: CAIDA | M1: MEDIDA DE CORTE | N1: ENCOGIMIENTO | O1: NOMBRE COLOR | P1: PRECIO UNITARIO | Q1: CANTIDAD | R1: TOTAL
B2: 80*80*75 | C2: Mantel | D2: 230 * 230 PR | E2: Saten Liso Nacional | F2: 19GCU | G2: 1 | H2: 1.5 | I2: 0 | J2: 80 | K2: 80 | L2: 75 | M2: {=CALCULOS!G2&" * "&CALCULOS!H2} | N2: 1 | O2: {=VLOOKUP(F2&TEXT(G2,"0"),COLORES!E2:G4400,3,0)} | P2: {=CALCULOS!I2+CALCULOS!J2+CALCULOS!K2} | Q2: 5 | R2: {=P2*Q2}
B3: 80*80*25 | C3: Cubre | D3: 130 * 130 | E3: Fenicia | F3: 28YEB | G3: 1 | H3: 1.5 | I3: 0 | J3: 80 | K3: 80 | L3: 25 | M3: {=CALCULOS!G3&" * "&CALCULOS!H3} | N3: 1 | O3: {=VLOOKUP(F3&TEXT(G3,"0"),COLORES!E2:G4400,3,0)} | P3: {=CALCULOS!I3+CALCULOS!J3+CALCULOS!K3} | Q3: 10 | R3: {=P3*Q3}
C4: Camino de mesa | D4: 40 * 120 | E4: Baroja | F4: 49MRV | G4: 1 | H4: 1.5 | I4: 0 | J4: 40 | K4: 120 | L4: 0 | M4: {=CALCULOS!G4&" * "&CALCULOS!H4} | N4: 1 | O4: {=VLOOKUP(F4&TEXT(G4,"0"),COLORES!E2:G4400,3,0)} | P4: {=CALCULOS!I4+CALCULOS!J4+CALCULOS!K4} | Q4: 0 | R4: {=P4*Q4}
B5: (/)180*75 | C5: Mantel | D5: 330 * 330 | E5: Saten Pes100 | F5: 2TVR | G5: 2 | H5: 1.5 | I5: 336 | J5: 180 | K5: 180 | L5: 75 | M5: {=CALCULOS!G5&" * "&CALCULOS!H5} | N5: 1 | O5: {=VLOOKUP(F5&TEXT(G5,"0"),COLORES!E2:G4400,3,0)} | P5: {=CALCULOS!I5+CALCULOS!J5+CALCULOS!K5} | Q5: 0 | R5: {=P5*Q5}
C6: Servilleta | D6: 50 * 50 | E6: Saten Liso Nacional | F6: 19GCU | G6: 1 | H6: 2 | I6: 0 | J6: 50 | K6: 50 | L6: 0 | M6: {=CALCULOS!G6&" * "&CALCULOS!H6} | N6: 0 | O6: {=VLOOKUP(F6&TEXT(G6,"0"),COLORES!E2:G4400,3,0)} | P6: {=CALCULOS!I6+CALCULOS!J6+CALCULOS!K6} | Q6: 0 | R6: {=P6*Q6}
C7: Servilleta | D7: 50 * 50 | E7: Saten Liso Nacional | F7: 19GCU | G7: 58 | H7: 2 | I7: 0 | J7: 50 | K7: 50 | L7: 0 | M7: {=CALCULOS!G7&" * "&CALCULOS!H7} | N7: 0 | O7: {=VLOOKUP(F7&TEXT(G7,"0"),COLORES!E2:G4400,3,0)} | P7: {=CALCULOS!I7+CALCULOS!J7+CALCULOS!K7} | Q7: 0 | R7: {=P7*Q7}
C8: Muleton | D8: 80 * 80 | E8: Muleton | F8: 24GRT | G8: 1 | H8: 3 | I8: 0 | J8: 80 | K8: 80 | L8: 0 | M8: {=CALCULOS!G8&" * "&CALCULOS!H8} | N8: 1 | O8: {=VLOOKUP(F8&TEXT(G8,"0"),COLORES!E2:G4400,3,0)} | P8: {=CALCULOS!I8+CALCULOS!J8+CALCULOS!K8} | Q8: 0 | R8: {=P8*Q8}
C9: Lito | D9: 45 * 70 | E9: Saten Liso Nacional | F9: 19GCU | G9: 1 | H9: 1.5 | I9: 0 | J9: 45 | K9: 70 | L9: 0 | M9: {=CALCULOS!G9&" * "&CALCULOS!H9} | N9: 1 | O9: {=VLOOKUP(F9&TEXT(G9,"0"),COLORES!E2:G4400,3,0)} | P9: {=CALCULOS!I9+CALCULOS!J9+CALCULOS!K9} | Q9: 0 | R9: {=P9*Q9}
C10: Individual | D10: 35 * 50 | E10: Saten Liso Nacional | F10: 19GCU | G10: 1 | H10: 6 | I10: 0 | J10: 35 | K10: 50 | L10: 0 | M10: {=CALCULOS!G10&" * "&CALCULOS!H10} | N10: 0 | O10: {=VLOOKUP(F10&TEXT(G10,"0"),COLORES!E2:G4400,3,0)} | P10: {=CALCULOS!I10+CALCULOS!J10+CALCULOS!K10} | Q10: 0 | R10: {=P10*Q10}
M11: =IFERROR(CALCULOS!G11&" * "&CALCULOS!H11,"") | O11: =IFERROR(VLOOKUP(F11&TEXT(G11,"0"),COLORES!$E$2:$G$4400,3,0),"") | P11: =IFERROR(CALCULOS!I11+CALCULOS!J11+CALCULOS!K11,"") | R11: =IFERROR(P11*Q11,"")
M12: =IFERROR(CALCULOS!G12&" * "&CALCULOS!H12,"") | O12: =IFERROR(VLOOKUP(F12&TEXT(G12,"0"),COLORES!$E$2:$G$4400,3,0),"") | P12: =IFERROR(CALCULOS!I12+CALCULOS!J12+CALCULOS!K12,"") | Q12: TOTAL | R12: =IFERROR(P12*Q12,"")
M13: =IFERROR(CALCULOS!G13&" * "&CALCULOS!H13,"") | O13: =IFERROR(VLOOKUP(F13&TEXT(G13,"0"),COLORES!$E$2:$G$4400,3,0),"") | P13: =IFERROR(CALCULOS!I13+CALCULOS!J13+CALCULOS!K13,"") | R13: =IFERROR(P13*Q13,"")
M14: =IFERROR(CALCULOS!G14&" * "&CALCULOS!H14,"") | O14: =IFERROR(VLOOKUP(F14&TEXT(G14,"0"),COLORES!$E$2:$G$4400,3,0),"") | P14: =IFERROR(CALCULOS!I14+CALCULOS!J14+CALCULOS!K14,"") | R14: =IFERROR(P14*Q14,"")
M15: =IFERROR(CALCULOS!G15&" * "&CALCULOS!H15,"") | O15: =IFERROR(VLOOKUP(F15&TEXT(G15,"0"),COLORES!$E$2:$G$4400,3,0),"") | P15: =IFERROR(CALCULOS!I15+CALCULOS!J15+CALCULOS!K15,"") | R15: =IFERROR(P15*Q15,"")
M16: =IFERROR(CALCULOS!G16&" * "&CALCULOS!H16,"") | O16: =IFERROR(VLOOKUP(F16&TEXT(G16,"0"),COLORES!$E$2:$G$4400,3,0),"") | P16: =IFERROR(CALCULOS!I16+CALCULOS!J16+CALCULOS!K16,"") | R16: =IFERROR(P16*Q16,"")
M17: =IFERROR(CALCULOS!G17&" * "&CALCULOS!H17,"") | O17: =IFERROR(VLOOKUP(F17&TEXT(G17,"0"),COLORES!$E$2:$G$4400,3,0),"") | P17: =IFERROR(CALCULOS!I17+CALCULOS!J17+CALCULOS!K17,"") | R17: =IFERROR(P17*Q17,"")
M18: =IFERROR(CALCULOS!G18&" * "&CALCULOS!H18,"") | O18: =IFERROR(VLOOKUP(F18&TEXT(G18,"0"),COLORES!$E$2:$G$4400,3,0),"") | P18: =IFERROR(CALCULOS!I18+CALCULOS!J18+CALCULOS!K18,"") | R18: =IFERROR(P18*Q18,"")
M19: =IFERROR(CALCULOS!G19&" * "&CALCULOS!H19,"") | O19: =IFERROR(VLOOKUP(F19&TEXT(G19,"0"),COLORES!$E$2:$G$4400,3,0),"") | P19: =IFERROR(CALCULOS!I19+CALCULOS!J19+CALCULOS!K19,"") | R19: =IFERROR(P19*Q19,"")
M20: =IFERROR(CALCULOS!G20&" * "&CALCULOS!H20,"") | O20: =IFERROR(VLOOKUP(F20&TEXT(G20,"0"),COLORES!$E$2:$G$4400,3,0),"") | P20: =IFERROR(CALCULOS!I20+CALCULOS!J20+CALCULOS!K20,"") | R20: =IFERROR(P20*Q20,"")
M21: =IFERROR(CALCULOS!G21&" * "&CALCULOS!H21,"") | O21: =IFERROR(VLOOKUP(F21&TEXT(G21,"0"),COLORES!$E$2:$G$4400,3,0),"") | P21: =IFERROR(CALCULOS!I21+CALCULOS!J21+CALCULOS!K21,"") | R21: =IFERROR(P21*Q21,"")
M22: =IFERROR(CALCULOS!G22&" * "&CALCULOS!H22,"") | O22: =IFERROR(VLOOKUP(F22&TEXT(G22,"0"),COLORES!$E$2:$G$4400,3,0),"") | P22: =IFERROR(CALCULOS!I22+CALCULOS!J22+CALCULOS!K22,"") | R22: =IFERROR(P22*Q22,"")
M23: =IFERROR(CALCULOS!G23&" * "&CALCULOS!H23,"") | O23: =IFERROR(VLOOKUP(F23&TEXT(G23,"0"),COLORES!$E$2:$G$4400,3,0),"") | P23: =IFERROR(CALCULOS!I23+CALCULOS!J23+CALCULOS!K23,"") | R23: =IFERROR(P23*Q23,"")
M24: =IFERROR(CALCULOS!G24&" * "&CALCULOS!H24,"") | O24: =IFERROR(VLOOKUP(F24&TEXT(G24,"0"),COLORES!$E$2:$G$4400,3,0),"") | P24: =IFERROR(CALCULOS!I24+CALCULOS!J24+CALCULOS!K24,"") | R24: =IFERROR(P24*Q24,"")
... M50: =IFERROR(CALCULOS!G50&" * "&CALCULOS!H50,"") | O50: =IFERROR(VLOOKUP(F50&TEXT(G50,"0"),COLORES!$E$2:$G$4400,3,0),"") | P50: =IFERROR(CALCULOS!I50+CALCULOS!J50+CALCULOS!K50,"") | R50: =IFERROR(P50*Q50,"")
Q51: TOTAL: | R51: =SUM(R2:R50)

Sheet CALCULOS
A1: POST_ART | B1: REF2_ART | C1: REF_COLOR | D1: POS_COLOR | E1: ANCHO_ROLLO | F1: COSTE_METRO | G1: MEDIDA CORTE_A | H1: MEDIDA CORTE_L | I1: COSTE TEJIDO | J1: COSTE_CONFEC | K1: FESTON
A2: {=MATCH(CALCULO!E2,ARTICULOS!F5:F200,0)} | B2: {=INDEX(ARTICULOS!D5:D200,A2)&INDEX(ARTICULOS!E5:E200,A2)} | C2: {=B2&CALCULO!G2} | D2: {=MATCH(C2,COLORES!E2:E4400,0)} | E2: {=INDEX(COLORES!I2:I4400,D2)} | F2: {=INDEX(COLORES!H2:H4400,D2)} | G2: {=IF(CALCULO!I2>0,ROUNDUP(CALCULO!I2*(1+INDEX(ARTICULOS!H5:H200,MATCH(CALCULO!E2,ARTICULOS!F5:F200,0))),0),IF(CALCULO!N2=1,IF(CALCULO!H2=1,ROUNDUP((CALCULO!J2+CALCULO!L2*2+5)*(1+INDEX(ARTICULOS!H5:H200,MATCH(CALCULO!E2,ARTICULOS!F5:F200,0))),0),ROUNDUP((CALCULO!J2+CALCULO!L2*2+CALCULO!H2*4)*(1+INDEX(ARTICULOS!H5:H200,MATCH(CALCULO!E2,ARTICULOS!F5:F200,0))),0)),IF(CALCULO!H2=1,ROUNDUP(CALCULO!J2+CALCULO!L2*2+5,0),ROUNDUP(CALCULO!J2+CALCULO!L2*2+CALCULO!H2*4,0))))} | H2: {=IF(CALCULO!H2=1,ROUNDUP((CALCULO!K2+CALCULO!L2*2+5)*(1+INDEX(ARTICULOS!G5:G200,MATCH(CALCULO!E2,ARTICULOS!F5:F200,0))),0),ROUNDUP((CALCULO!K2+CALCULO!L2*2+CALCULO!H2*4)*(1+INDEX(ARTICULOS!G5:G200,MATCH(CALCULO!E2,ARTICULOS!F5:F200,0))),0))} | I2: {=ROUND(F2*2*H2/100/INT(E2/(G2/100)),2)} | J2: {=IF(CALCULO!H2=1,INDEX(CONFECCION!C15:AD30,MATCH(G2,CONFECCION!A15:A30,1),MATCH(H2,CONFECCION!C14:AD14,1)),2*INDEX(CONFECCION!C15:AD30,MATCH(G2,CONFECCION!A15:A30,1),MATCH(H2,CONFECCION!C14:AD14,1)))} | K2: {=IF(AND(CALCULO!C2="Servilleta",CALCULO!G2=58),ROUND((G2*2+H2*2)*CONFECCION!B32/100,2),IF(CALCULO!C2="Individual",ROUND((G2*2+H2*2)*CONFECCION!B32/100,2),0))}
A3: {=MATCH(CALCULO!E3,ARTICULOS!F6:F201,0)} | B3: {=INDEX(ARTICULOS!D6:D201,A3)&INDEX(ARTICULOS!E6:E201,A3)} | C3: {=B3&CALCULO!G3} | D3: {=MATCH(C3,COLORES!E3:E4401,0)} | E3: {=INDEX(COLORES!I3:I4401,D3)} | F3: {=INDEX(COLORES!H3:H4401,D3)} | G3: {=IF(CALCULO!I3>0,ROUNDUP(CALCULO!I3*(1+INDEX(ARTICULOS!H5:H200,MATCH(CALCULO!E3,ARTICULOS!F5:F200,0))),0),IF(CALCULO!N3=1,IF(CALCULO!H3=1,ROUNDUP((CALCULO!J3+CALCULO!L3*2+5)*(1+INDEX(ARTICULOS!H5:H200,MATCH(CALCULO!E3,ARTICULOS!F5:F200,0))),0),ROUNDUP((CALCULO!J3+CALCULO!L3*2+CALCULO!H3*4)*(1+INDEX(ARTICULOS!H5:H200,MATCH(CALCULO!E3,ARTICULOS!F5:F200,0))),0)),IF(CALCULO!H3=1,ROUNDUP(CALCULO!J3+CALCULO!L3*2+5,0),ROUNDUP(CALCULO!J3+CALCULO!L3*2+CALCULO!H3*4,0))))} | H3: {=IF(CALCULO!H3=1,ROUNDUP((CALCULO!K3+CALCULO!L3*2+5)*(1+INDEX(ARTICULOS!G5:G200,MATCH(CALCULO!E3,ARTICULOS!F5:F200,0))),0),ROUNDUP((CALCULO!K3+CALCULO!L3*2+CALCULO!H3*4)*(1+INDEX(ARTICULOS!G5:G200,MATCH(CALCULO!E3,ARTICULOS!F5:F200,0))),0))} | I3: {=ROUND(F3*2*H3/100/INT(E3/(G3/100)),2)} | J3: {=IF(CALCULO!H3=1,INDEX(CONFECCION!C15:AD30,MATCH(G3,CONFECCION!A15:A30,1),MATCH(H3,CONFECCION!C14:AD14,1)),2*INDEX(CONFECCION!C15:AD30,MATCH(G3,CONFECCION!A15:A30,1),MATCH(H3,CONFECCION!C14:AD14,1)))} | K3: {=IF(AND(CALCULO!C3="Servilleta",CALCULO!G3=58),ROUND((G3*2+H3*2)*CONFECCION!B32/100,2),IF(CALCULO!C3="Individual",ROUND((G3*2+H3*2)*CONFECCION!B32/100,2),0))}
A4: {=MATCH(CALCULO!E4,ARTICULOS!F7:F202,0)} | B4: {=INDEX(ARTICULOS!D7:D202,A4)&INDEX(ARTICULOS!E7:E202,A4)} | C4: {=B4&CALCULO!G4} | D4: {=MATCH(C4,COLORES!E4:E4402,0)} | E4: {=INDEX(COLORES!I4:I4402,D4)} | F4: {=INDEX(COLORES!H4:H4402,D4)} | G4: {=IF(CALCULO!I4>0,ROUNDUP(CALCULO!I4*(1+INDEX(ARTICULOS!H5:H200,MATCH(CALCULO!E4,ARTICULOS!F5:F200,0))),0),IF(CALCULO!N4=1,IF(CALCULO!H4=1,ROUNDUP((CALCULO!J4+CALCULO!L4*2+5)*(1+INDEX(ARTICULOS!H5:H200,MATCH(CALCULO!E4,ARTICULOS!F5:F200,0))),0),ROUNDUP((CALCULO!J4+CALCULO!L4*2+CALCULO!H4*4)*(1+INDEX(ARTICULOS!H5:H200,MATCH(CALCULO!E4,ARTICULOS!F5:F200,0))),0)),IF(CALCULO!H4=1,ROUNDUP(CALCULO!J4+CALCULO!L4*2+5,0),ROUNDUP(CALCULO!J4+CALCULO!L4*2+CALCULO!H4*4,0))))} | H4: {=IF(CALCULO!H4=1,ROUNDUP((CALCULO!K4+CALCULO!L4*2+5)*(1+INDEX(ARTICULOS!G5:G200,MATCH(CALCULO!E4,ARTICULOS!F5:F200,0))),0),ROUNDUP((CALCULO!K4+CALCULO!L4*2+CALCULO!H4*4)*(1+INDEX(ARTICULOS!G5:G200,MATCH(CALCULO!E4,ARTICULOS!F5:F200,0))),0))} | I4: {=ROUND(F4*2*H4/100/INT(E4/(G4/100)),2)} | J4: {=IF(CALCULO!H4=1,INDEX(CONFECCION!C15:AD30,MATCH(G4,CONFECCION!A15:A30,1),MATCH(H4,CONFECCION!C14:AD14,1)),2*INDEX(CONFECCION!C15:AD30,MATCH(G4,CONFECCION!A15:A30,1),MATCH(H4,CONFECCION!C14:AD14,1)))} | K4: {=IF(AND(CALCULO!C4="Servilleta",CALCULO!G4=58),ROUND((G4*2+H4*2)*CONFECCION!B32/100,2),IF(CALCULO!C4="Individual",ROUND((G4*2+H4*2)*CONFECCION!B32/100,2),0))}
A5: {=MATCH(CALCULO!F5&CALCULO!G5,COLORES!E2:E4400,0)} | B5: {=CALCULO!F5} | C5: {=CALCULO!F5&CALCULO!G5} | D5: {=MATCH(C5,COLORES!E5:E4403,0)} | E5: {=INDEX(COLORES!I5:I4403,D5)} | F5: {=INDEX(COLORES!H5:H4403,D5)} | G5: {=IF(CALCULO!I5>0,ROUNDUP(CALCULO!I5*(1+INDEX(ARTICULOS!H5:H200,MATCH(CALCULO!E5,ARTICULOS!F5:F200,0))),0),IF(CALCULO!N5=1,IF(CALCULO!H5=1,ROUNDUP((CALCULO!J5+CALCULO!L5*2+5)*(1+INDEX(ARTICULOS!H5:H200,MATCH(CALCULO!E5,ARTICULOS!F5:F200,0))),0),ROUNDUP((CALCULO!J5+CALCULO!L5*2+CALCULO!H5*4)*(1+INDEX(ARTICULOS!H5:H200,MATCH(CALCULO!E5,ARTICULOS!F5:F200,0))),0)),IF(CALCULO!H5=1,ROUNDUP(CALCULO!J5+CALCULO!L5*2+5,0),ROUNDUP(CALCULO!J5+CALCULO!L5*2+CALCULO!H5*4,0))))} | H5: {=IF(CALCULO!H5=1,ROUNDUP((CALCULO!K5+CALCULO!L5*2+5)*(1+INDEX(ARTICULOS!G5:G200,MATCH(CALCULO!E5,ARTICULOS!F5:F200,0))),0),ROUNDUP((CALCULO!K5+CALCULO!L5*2+CALCULO!H5*4)*(1+INDEX(ARTICULOS!G5:G200,MATCH(CALCULO!E5,ARTICULOS!F5:F200,0))),0))} | I5: {=ROUND(F5*2*H5/100/IF(INT(E5/(G5/100))=0,1,INT(E5/(G5/100))),2)} | J5: {=2*INDEX(CONFECCION!C15:AD30,MATCH(G5,CONFECCION!A15:A30,1),MATCH(H5,CONFECCION!C14:AD14,1))*IF(INT(E5/(G5/100))=0,3,1)} | K5: {=IF(AND(CALCULO!C5="Servilleta",CALCULO!G5=58),ROUND((G5*2+H5*2)*CONFECCION!B32/100,2),IF(CALCULO!C5="Individual",ROUND((G5*2+H5*2)*CONFECCION!B32/100,2),0))}
A6: {=MATCH(CALCULO!E6,ARTICULOS!F9:F204,0)} | B6: {=INDEX(ARTICULOS!D9:D204,A6)&INDEX(ARTICULOS!E9:E204,A6)} | C6: {=B6&CALCULO!G6} | D6: {=MATCH(C6,COLORES!E6:E4404,0)} | E6: {=INDEX(COLORES!I6:I4404,D6)} | F6: {=INDEX(COLORES!H6:H4404,D6)} | G6: {=IF(CALCULO!I6>0,ROUNDUP(CALCULO!I6*(1+INDEX(ARTICULOS!H5:H200,MATCH(CALCULO!E6,ARTICULOS!F5:F200,0))),0),IF(CALCULO!N6=1,IF(CALCULO!H6=1,ROUNDUP((CALCULO!J6+CALCULO!L6*2+5)*(1+INDEX(ARTICULOS!H5:H200,MATCH(CALCULO!E6,ARTICULOS!F5:F200,0))),0),ROUNDUP((CALCULO!J6+CALCULO!L6*2+CALCULO!H6*4)*(1+INDEX(ARTICULOS!H5:H200,MATCH(CALCULO!E6,ARTICULOS!F5:F200,0))),0)),IF(CALCULO!H6=1,ROUNDUP(CALCULO!J6+CALCULO!L6*2+5,0),ROUNDUP(CALCULO!J6+CALCULO!L6*2+CALCULO!H6*4,0))))} | H6: {=IF(CALCULO!H6=1,ROUNDUP((CALCULO!K6+CALCULO!L6*2+5)*(1+INDEX(ARTICULOS!G5:G200,MATCH(CALCULO!E6,ARTICULOS!F5:F200,0))),0),ROUNDUP((CALCULO!K6+CALCULO!L6*2+CALCULO!H6*4)*(1+INDEX(ARTICULOS!G5:G200,MATCH(CALCULO!E6,ARTICULOS!F5:F200,0))),0))} | I6: {=ROUND(F6*2*H6/100/INT(E6/(G6/100)),2)} | J6: {=IF(CALCULO!H6=1,INDEX(CONFECCION!C15:AD30,MATCH(G6,CONFECCION!A15:A30,1),MATCH(H6,CONFECCION!C14:AD14,1)),2*INDEX(CONFECCION!C15:AD30,MATCH(G6,CONFECCION!A15:A30,1),MATCH(H6,CONFECCION!C14:AD14,1)))} | K6: {=IF(AND(CALCULO!C6="Servilleta",CALCULO!G6=58),ROUND((G6*2+H6*2)*CONFECCION!B32/100,2),IF(CALCULO!C6="Individual",ROUND((G6*2+H6*2)*CONFECCION!B32/100,2),0))}
A7: {=MATCH(CALCULO!E7,ARTICULOS!F10:F205,0)} | B7: {=INDEX(ARTICULOS!D10:D205,A7)&INDEX(ARTICULOS!E10:E205,A7)} | C7: {=B7&CALCULO!G7} | D7: {=MATCH(C7,COLORES!E7:E4405,0)} | E7: {=INDEX(COLORES!I7:I4405,D7)} | F7: {=INDEX(COLORES!H7:H4405,D7)} | G7: {=IF(CALCULO!I7>0,ROUNDUP(CALCULO!I7*(1+INDEX(ARTICULOS!H5:H200,MATCH(CALCULO!E7,ARTICULOS!F5:F200,0))),0),IF(CALCULO!N7=1,IF(CALCULO!H7=1,ROUNDUP((CALCULO!J7+CALCULO!L7*2+5)*(1+INDEX(ARTICULOS!H5:H200,MATCH(CALCULO!E7,ARTICULOS!F5:F200,0))),0),ROUNDUP((CALCULO!J7+CALCULO!L7*2+CALCULO!H7*4)*(1+INDEX(ARTICULOS!H5:H200,MATCH(CALCULO!E7,ARTICULOS!F5:F200,0))),0)),IF(CALCULO!H7=1,ROUNDUP(CALCULO!J7+CALCULO!L7*2+5,0),ROUNDUP(CALCULO!J7+CALCULO!L7*2+CALCULO!H7*4,0))))} | H7: {=IF(CALCULO!H7=1,ROUNDUP((CALCULO!K7+CALCULO!L7*2+5)*(1+INDEX(ARTICULOS!G5:G200,MATCH(CALCULO!E7,ARTICULOS!F5:F200,0))),0),ROUNDUP((CALCULO!K7+CALCULO!L7*2+CALCULO!H7*4)*(1+INDEX(ARTICULOS!G5:G200,MATCH(CALCULO!E7,ARTICULOS!F5:F200,0))),0))} | I7: {=ROUND(F7*2*H7/100/INT(E7/(G7/100)),2)} | J7: {=IF(CALCULO!H7=1,INDEX(CONFECCION!C15:AD30,MATCH(G7,CONFECCION!A15:A30,1),MATCH(H7,CONFECCION!C14:AD14,1)),2*INDEX(CONFECCION!C15:AD30,MATCH(G7,CONFECCION!A15:A30,1),MATCH(H7,CONFECCION!C14:AD14,1)))} | K7: {=IF(AND(CALCULO!C7="Servilleta",CALCULO!G7=58),ROUND((G7*2+H7*2)*CONFECCION!B32/100,2),IF(CALCULO!C7="Individual",ROUND((G7*2+H7*2)*CONFECCION!B32/100,2),0))}
A8: {=MATCH(CALCULO!E8,ARTICULOS!F11:F206,0)} | B8: {=INDEX(ARTICULOS!D11:D206,A8)&INDEX(ARTICULOS!E11:E206,A8)} | C8: {=B8&CALCULO!G8} | D8: {=MATCH(C8,COLORES!E8:E4406,0)} | E8: {=INDEX(COLORES!I8:I4406,D8)} | F8: {=INDEX(COLORES!H8:H4406,D8)} | G8: {=IF(CALCULO!I8>0,ROUNDUP(CALCULO!I8*(1+INDEX(ARTICULOS!H5:H200,MATCH(CALCULO!E8,ARTICULOS!F5:F200,0))),0),IF(CALCULO!N8=1,IF(CALCULO!H8=1,ROUNDUP((CALCULO!J8+CALCULO!L8*2+5)*(1+INDEX(ARTICULOS!H5:H200,MATCH(CALCULO!E8,ARTICULOS!F5:F200,0))),0),ROUNDUP((CALCULO!J8+CALCULO!L8*2+CALCULO!H8*4)*(1+INDEX(ARTICULOS!H5:H200,MATCH(CALCULO!E8,ARTICULOS!F5:F200,0))),0)),IF(CALCULO!H8=1,ROUNDUP(CALCULO!J8+CALCULO!L8*2+5,0),ROUNDUP(CALCULO!J8+CALCULO!L8*2+CALCULO!H8*4,0))))} | H8: {=IF(CALCULO!H8=1,ROUNDUP((CALCULO!K8+CALCULO!L8*2+5)*(1+INDEX(ARTICULOS!G5:G200,MATCH(CALCULO!E8,ARTICULOS!F5:F200,0))),0),ROUNDUP((CALCULO!K8+CALCULO!L8*2+CALCULO!H8*4)*(1+INDEX(ARTICULOS!G5:G200,MATCH(CALCULO!E8,ARTICULOS!F5:F200,0))),0))} | I8: {=ROUND(F8*2*H8/100/INT(E8/(G8/100)),2)} | J8: {=IF(CALCULO!H8=1,INDEX(CONFECCION!C15:AD30,MATCH(G8,CONFECCION!A15:A30,1),MATCH(H8,CONFECCION!C14:AD14,1)),2*INDEX(CONFECCION!C15:AD30,MATCH(G8,CONFECCION!A15:A30,1),MATCH(H8,CONFECCION!C14:AD14,1)))} | K8: {=IF(AND(CALCULO!C8="Servilleta",CALCULO!G8=58),ROUND((G8*2+H8*2)*CONFECCION!B32/100,2),IF(CALCULO!C8="Individual",ROUND((G8*2+H8*2)*CONFECCION!B32/100,2),0))}
A9: {=MATCH(CALCULO!E9,ARTICULOS!F12:F207,0)} | B9: {=INDEX(ARTICULOS!D12:D207,A9)&INDEX(ARTICULOS!E12:E207,A9)} | C9: {=B9&CALCULO!G9} | D9: {=MATCH(C9,COLORES!E9:E4407,0)} | E9: {=INDEX(COLORES!I9:I4407,D9)} | F9: {=INDEX(COLORES!H9:H4407,D9)} | G9: {=IF(CALCULO!I9>0,ROUNDUP(CALCULO!I9*(1+INDEX(ARTICULOS!H5:H200,MATCH(CALCULO!E9,ARTICULOS!F5:F200,0))),0),IF(CALCULO!N9=1,IF(CALCULO!H9=1,ROUNDUP((CALCULO!J9+CALCULO!L9*2+5)*(1+INDEX(ARTICULOS!H5:H200,MATCH(CALCULO!E9,ARTICULOS!F5:F200,0))),0),ROUNDUP((CALCULO!J9+CALCULO!L9*2+CALCULO!H9*4)*(1+INDEX(ARTICULOS!H5:H200,MATCH(CALCULO!E9,ARTICULOS!F5:F200,0))),0)),IF(CALCULO!H9=1,ROUNDUP(CALCULO!J9+CALCULO!L9*2+5,0),ROUNDUP(CALCULO!J9+CALCULO!L9*2+CALCULO!H9*4,0))))} | H9: {=IF(CALCULO!H9=1,ROUNDUP((CALCULO!K9+CALCULO!L9*2+5)*(1+INDEX(ARTICULOS!G5:G200,MATCH(CALCULO!E9,ARTICULOS!F5:F200,0))),0),ROUNDUP((CALCULO!K9+CALCULO!L9*2+CALCULO!H9*4)*(1+INDEX(ARTICULOS!G5:G200,MATCH(CALCULO!E9,ARTICULOS!F5:F200,0))),0))} | I9: {=ROUND(F9*2*H9/100/INT(E9/(G9/100)),2)} | J9: {=INDEX(CONFECCION!C15:AD30,MATCH(G9,CONFECCION!A15:A30,1),MATCH(H9,CONFECCION!C14:AD14,1))} | K9: {=IF(AND(CALCULO!C9="Servilleta",CALCULO!G9=58),ROUND((G9*2+H9*2)*CONFECCION!B32/100,2),IF(CALCULO!C9="Individual",ROUND((G9*2+H9*2)*CONFECCION!B32/100,2),0))}
A10: {=MATCH(CALCULO!E10,ARTICULOS!F13:F208,0)} | B10: {=INDEX(ARTICULOS!D13:D208,A10)&INDEX(ARTICULOS!E13:E208,A10)} | C10: {=B10&CALCULO!G10} | D10: {=MATCH(C10,COLORES!E10:E4408,0)} | E10: {=INDEX(COLORES!I10:I4408,D10)} | F10: {=INDEX(COLORES!H10:H4408,D10)} | G10: {=IF(CALCULO!I10>0,ROUNDUP(CALCULO!I10*(1+INDEX(ARTICULOS!H5:H200,MATCH(CALCULO!E10,ARTICULOS!F5:F200,0))),0),IF(CALCULO!N10=1,IF(CALCULO!H10=1,ROUNDUP((CALCULO!J10+CALCULO!L10*2+5)*(1+INDEX(ARTICULOS!H5:H200,MATCH(CALCULO!E10,ARTICULOS!F5:F200,0))),0),ROUNDUP((CALCULO!J10+CALCULO!L10*2+CALCULO!H10*4)*(1+INDEX(ARTICULOS!H5:H200,MATCH(CALCULO!E10,ARTICULOS!F5:F200,0))),0)),IF(CALCULO!H10=1,ROUNDUP(CALCULO!J10+CALCULO!L10*2+5,0),ROUNDUP(CALCULO!J10+CALCULO!L10*2+CALCULO!H10*4,0))))} | H10: {=IF(CALCULO!H10=1,ROUNDUP((CALCULO!K10+CALCULO!L10*2+5)*(1+INDEX(ARTICULOS!G5:G200,MATCH(CALCULO!E10,ARTICULOS!F5:F200,0))),0),ROUNDUP((CALCULO!K10+CALCULO!L10*2+CALCULO!H10*4)*(1+INDEX(ARTICULOS!G5:G200,MATCH(CALCULO!E10,ARTICULOS!F5:F200,0))),0))} | I10: {=ROUND(F10*2*H10/100/INT(E10/(G10/100)),2)} | J10: {=IF(CALCULO!H10=1,INDEX(CONFECCION!C15:AD30,MATCH(G10,CONFECCION!A15:A30,1),MATCH(H10,CONFECCION!C14:AD14,1)),2*INDEX(CONFECCION!C15:AD30,MATCH(G10,CONFECCION!A15:A30,1),MATCH(H10,CONFECCION!C14:AD14,1)))} | K10: {=IF(AND(CALCULO!C10="Servilleta",CALCULO!G10=58),ROUND((G10*2+H10*2)*CONFECCION!B32/100,2),IF(CALCULO!C10="Individual",ROUND((G10*2+H10*2)*CONFECCION!B32/100,2),0))}
A11: =IFERROR(IF(CALCULO!E11<>"",MATCH(CALCULO!E11,ARTICULOS!$F$5:$F$700,0),MATCH(CALCULO!F11&TEXT(CALCULO!G11,"0"),COLORES!$E$2:$E$4400,0)),"") | B11: =IFERROR(IF(CALCULO!E11<>"",INDEX(ARTICULOS!$D$5:$D$700,A11)&INDEX(ARTICULOS!$E$5:$E$700,A11),CALCULO!F11),"") | C11: =IFERROR(B11&TEXT(CALCULO!G11,"0"),"") | D11: =IFERROR(MATCH(C11,COLORES!$E$2:$E$4400,0),"") | E11: =IFERROR(INDEX(COLORES!$I$2:$I$4400,D11),"") | F11: =IFERROR(INDEX(COLORES!$H$2:$H$4400,D11),"") | G11: =IFERROR(IF(CALCULO!I11>0,ROUNDUP(CALCULO!I11*(1+IF(CALCULO!N11=1,IFERROR(INDEX(ARTICULOS!$H$5:$H$700,MATCH(INDEX(COLORES!$D$2:$D$4400,D11),ARTICULOS!$F$5:$F$700,0)),0),0)),0),IF(CALCULO!N11=1,IF(CALCULO!H11=1,ROUNDUP((CALCULO!J11+CALCULO!L11*2+5)*(1+IFERROR(INDEX(ARTICULOS!$H$5:$H$700,MATCH(INDEX(COLORES!$D$2:$D$4400,D11),ARTICULOS!$F$5:$F$700,0)),0)),0),ROUNDUP((CALCULO!J11+CALCULO!L11*2+CALCULO!H11*4)*(1+IFERROR(INDEX(ARTICULOS!$H$5:$H$700,MATCH(INDEX(COLORES!$D$2:$D$4400,D11),ARTICULOS!$F$5:$F$700,0)),0)),0)),IF(CALCULO!H11=1,ROUNDUP(CALCULO!J11+CALCULO!L11*2+5,0),ROUNDUP(CALCULO!J11+CALCULO!L11*2+CALCULO!H11*4,0)))),"") | H11: =IFERROR(IF(CALCULO!H11=1,ROUNDUP((CALCULO!K11+CALCULO!L11*2+5)*(1+IF(CALCULO!N11=1,IFERROR(INDEX(ARTICULOS!$G$5:$G$700,MATCH(INDEX(COLORES!$D$2:$D$4400,D11),ARTICULOS!$F$5:$F$700,0)),0),0)),0),ROUNDUP((CALCULO!K11+CALCULO!L11*2+CALCULO!H11*4)*(1+IF(CALCULO!N11=1,IFERROR(INDEX(ARTICULOS!$G$5:$G$700,MATCH(INDEX(COLORES!$D$2:$D$4400,D11),ARTICULOS!$F$5:$F$700,0)),0),0)),0)),"") | I11: =IFERROR(ROUND(F11*2*H11/100/IF(INT(E11/(G11/100))=0,1,INT(E11/(G11/100))),2),"") | J11: =IFERROR(IF(CALCULO!C11="Lito",INDEX(CONFECCION!$C$15:$AD$30,MATCH(G11,CONFECCION!$A$15:$A$30,1),MATCH(H11,CONFECCION!$C$14:$AD$14,1)),IF(INT(E11/(G11/100))=0,2*INDEX(CONFECCION!$C$15:$AD$30,MATCH(G11,CONFECCION!$A$15:$A$30,1),MATCH(H11,CONFECCION!$C$14:$AD$14,1))*3,IF(CALCULO!H11=1,INDEX(CONFECCION!$C$15:$AD$30,MATCH(G11,CONFECCION!$A$15:$A$30,1),MATCH(H11,CONFECCION!$C$14:$AD$14,1)),2*INDEX(CONFECCION!$C$15:$AD$30,MATCH(G11,CONFECCION!$A$15:$A$30,1),MATCH(H11,CONFECCION!$C$14:$AD$14,1))))),"") | K11: =IFERROR(IF(OR(AND(CALCULO!C11="Servilleta",CALCULO!G11=58),CALCULO!C11="Individual"),ROUND((G11*2+H11*2)*CONFECCION!$B$32/100,2),0),"")
A12: =IFERROR(IF(CALCULO!E12<>"",MATCH(CALCULO!E12,ARTICULOS!$F$5:$F$700,0),MATCH(CALCULO!F12&TEXT(CALCULO!G12,"0"),COLORES!$E$2:$E$4400,0)),"") | B12: =IFERROR(IF(CALCULO!E12<>"",INDEX(ARTICULOS!$D$5:$D$700,A12)&INDEX(ARTICULOS!$E$5:$E$700,A12),CALCULO!F12),"") | C12: =IFERROR(B12&TEXT(CALCULO!G12,"0"),"") | D12: =IFERROR(MATCH(C12,COLORES!$E$2:$E$4400,0),"") | E12: =IFERROR(INDEX(COLORES!$I$2:$I$4400,D12),"") | F12: =IFERROR(INDEX(COLORES!$H$2:$H$4400,D12),"") | G12: =IFERROR(IF(CALCULO!I12>0,ROUNDUP(CALCULO!I12*(1+IF(CALCULO!N12=1,IFERROR(INDEX(ARTICULOS!$H$5:$H$700,MATCH(INDEX(COLORES!$D$2:$D$4400,D12),ARTICULOS!$F$5:$F$700,0)),0),0)),0),IF(CALCULO!N12=1,IF(CALCULO!H12=1,ROUNDUP((CALCULO!J12+CALCULO!L12*2+5)*(1+IFERROR(INDEX(ARTICULOS!$H$5:$H$700,MATCH(INDEX(COLORES!$D$2:$D$4400,D12),ARTICULOS!$F$5:$F$700,0)),0)),0),ROUNDUP((CALCULO!J12+CALCULO!L12*2+CALCULO!H12*4)*(1+IFERROR(INDEX(ARTICULOS!$H$5:$H$700,MATCH(INDEX(COLORES!$D$2:$D$4400,D12),ARTICULOS!$F$5:$F$700,0)),0)),0)),IF(CALCULO!H12=1,ROUNDUP(CALCULO!J12+CALCULO!L12*2+5,0),ROUNDUP(CALCULO!J12+CALCULO!L12*2+CALCULO!H12*4,0)))),"") | H12: =IFERROR(IF(CALCULO!H12=1,ROUNDUP((CALCULO!K12+CALCULO!L12*2+5)*(1+IF(CALCULO!N12=1,IFERROR(INDEX(ARTICULOS!$G$5:$G$700,MATCH(INDEX(COLORES!$D$2:$D$4400,D12),ARTICULOS!$F$5:$F$700,0)),0),0)),0),ROUNDUP((CALCULO!K12+CALCULO!L12*2+CALCULO!H12*4)*(1+IF(CALCULO!N12=1,IFERROR(INDEX(ARTICULOS!$G$5:$G$700,MATCH(INDEX(COLORES!$D$2:$D$4400,D12),ARTICULOS!$F$5:$F$700,0)),0),0)),0)),"") | I12: =IFERROR(ROUND(F12*2*H12/100/IF(INT(E12/(G12/100))=0,1,INT(E12/(G12/100))),2),"") | J12: =IFERROR(IF(CALCULO!C12="Lito",INDEX(CONFECCION!$C$15:$AD$30,MATCH(G12,CONFECCION!$A$15:$A$30,1),MATCH(H12,CONFECCION!$C$14:$AD$14,1)),IF(INT(E12/(G12/100))=0,2*INDEX(CONFECCION!$C$15:$AD$30,MATCH(G12,CONFECCION!$A$15:$A$30,1),MATCH(H12,CONFECCION!$C$14:$AD$14,1))*3,IF(CALCULO!H12=1,INDEX(CONFECCION!$C$15:$AD$30,MATCH(G12,CONFECCION!$A$15:$A$30,1),MATCH(H12,CONFECCION!$C$14:$AD$14,1)),2*INDEX(CONFECCION!$C$15:$AD$30,MATCH(G12,CONFECCION!$A$15:$A$30,1),MATCH(H12,CONFECCION!$C$14:$AD$14,1))))),"") | K12: =IFERROR(IF(OR(AND(CALCULO!C12="Servilleta",CALCULO!G12=58),CALCULO!C12="Individual"),ROUND((G12*2+H12*2)*CONFECCION!$B$32/100,2),0),"")
A13: =IFERROR(IF(CALCULO!E13<>"",MATCH(CALCULO!E13,ARTICULOS!$F$5:$F$700,0),MATCH(CALCULO!F13&TEXT(CALCULO!G13,"0"),COLORES!$E$2:$E$4400,0)),"") | B13: =IFERROR(IF(CALCULO!E13<>"",INDEX(ARTICULOS!$D$5:$D$700,A13)&INDEX(ARTICULOS!$E$5:$E$700,A13),CALCULO!F13),"") | C13: =IFERROR(B13&TEXT(CALCULO!G13,"0"),"") | D13: =IFERROR(MATCH(C13,COLORES!$E$2:$E$4400,0),"") | E13: =IFERROR(INDEX(COLORES!$I$2:$I$4400,D13),"") | F13: =IFERROR(INDEX(COLORES!$H$2:$H$4400,D13),"") | G13: =IFERROR(IF(CALCULO!I13>0,ROUNDUP(CALCULO!I13*(1+IF(CALCULO!N13=1,IFERROR(INDEX(ARTICULOS!$H$5:$H$700,MATCH(INDEX(COLORES!$D$2:$D$4400,D13),ARTICULOS!$F$5:$F$700,0)),0),0)),0),IF(CALCULO!N13=1,IF(CALCULO!H13=1,ROUNDUP((CALCULO!J13+CALCULO!L13*2+5)*(1+IFERROR(INDEX(ARTICULOS!$H$5:$H$700,MATCH(INDEX(COLORES!$D$2:$D$4400,D13),ARTICULOS!$F$5:$F$700,0)),0)),0),ROUNDUP((CALCULO!J13+CALCULO!L13*2+CALCULO!H13*4)*(1+IFERROR(INDEX(ARTICULOS!$H$5:$H$700,MATCH(INDEX(COLORES!$D$2:$D$4400,D13),ARTICULOS!$F$5:$F$700,0)),0)),0)),IF(CALCULO!H13=1,ROUNDUP(CALCULO!J13+CALCULO!L13*2+5,0),ROUNDUP(CALCULO!J13+CALCULO!L13*2+CALCULO!H13*4,0)))),"") | H13: =IFERROR(IF(CALCULO!H13=1,ROUNDUP((CALCULO!K13+CALCULO!L13*2+5)*(1+IF(CALCULO!N13=1,IFERROR(INDEX(ARTICULOS!$G$5:$G$700,MATCH(INDEX(COLORES!$D$2:$D$4400,D13),ARTICULOS!$F$5:$F$700,0)),0),0)),0),ROUNDUP((CALCULO!K13+CALCULO!L13*2+CALCULO!H13*4)*(1+IF(CALCULO!N13=1,IFERROR(INDEX(ARTICULOS!$G$5:$G$700,MATCH(INDEX(COLORES!$D$2:$D$4400,D13),ARTICULOS!$F$5:$F$700,0)),0),0)),0)),"") | I13: =IFERROR(ROUND(F13*2*H13/100/IF(INT(E13/(G13/100))=0,1,INT(E13/(G13/100))),2),"") | J13: =IFERROR(IF(CALCULO!C13="Lito",INDEX(CONFECCION!$C$15:$AD$30,MATCH(G13,CONFECCION!$A$15:$A$30,1),MATCH(H13,CONFECCION!$C$14:$AD$14,1)),IF(INT(E13/(G13/100))=0,2*INDEX(CONFECCION!$C$15:$AD$30,MATCH(G13,CONFECCION!$A$15:$A$30,1),MATCH(H13,CONFECCION!$C$14:$AD$14,1))*3,IF(CALCULO!H13=1,INDEX(CONFECCION!$C$15:$AD$30,MATCH(G13,CONFECCION!$A$15:$A$30,1),MATCH(H13,CONFECCION!$C$14:$AD$14,1)),2*INDEX(CONFECCION!$C$15:$AD$30,MATCH(G13,CONFECCION!$A$15:$A$30,1),MATCH(H13,CONFECCION!$C$14:$AD$14,1))))),"") | K13: =IFERROR(IF(OR(AND(CALCULO!C13="Servilleta",CALCULO!G13=58),CALCULO!C13="Individual"),ROUND((G13*2+H13*2)*CONFECCION!$B$32/100,2),0),"")
A14: =IFERROR(IF(CALCULO!E14<>"",MATCH(CALCULO!E14,ARTICULOS!$F$5:$F$700,0),MATCH(CALCULO!F14&TEXT(CALCULO!G14,"0"),COLORES!$E$2:$E$4400,0)),"") | B14: =IFERROR(IF(CALCULO!E14<>"",INDEX(ARTICULOS!$D$5:$D$700,A14)&INDEX(ARTICULOS!$E$5:$E$700,A14),CALCULO!F14),"") | C14: =IFERROR(B14&TEXT(CALCULO!G14,"0"),"") | D14: =IFERROR(MATCH(C14,COLORES!$E$2:$E$4400,0),"") | E14: =IFERROR(INDEX(COLORES!$I$2:$I$4400,D14),"") | F14: =IFERROR(INDEX(COLORES!$H$2:$H$4400,D14),"") | G14: =IFERROR(IF(CALCULO!I14>0,ROUNDUP(CALCULO!I14*(1+IF(CALCULO!N14=1,IFERROR(INDEX(ARTICULOS!$H$5:$H$700,MATCH(INDEX(COLORES!$D$2:$D$4400,D14),ARTICULOS!$F$5:$F$700,0)),0),0)),0),IF(CALCULO!N14=1,IF(CALCULO!H14=1,ROUNDUP((CALCULO!J14+CALCULO!L14*2+5)*(1+IFERROR(INDEX(ARTICULOS!$H$5:$H$700,MATCH(INDEX(COLORES!$D$2:$D$4400,D14),ARTICULOS!$F$5:$F$700,0)),0)),0),ROUNDUP((CALCULO!J14+CALCULO!L14*2+CALCULO!H14*4)*(1+IFERROR(INDEX(ARTICULOS!$H$5:$H$700,MATCH(INDEX(COLORES!$D$2:$D$4400,D14),ARTICULOS!$F$5:$F$700,0)),0)),0)),IF(CALCULO!H14=1,ROUNDUP(CALCULO!J14+CALCULO!L14*2+5,0),ROUNDUP(CALCULO!J14+CALCULO!L14*2+CALCULO!H14*4,0)))),"") | H14: =IFERROR(IF(CALCULO!H14=1,ROUNDUP((CALCULO!K14+CALCULO!L14*2+5)*(1+IF(CALCULO!N14=1,IFERROR(INDEX(ARTICULOS!$G$5:$G$700,MATCH(INDEX(COLORES!$D$2:$D$4400,D14),ARTICULOS!$F$5:$F$700,0)),0),0)),0),ROUNDUP((CALCULO!K14+CALCULO!L14*2+CALCULO!H14*4)*(1+IF(CALCULO!N14=1,IFERROR(INDEX(ARTICULOS!$G$5:$G$700,MATCH(INDEX(COLORES!$D$2:$D$4400,D14),ARTICULOS!$F$5:$F$700,0)),0),0)),0)),"") | I14: =IFERROR(ROUND(F14*2*H14/100/IF(INT(E14/(G14/100))=0,1,INT(E14/(G14/100))),2),"") | J14: =IFERROR(IF(CALCULO!C14="Lito",INDEX(CONFECCION!$C$15:$AD$30,MATCH(G14,CONFECCION!$A$15:$A$30,1),MATCH(H14,CONFECCION!$C$14:$AD$14,1)),IF(INT(E14/(G14/100))=0,2*INDEX(CONFECCION!$C$15:$AD$30,MATCH(G14,CONFECCION!$A$15:$A$30,1),MATCH(H14,CONFECCION!$C$14:$AD$14,1))*3,IF(CALCULO!H14=1,INDEX(CONFECCION!$C$15:$AD$30,MATCH(G14,CONFECCION!$A$15:$A$30,1),MATCH(H14,CONFECCION!$C$14:$AD$14,1)),2*INDEX(CONFECCION!$C$15:$AD$30,MATCH(G14,CONFECCION!$A$15:$A$30,1),MATCH(H14,CONFECCION!$C$14:$AD$14,1))))),"") | K14: =IFERROR(IF(OR(AND(CALCULO!C14="Servilleta",CALCULO!G14=58),CALCULO!C14="Individual"),ROUND((G14*2+H14*2)*CONFECCION!$B$32/100,2),0),"")
A15: =IFERROR(IF(CALCULO!E15<>"",MATCH(CALCULO!E15,ARTICULOS!$F$5:$F$700,0),MATCH(CALCULO!F15&TEXT(CALCULO!G15,"0"),COLORES!$E$2:$E$4400,0)),"") | B15: =IFERROR(IF(CALCULO!E15<>"",INDEX(ARTICULOS!$D$5:$D$700,A15)&INDEX(ARTICULOS!$E$5:$E$700,A15),CALCULO!F15),"") | C15: =IFERROR(B15&TEXT(CALCULO!G15,"0"),"") | D15: =IFERROR(MATCH(C15,COLORES!$E$2:$E$4400,0),"") | E15: =IFERROR(INDEX(COLORES!$I$2:$I$4400,D15),"") | F15: =IFERROR(INDEX(COLORES!$H$2:$H$4400,D15),"") | G15: =IFERROR(IF(CALCULO!I15>0,ROUNDUP(CALCULO!I15*(1+IF(CALCULO!N15=1,IFERROR(INDEX(ARTICULOS!$H$5:$H$700,MATCH(INDEX(COLORES!$D$2:$D$4400,D15),ARTICULOS!$F$5:$F$700,0)),0),0)),0),IF(CALCULO!N15=1,IF(CALCULO!H15=1,ROUNDUP((CALCULO!J15+CALCULO!L15*2+5)*(1+IFERROR(INDEX(ARTICULOS!$H$5:$H$700,MATCH(INDEX(COLORES!$D$2:$D$4400,D15),ARTICULOS!$F$5:$F$700,0)),0)),0),ROUNDUP((CALCULO!J15+CALCULO!L15*2+CALCULO!H15*4)*(1+IFERROR(INDEX(ARTICULOS!$H$5:$H$700,MATCH(INDEX(COLORES!$D$2:$D$4400,D15),ARTICULOS!$F$5:$F$700,0)),0)),0)),IF(CALCULO!H15=1,ROUNDUP(CALCULO!J15+CALCULO!L15*2+5,0),ROUNDUP(CALCULO!J15+CALCULO!L15*2+CALCULO!H15*4,0)))),"") | H15: =IFERROR(IF(CALCULO!H15=1,ROUNDUP((CALCULO!K15+CALCULO!L15*2+5)*(1+IF(CALCULO!N15=1,IFERROR(INDEX(ARTICULOS!$G$5:$G$700,MATCH(INDEX(COLORES!$D$2:$D$4400,D15),ARTICULOS!$F$5:$F$700,0)),0),0)),0),ROUNDUP((CALCULO!K15+CALCULO!L15*2+CALCULO!H15*4)*(1+IF(CALCULO!N15=1,IFERROR(INDEX(ARTICULOS!$G$5:$G$700,MATCH(INDEX(COLORES!$D$2:$D$4400,D15),ARTICULOS!$F$5:$F$700,0)),0),0)),0)),"") | I15: =IFERROR(ROUND(F15*2*H15/100/IF(INT(E15/(G15/100))=0,1,INT(E15/(G15/100))),2),"") | J15: =IFERROR(IF(CALCULO!C15="Lito",INDEX(CONFECCION!$C$15:$AD$30,MATCH(G15,CONFECCION!$A$15:$A$30,1),MATCH(H15,CONFECCION!$C$14:$AD$14,1)),IF(INT(E15/(G15/100))=0,2*INDEX(CONFECCION!$C$15:$AD$30,MATCH(G15,CONFECCION!$A$15:$A$30,1),MATCH(H15,CONFECCION!$C$14:$AD$14,1))*3,IF(CALCULO!H15=1,INDEX(CONFECCION!$C$15:$AD$30,MATCH(G15,CONFECCION!$A$15:$A$30,1),MATCH(H15,CONFECCION!$C$14:$AD$14,1)),2*INDEX(CONFECCION!$C$15:$AD$30,MATCH(G15,CONFECCION!$A$15:$A$30,1),MATCH(H15,CONFECCION!$C$14:$AD$14,1))))),"") | K15: =IFERROR(IF(OR(AND(CALCULO!C15="Servilleta",CALCULO!G15=58),CALCULO!C15="Individual"),ROUND((G15*2+H15*2)*CONFECCION!$B$32/100,2),0),"")
