Workbook

Sheet DATOS
A3: PRESUPUESO Nº: | B3: 110125
A4: CLIENTE: | B4: CLIENTE
A5: FECHA: | B5: =TODAY()
A6: COMERCIAL: | B6: MARIO
A7: REFERNCIA:
A8: DATOS FISCALES
A9: SOCIEDAD: | B9: CLIENTE
A10: NIF:
A11: DIRECCION:
A12: CORREO:
A13: PERSONA DE CONTACTO:
A14: TELEFONO:

Sheet PRESUPUESTO
A3: PRESU. Nº: | C3: =DATOS!B3 | AP3: PRESUPUESTO: | AR3: =C3
A4: CLIENTE: | C4: =DATOS!B4 | AP4: CLIENTE: | AR4: =C4
A5: FECHA: | C5: =DATOS!B5 | AP5: Con Fecha: | AR5: =C5 | AT5: COMERCIAL:
A6: COMERCIAL: | C6: =DATOS!B6 | AP6: Validez hasta: | AR6: =AR5+10 | AT6: REFERENCIA:
A7: REFERENCIA: | C7: =DATOS!B7
A8: DATOS DE TEJIDO | L8: TAMAÑO DEL ARTICULO A CONFECCIONAR | S8: MEDIDA TERMINADA | V8: DOBLADILLO | W8: MEDIDA CON DOBLAD. | Y8: ENCOG. (1/0) | Z8: MEDIDA CORTE | AB8: REDONDO (1/2) | AC8: EMPALME | AD8: REF. EMPALME | AE8: NUM. EMPALM | AF8: NUM. EMPALM. | AG8: CONFECCIÓN | AH8: COBRA SOBRANTE | AI8: TEJIDO | AJ8: FESTÓN (1/2) | AK8: PRECIO | AL8: COLOR | AM8: PICOS REDOND
A9: CANTIDAD | B9: MARGEN | C9: NOMBRE ARTICULO | D9: COLOR | E9: REF. 1 | F9: REF. 2 | G9: REF. 3 | I9: COSTE | J9: ANCHO PIEZA | K9: PRECIO VENTA | L9: ARTICULO (1/2/3/4/5/6) | M9: ANCHO | N9: LARGO | O9: REDONDA | P9: ALTO DE LA MESA | Q9: AÑADIR LARGO | R9: CAIDA MANTEL | S9: MEDIDA MESA | T9: ANCHO | U9: LARGO | V9: (1) Sencillo o Medida | W9: ANCHO | X9: LARGO | Y9: (1) Si (0) No | Z9: ANCHO | AA9: LARGO | AB9: (1) Si (2) No | AC9: (1) Si (2) No | AF9: SOLO SIN SON MENOS | AH9: (1) Si (2) No | AJ9: (1) Si (2) No | AK9: FESTÓN | AL9: FESTÓN | AM9: (1) Si (2) No | AP9: CINTA | AQ9: MESA | AR9: ARTICULO | AS9: MEDIDA USO | AT9: DESCRIPCION ARTICULO | AU9: COLOR | AV9: DOBLADILLO | AX9: MEDIDA DE CORTE | AY9: PRECIO UNITARIO | AZ9: CANTIDAD | BA9: TOTAL
A10: 0 | B10: 1 | D10: 1 | E10: =MATCH(C10,ARTICULOS!$F$10:$F$699,0) | F10: =+VLOOKUP(E10,ARTICULOS!$D$10:$I$699,6) | G10: =+F10&D10 | H10: =+MATCH(G10,COLORES!$E$7:$E$4394,0) | I10: =VLOOKUP(H10,COLORES!$A$7:$I$4394,8) | J10: =VLOOKUP(H10,COLORES!$A$7:$I$4394,9) | K10: =I10*(1+B10) | L10: 0 | M10: 0 | N10: 0 | O10: 0 | P10: 0 | Q10: 0 | S10: =IF(P10>0,IF(O10>0,"(/)"&O10&"*"&P10&IF(Q10>0,"+"&Q10,IF(Q10=0,"",Q10)),+M10&"*"&N10&"*"&P10&IF(Q10>0,"+"&Q10,IF(Q10=0,"",Q10))),"") | T10: =+IF(O10>0,O10+R10*2,M10+R10*2)+P10*2+Q10*2 | U10: =+IF(O10>0,O10+R10*2,N10+R10*2)+P10*2+Q10*2 | W10: =IF(V10=1,T10+5,T10+(V10*4)) | X10: =IF(V10=1,U10+5,U10+(V10*4)) | Y10: 0 | Z10: =IF(Y10=1,ROUNDUP(W10*(1+VLOOKUP(E10,ARTICULOS!$D$10:$H$699,5)),0),W10) | AA10: =IF(Y10=1,ROUNDUP(X10*(1+VLOOKUP(E10,ARTICULOS!$D$10:$H$699,4)),0),X10) | AB10: 2 | AD10: =IF(AC10=1,J10*100&Z10,"") | AE10: =IF(AC10=1,VLOOKUP(AD10,EMPALME!$C$2:$F$33,4),"") | AG10: =IF(L10=3,IF(V10=1,CONFECCION!$C$18,CONFECCION!$C$18*2),IF(V10=1,HLOOKUP(AA10,CONFECCION!$C$17:$AD$33,VLOOKUP(Z10,CONFECCION!$A$18:$B$33,2)-16),2*HLOOKUP(AA10,CONFECCION!$C$17:$AD$33,VLOOKUP(Z10,CONFECCION!$A$18:$B$33,2)-16)))*IF(AC10=1,3,1) | AI10: =IF(AC10=1,AA10/100*K10+IF(AF10>0,K10*(VLOOKUP(AD10,EMPALME!$C$2:$D$33,2)/100)/AF10,K10*(VLOOKUP(AD10,EMPALME!$C$2:$D$33,2)/100)/VLOOKUP(AD10,EMPALME!$C$2:$F$33,4)),IF(AH10=2,ROUND((K10*(AA10/100)-(I10/10)*INT((AA10/100)/0.55)*INT((J10-(Z10/100)*INT(J10/(Z10/100)))/0.55))/INT(J10/(Z10/100)),2),ROUND(K10*(AA10/100)/INT(J10/(Z10/100)),2))) | AJ10: 2 | AK10: =ROUND(IF(AJ10=2,0,((Z10*2)+(AA10*2))*CONFECCION!$B$35/100),2) | AM10: 2 | AQ10: =IF(S10=0,"",S10) | AR10: =IF(A10=0,"",VLOOKUP(L10,ARTICULOS!$A$10:$B$19,2)) | AS10: =IF(A10=0,"",T10&" * "&U10)&IF(AM10=1," PR","") | AT10: =IF(A10=0,"",VLOOKUP(E10,ARTICULOS!$D$10:$F$699,3)) | AU10: =IF(A10=0,"","c/ "&D10&" "&VLOOKUP(H10,COLORES!$A$7:$G$4394,7)) | AV10: =IF(A10=0,"",IF(V10=1,"Dobl. Sencillo","Dobl. "&V10&" cm.")) | AW10: =+IF(Y10=1,"SI","") | AX10: =IF(A10=0,"",IF(AB10=2,Z10&" * "&AA10,IF(Z10=AA10,"Redondo "&Z10&" * "&AA10,"Ovalado "&Z10&" * "&AA10))) | AY10: =IF(A10=0,"",AG10+AI10+AK10) | AZ10: =IF(A10=0,"",A10) | BA10: =IF(A10=0,"",ROUND(AY10*AZ10,2))
A11: 0 | B11: 1 | D11: 1 | E11: =MATCH(C11,ARTICULOS!$F$10:$F$699,0) | F11: =+VLOOKUP(E11,ARTICULOS!$D$10:$I$699,6) | G11: =+F11&D11 | H11: =+MATCH(G11,COLORES!$E$7:$E$4394,0) | I11: =VLOOKUP(H11,COLORES!$A$7:$I$4394,8) | J11: =VLOOKUP(H11,COLORES!$A$7:$I$4394,9) | K11: =I11*(1+B11) | L11: 0 | M11: 0 | N11: 0 | O11: 0 | P11: 0 | Q11: 0 | S11: =IF(P11>0,IF(O11>0,"(/)"&O11&"*"&P11&IF(Q11>0,"+"&Q11,IF(Q11=0,"",Q11)),+M11&"*"&N11&"*"&P11&IF(Q11>0,"+"&Q11,IF(Q11=0,"",Q11))),"") | T11: =+IF(O11>0,O11+R11*2,M11+R11*2)+P11*2+Q11*2 | U11: =+IF(O11>0,O11+R11*2,N11+R11*2)+P11*2+Q11*2 | W11: =IF(V11=1,T11+5,T11+(V11*4)) | X11: =IF(V11=1,U11+5,U11+(V11*4)) | Y11: 0 | Z11: =IF(Y11=1,ROUNDUP(W11*(1+VLOOKUP(E11,ARTICULOS!$D$10:$H$699,5)),0),W11) | AA11: =IF(Y11=1,ROUNDUP(X11*(1+VLOOKUP(E11,ARTICULOS!$D$10:$H$699,4)),0),X11) | AB11: 2 | AD11: =IF(AC11=1,J11*100&Z11,"") | AE11: =IF(AC11=1,VLOOKUP(AD11,EMPALME!$C$2:$F$33,4),"") | AG11: =IF(L11=3,IF(V11=1,CONFECCION!$C$18,CONFECCION!$C$18*2),IF(V11=1,HLOOKUP(AA11,CONFECCION!$C$17:$AD$33,VLOOKUP(Z11,CONFECCION!$A$18:$B$33,2)-16),2*HLOOKUP(AA11,CONFECCION!$C$17:$AD$33,VLOOKUP(Z11,CONFECCION!$A$18:$B$33,2)-16)))*IF(AC11=1,3,1) | AI11: =IF(AC11=1,AA11/100*K11+IF(AF11>0,K11*(VLOOKUP(AD11,EMPALME!$C$2:$D$33,2)/100)/AF11,K11*(VLOOKUP(AD11,EMPALME!$C$2:$D$33,2)/100)/VLOOKUP(AD11,EMPALME!$C$2:$F$33,4)),IF(AH11=2,ROUND((K11*(AA11/100)-(I11/10)*INT((AA11/100)/0.55)*INT((J11-(Z11/100)*INT(J11/(Z11/100)))/0.55))/INT(J11/(Z11/100)),2),ROUND(K11*(AA11/100)/INT(J11/(Z11/100)),2))) | AJ11: 2 | AK11: =ROUND(IF(AJ11=2,0,((Z11*2)+(AA11*2))*CONFECCION!$B$35/100),2) | AM11: 2 | AQ11: =IF(S11=0,"",S11) | AR11: =IF(A11=0,"",VLOOKUP(L11,ARTICULOS!$A$10:$B$19,2)) | AS11: =IF(A11=0,"",T11&" * "&U11)&IF(AM11=1," PR","") | AT11: =IF(A11=0,"",VLOOKUP(E11,ARTICULOS!$D$10:$F$699,3)) | AU11: =IF(A11=0,"","c/ "&D11&" "&VLOOKUP(H11,COLORES!$A$7:$G$4394,7)) | AV11: =IF(A11=0,"",IF(V11=1,"Dobl. Sencillo","Dobl. "&V11&" cm.")) | AW11: =+IF(Y11=1,"SI","") | AX11: =IF(A11=0,"",IF(AB11=2,Z11&" * "&AA11,IF(Z11=AA11,"Redondo "&Z11&" * "&AA11,"Ovalado "&Z11&" * "&AA11))) | AY11: =IF(A11=0,"",AG11+AI11+AK11) | AZ11: =IF(A11=0,"",A11) | BA11: =IF(A11=0,"",ROUND(AY11*AZ11,2))
A12: 0 | B12: 1 | D12: 1 | E12: =MATCH(C12,ARTICULOS!$F$10:$F$699,0) | F12: =+VLOOKUP(E12,ARTICULOS!$D$10:$I$699,6) | G12: =+F12&D12 | H12: =+MATCH(G12,COLORES!$E$7:$E$4394,0) | I12: =VLOOKUP(H12,COLORES!$A$7:$I$4394,8) | J12: =VLOOKUP(H12,COLORES!$A$7:$I$4394,9) | K12: =I12*(1+B12) | L12: 0 | M12: 0 | N12: 0 | O12: 0 | P12: 0 | Q12: 0 | S12: =IF(P12>0,IF(O12>0,"(/)"&O12&"*"&P12&IF(Q12>0,"+"&Q12,IF(Q12=0,"",Q12)),+M12&"*"&N12&"*"&P12&IF(Q12>0,"+"&Q12,IF(Q12=0,"",Q12))),"") | T12: =+IF(O12>0,O12+R12*2,M12+R12*2)+P12*2+Q12*2 | U12: =+IF(O12>0,O12+R12*2,N12+R12*2)+P12*2+Q12*2 | W12: =IF(V12=1,T12+5,T12+(V12*4)) | X12: =IF(V12=1,U12+5,U12+(V12*4)) | Y12: 0 | Z12: =IF(Y12=1,ROUNDUP(W12*(1+VLOOKUP(E12,ARTICULOS!$D$10:$H$699,5)),0),W12) | AA12: =IF(Y12=1,ROUNDUP(X12*(1+VLOOKUP(E12,ARTICULOS!$D$10:$H$699,4)),0),X12) | AB12: 2 | AD12: =IF(AC12=1,J12*100&Z12,"") | AE12: =IF(AC12=1,VLOOKUP(AD12,EMPALME!$C$2:$F$33,4),"") | AG12: =IF(L12=3,IF(V12=1,CONFECCION!$C$18,CONFECCION!$C$18*2),IF(V12=1,HLOOKUP(AA12,CONFECCION!$C$17:$AD$33,VLOOKUP(Z12,CONFECCION!$A$18:$B$33,2)-16),2*HLOOKUP(AA12,CONFECCION!$C$17:$AD$33,VLOOKUP(Z12,CONFECCION!$A$18:$B$33,2)-16)))*IF(AC12=1,3,1) | AI12: =IF(AC12=1,AA12/100*K12+IF(AF12>0,K12*(VLOOKUP(AD12,EMPALME!$C$2:$D$33,2)/100)/AF12,K12*(VLOOKUP(AD12,EMPALME!$C$2:$D$33,2)/100)/VLOOKUP(AD12,EMPALME!$C$2:$F$33,4)),IF(AH12=2,ROUND((K12*(AA12/100)-(I12/10)*INT((AA12/100)/0.55)*INT((J12-(Z12/100)*INT(J12/(Z12/100)))/0.55))/INT(J12/(Z12/100)),2),ROUND(K12*(AA12/100)/INT(J12/(Z12/100)),2))) | AJ12: 2 | AK12: =ROUND(IF(AJ12=2,0,((Z12*2)+(AA12*2))*CONFECCION!$B$35/100),2) | AM12: 2 | AQ12: =IF(S12=0,"",S12) | AR12: =IF(A12=0,"",VLOOKUP(L12,ARTICULOS!$A$10:$B$19,2)) | AS12: =IF(A12=0,"",T12&" * "&U12)&IF(AM12=1," PR","") | AT12: =IF(A12=0,"",VLOOKUP(E12,ARTICULOS!$D$10:$F$699,3)) | AU12: =IF(A12=0,"","c/ "&D12&" "&VLOOKUP(H12,COLORES!$A$7:$G$4394,7)) | AV12: =IF(A12=0,"",IF(V12=1,"Dobl. Sencillo","Dobl. "&V12&" cm.")) | AW12: =+IF(Y12=1,"SI","") | AX12: =IF(A12=0,"",IF(AB12=2,Z12&" * "&AA12,IF(Z12=AA12,"Redondo "&Z12&" * "&AA12,"Ovalado "&Z12&" * "&AA12))) | AY12: =IF(A12=0,"",AG12+AI12+AK12) | AZ12: =IF(A12=0,"",A12) | BA12: =IF(A12=0,"",ROUND(AY12*AZ12,2))
A13: 0 | B13: 1 | D13: 1 | E13: =MATCH(C13,ARTICULOS!$F$10:$F$699,0) | F13: =+VLOOKUP(E13,ARTICULOS!$D$10:$I$699,6) | G13: =+F13&D13 | H13: =+MATCH(G13,COLORES!$E$7:$E$4394,0) | I13: =VLOOKUP(H13,COLORES!$A$7:$I$4394,8) | J13: =VLOOKUP(H13,COLORES!$A$7:$I$4394,9) | K13: =I13*(1+B13) | L13: 0 | M13: 0 | N13: 0 | O13: 0 | P13: 0 | Q13: 0 | S13: =IF(P13>0,IF(O13>0,"(/)"&O13&"*"&P13&IF(Q13>0,"+"&Q13,IF(Q13=0,"",Q13)),+M13&"*"&N13&"*"&P13&IF(Q13>0,"+"&Q13,IF(Q13=0,"",Q13))),"") | T13: =+IF(O13>0,O13+R13*2,M13+R13*2)+P13*2+Q13*2 | U13: =+IF(O13>0,O13+R13*2,N13+R13*2)+P13*2+Q13*2 | W13: =IF(V13=1,T13+5,T13+(V13*4)) | X13: =IF(V13=1,U13+5,U13+(V13*4)) | Y13: 0 | Z13: =IF(Y13=1,ROUNDUP(W13*(1+VLOOKUP(E13,ARTICULOS!$D$10:$H$699,5)),0),W13) | AA13: =IF(Y13=1,ROUNDUP(X13*(1+VLOOKUP(E13,ARTICULOS!$D$10:$H$699,4)),0),X13) | AB13: 2 | AD13: =IF(AC13=1,J13*100&Z13,"") | AE13: =IF(AC13=1,VLOOKUP(AD13,EMPALME!$C$2:$F$33,4),"") | AG13: =IF(L13=3,IF(V13=1,CONFECCION!$C$18,CONFECCION!$C$18*2),IF(V13=1,HLOOKUP(AA13,CONFECCION!$C$17:$AD$33,VLOOKUP(Z13,CONFECCION!$A$18:$B$33,2)-16),2*HLOOKUP(AA13,CONFECCION!$C$17:$AD$33,VLOOKUP(Z13,CONFECCION!$A$18:$B$33,2)-16)))*IF(AC13=1,3,1) | AI13: =IF(AC13=1,AA13/100*K13+IF(AF13>0,K13*(VLOOKUP(AD13,EMPALME!$C$2:$D$33,2)/100)/AF13,K13*(VLOOKUP(AD13,EMPALME!$C$2:$D$33,2)/100)/VLOOKUP(AD13,EMPALME!$C$2:$F$33,4)),IF(AH13=2,ROUND((K13*(AA13/100)-(I13/10)*INT((AA13/100)/0.55)*INT((J13-(Z13/100)*INT(J13/(Z13/100)))/0.55))/INT(J13/(Z13/100)),2),ROUND(K13*(AA13/100)/INT(J13/(Z13/100)),2))) | AJ13: 2 | AK13: =ROUND(IF(AJ13=2,0,((Z13*2)+(AA13*2))*CONFECCION!$B$35/100),2) | AM13: 2 | AQ13: =IF(S13=0,"",S13) | AR13: =IF(A13=0,"",VLOOKUP(L13,ARTICULOS!$A$10:$B$19,2)) | AS13: =IF(A13=0,"",T13&" * "&U13)&IF(AM13=1," PR","") | AT13: =IF(A13=0,"",VLOOKUP(E13,ARTICULOS!$D$10:$F$699,3)) | AU13: =IF(A13=0,"","c/ "&D13&" "&VLOOKUP(H13,COLORES!$A$7:$G$4394,7)) | AV13: =IF(A13=0,"",IF(V13=1,"Dobl. Sencillo","Dobl. "&V13&" cm.")) | AW13: =+IF(Y13=1,"SI","") | AX13: =IF(A13=0,"",IF(AB13=2,Z13&" * "&AA13,IF(Z13=AA13,"Redondo "&Z13&" * "&AA13,"Ovalado "&Z13&" * "&AA13))) | AY13: =IF(A13=0,"",AG13+AI13+AK13) | AZ13: =IF(A13=0,"",A13) | BA13: =IF(A13=0,"",ROUND(AY13*AZ13,2))
A14: 0 | B14: 1 | D14: 1 | E14: =MATCH(C14,ARTICULOS!$F$10:$F$699,0) | F14: =+VLOOKUP(E14,ARTICULOS!$D$10:$I$699,6) | G14: =+F14&D14 | H14: =+MATCH(G14,COLORES!$E$7:$E$4394,0) | I14: =VLOOKUP(H14,COLORES!$A$7:$I$4394,8) | J14: =VLOOKUP(H14,COLORES!$A$7:$I$4394,9) | K14: =I14*(1+B14) | L14: 0 | M14: 0 | N14: 0 | O14: 0 | P14: 0 | Q14: 0 | S14: =IF(P14>0,IF(O14>0,"(/)"&O14&"*"&P14&IF(Q14>0,"+"&Q14,IF(Q14=0,"",Q14)),+M14&"*"&N14&"*"&P14&IF(Q14>0,"+"&Q14,IF(Q14=0,"",Q14))),"") | T14: =+IF(O14>0,O14+R14*2,M14+R14*2)+P14*2+Q14*2 | U14: =+IF(O14>0,O14+R14*2,N14+R14*2)+P14*2+Q14*2 | W14: =IF(V14=1,T14+5,T14+(V14*4)) | X14: =IF(V14=1,U14+5,U14+(V14*4)) | Y14: 0 | Z14: =IF(Y14=1,ROUNDUP(W14*(1+VLOOKUP(E14,ARTICULOS!$D$10:$H$699,5)),0),W14) | AA14: =IF(Y14=1,ROUNDUP(X14*(1+VLOOKUP(E14,ARTICULOS!$D$10:$H$699,4)),0),X14) | AB14: 2 | AD14: =IF(AC14=1,J14*100&Z14,"") | AE14: =IF(AC14=1,VLOOKUP(AD14,EMPALME!$C$2:$F$33,4),"") | AG14: =IF(L14=3,IF(V14=1,CONFECCION!$C$18,CONFECCION!$C$18*2),IF(V14=1,HLOOKUP(AA14,CONFECCION!$C$17:$AD$33,VLOOKUP(Z14,CONFECCION!$A$18:$B$33,2)-16),2*HLOOKUP(AA14,CONFECCION!$C$17:$AD$33,VLOOKUP(Z14,CONFECCION!$A$18:$B$33,2)-16)))*IF(AC14=1,3,1) | AI14: =IF(AC14=1,AA14/100*K14+IF(AF14>0,K14*(VLOOKUP(AD14,EMPALME!$C$2:$D$33,2)/100)/AF14,K14*(VLOOKUP(AD14,EMPALME!$C$2:$D$33,2)/100)/VLOOKUP(AD14,EMPALME!$C$2:$F$33,4)),IF(AH14=2,ROUND((K14*(AA14/100)-(I14/10)*INT((AA14/100)/0.55)*INT((J14-(Z14/100)*INT(J14/(Z14/100)))/0.55))/INT(J14/(Z14/100)),2),ROUND(K14*(AA14/100)/INT(J14/(Z14/100)),2))) | AJ14: 2 | AK14: =ROUND(IF(AJ14=2,0,((Z14*2)+(AA14*2))*CONFECCION!$B$35/100),2) | AM14: 2 | AQ14: =IF(S14=0,"",S14) | AR14: =IF(A14=0,"",VLOOKUP(L14,ARTICULOS!$A$10:$B$19,2)) | AS14: =IF(A14=0,"",T14&" * "&U14)&IF(AM14=1," PR","") | AT14: =IF(A14=0,"",VLOOKUP(E14,ARTICULOS!$D$10:$F$699,3)) | AU14: =IF(A14=0,"","c/ "&D14&" "&VLOOKUP(H14,COLORES!$A$7:$G$4394,7)) | AV14: =IF(A14=0,"",IF(V14=1,"Dobl. Sencillo","Dobl. "&V14&" cm.")) | AW14: =+IF(Y14=1,"SI","") | AX14: =IF(A14=0,"",IF(AB14=2,Z14&" * "&AA14,IF(Z14=AA14,"Redondo "&Z14&" * "&AA14,"Ovalado "&Z14&" * "&AA14))) | AY14: =IF(A14=0,"",AG14+AI14+AK14) | AZ14: =IF(A14=0,"",A14) | BA14: =IF(A14=0,"",ROUND(AY14*AZ14,2))
A15: 0 | B15: 1 | D15: 1 | E15: =MATCH(C15,ARTICULOS!$F$10:$F$699,0) | F15: =+VLOOKUP(E15,ARTICULOS!$D$10:$I$699,6) | G15: =+F15&D15 | H15: =+MATCH(G15,COLORES!$E$7:$E$4394,0) | I15: =VLOOKUP(H15,COLORES!$A$7:$I$4394,8) | J15: =VLOOKUP(H15,COLORES!$A$7:$I$4394,9) | K15: =I15*(1+B15) | L15: 0 | M15: 0 | N15: 0 | O15: 0 | P15: 0 | Q15: 0 | S15: =IF(P15>0,IF(O15>0,"(/)"&O15&"*"&P15&IF(Q15>0,"+"&Q15,IF(Q15=0,"",Q15)),+M15&"*"&N15&"*"&P15&IF(Q15>0,"+"&Q15,IF(Q15=0,"",Q15))),"") | T15: =+IF(O15>0,O15+R15*2,M15+R15*2)+P15*2+Q15*2 | U15: =+IF(O15>0,O15+R15*2,N15+R15*2)+P15*2+Q15*2 | W15: =IF(V15=1,T15+5,T15+(V15*4)) | X15: =IF(V15=1,U15+5,U15+(V15*4)) | Y15: 0 | Z15: =IF(Y15=1,ROUNDUP(W15*(1+VLOOKUP(E15,ARTICULOS!$D$10:$H$699,5)),0),W15) | AA15: =IF(Y15=1,ROUNDUP(X15*(1+VLOOKUP(E15,ARTICULOS!$D$10:$H$699,4)),0),X15) | AB15: 2 | AD15: =IF(AC15=1,J15*100&Z15,"") | AE15: =IF(AC15=1,VLOOKUP(AD15,EMPALME!$C$2:$F$33,4),"") | AG15: =IF(L15=3,IF(V15=1,CONFECCION!$C$18,CONFECCION!$C$18*2),IF(V15=1,HLOOKUP(AA15,CONFECCION!$C$17:$AD$33,VLOOKUP(Z15,CONFECCION!$A$18:$B$33,2)-16),2*HLOOKUP(AA15,CONFECCION!$C$17:$AD$33,VLOOKUP(Z15,CONFECCION!$A$18:$B$33,2)-16)))*IF(AC15=1,3,1) | AI15: =IF(AC15=1,AA15/100*K15+IF(AF15>0,K15*(VLOOKUP(AD15,EMPALME!$C$2:$D$33,2)/100)/AF15,K15*(VLOOKUP(AD15,EMPALME!$C$2:$D$33,2)/100)/VLOOKUP(AD15,EMPALME!$C$2:$F$33,4)),IF(AH15=2,ROUND((K15*(AA15/100)-(I15/10)*INT((AA15/100)/0.55)*INT((J15-(Z15/100)*INT(J15/(Z15/100)))/0.55))/INT(J15/(Z15/100)),2),ROUND(K15*(AA15/100)/INT(J15/(Z15/100)),2))) | AJ15: 2 | AK15: =ROUND(IF(AJ15=2,0,((Z15*2)+(AA15*2))*CONFECCION!$B$35/100),2) | AM15: 2 | AQ15: =IF(S15=0,"",S15) | AR15: =IF(A15=0,"",VLOOKUP(L15,ARTICULOS!$A$10:$B$19,2)) | AS15: =IF(A15=0,"",T15&" * "&U15)&IF(AM15=1," PR","") | AT15: =IF(A15=0,"",VLOOKUP(E15,ARTICULOS!$D$10:$F$699,3)) | AU15: =IF(A15=0,"","c/ "&D15&" "&VLOOKUP(H15,COLORES!$A$7:$G$4394,7)) | AV15: =IF(A15=0,"",IF(V15=1,"Dobl. Sencillo","Dobl. "&V15&" cm.")) | AW15: =+IF(Y15=1,"SI","") | AX15: =IF(A15=0,"",IF(AB15=2,Z15&" * "&AA15,IF(Z15=AA15,"Redondo "&Z15&" * "&AA15,"Ovalado "&Z15&" * "&AA15))) | AY15: =IF(A15=0,"",AG15+AI15+AK15) | AZ15: =IF(A15=0,"",A15) | BA15: =IF(A15=0,"",ROUND(AY15*AZ15,2))
A16: 0 | B16: 1 | D16: 1 | E16: =MATCH(C16,ARTICULOS!$F$10:$F$699,0) | F16: =+VLOOKUP(E16,ARTICULOS!$D$10:$I$699,6) | G16: =+F16&D16 | H16: =+MATCH(G16,COLORES!$E$7:$E$4394,0) | I16: =VLOOKUP(H16,COLORES!$A$7:$I$4394,8) | J16: =VLOOKUP(H16,COLORES!$A$7:$I$4394,9) | K16: =I16*(1+B16) | L16: 0 | M16: 0 | N16: 0 | O16: 0 | P16: 0 | Q16: 0 | S16: =IF(P16>0,IF(O16>0,"(/)"&O16&"*"&P16&IF(Q16>0,"+"&Q16,IF(Q16=0,"",Q16)),+M16&"*"&N16&"*"&P16&IF(Q16>0,"+"&Q16,IF(Q16=0,"",Q16))),"") | T16: =+IF(O16>0,O16+R16*2,M16+R16*2)+P16*2+Q16*2 | U16: =+IF(O16>0,O16+R16*2,N16+R16*2)+P16*2+Q16*2 | W16: =IF(V16=1,T16+5,T16+(V16*4)) | X16: =IF(V16=1,U16+5,U16+(V16*4)) | Y16: 0 | Z16: =IF(Y16=1,ROUNDUP(W16*(1+VLOOKUP(E16,ARTICULOS!$D$10:$H$699,5)),0),W16) | AA16: =IF(Y16=1,ROUNDUP(X16*(1+VLOOKUP(E16,ARTICULOS!$D$10:$H$699,4)),0),X16) | AB16: 2 | AD16: =IF(AC16=1,J16*100&Z16,"") | AE16: =IF(AC16=1,VLOOKUP(AD16,EMPALME!$C$2:$F$33,4),"") | AG16: =IF(L16=3,IF(V16=1,CONFECCION!$C$18,CONFECCION!$C$18*2),IF(V16=1,HLOOKUP(AA16,CONFECCION!$C$17:$AD$33,VLOOKUP(Z16,CONFECCION!$A$18:$B$33,2)-16),2*HLOOKUP(AA16,CONFECCION!$C$17:$AD$33,VLOOKUP(Z16,CONFECCION!$A$18:$B$33,2)-16)))*IF(AC16=1,3,1) | AI16: =IF(AC16=1,AA16/100*K16+IF(AF16>0,K16*(VLOOKUP(AD16,EMPALME!$C$2:$D$33,2)/100)/AF16,K16*(VLOOKUP(AD16,EMPALME!$C$2:$D$33,2)/100)/VLOOKUP(AD16,EMPALME!$C$2:$F$33,4)),IF(AH16=2,ROUND((K16*(AA16/100)-(I16/10)*INT((AA16/100)/0.55)*INT((J16-(Z16/100)*INT(J16/(Z16/100)))/0.55))/INT(J16/(Z16/100)),2),ROUND(K16*(AA16/100)/INT(J16/(Z16/100)),2))) | AJ16: 2 | AK16: =ROUND(IF(AJ16=2,0,((Z16*2)+(AA16*2))*CONFECCION!$B$35/100),2) | AM16: 2 | AQ16: =IF(S16=0,"",S16) | AR16: =IF(A16=0,"",VLOOKUP(L16,ARTICULOS!$A$10:$B$19,2)) | AS16: =IF(A16=0,"",T16&" * "&U16)&IF(AM16=1," PR","") | AT16: =IF(A16=0,"",VLOOKUP(E16,ARTICULOS!$D$10:$F$699,3)) | AU16: =IF(A16=0,"","c/ "&D16&" "&VLOOKUP(H16,COLORES!$A$7:$G$4394,7)) | AV16: =IF(A16=0,"",IF(V16=1,"Dobl. Sencillo","Dobl. "&V16&" cm.")) | AW16: =+IF(Y16=1,"SI","") | AX16: =IF(A16=0,"",IF(AB16=2,Z16&" * "&AA16,IF(Z16=AA16,"Redondo "&Z16&" * "&AA16,"Ovalado "&Z16&" * "&AA16))) | AY16: =IF(A16=0,"",AG16+AI16+AK16) | AZ16: =IF(A16=0,"",A16) | BA16: =IF(A16=0,"",ROUND(AY16*AZ16,2))
A17: 0 | B17: 1 | D17: 1 | E17: =MATCH(C17,ARTICULOS!$F$10:$F$699,0) | F17: =+VLOOKUP(E17,ARTICULOS!$D$10:$I$699,6) | G17: =+F17&D17 | H17: =+MATCH(G17,COLORES!$E$7:$E$4394,0) | I17: =VLOOKUP(H17,COLORES!$A$7:$I$4394,8) | J17: =VLOOKUP(H17,COLORES!$A$7:$I$4394,9) | K17: =I17*(1+B17) | L17: 0 | M17: 0 | N17: 0 | O17: 0 | P17: 0 | Q17: 0 | S17: =IF(P17>0,IF(O17>0,"(/)"&O17&"*"&P17&IF(Q17>0,"+"&Q17,IF(Q17=0,"",Q17)),+M17&"*"&N17&"*"&P17&IF(Q17>0,"+"&Q17,IF(Q17=0,"",Q17))),"") | T17: =+IF(O17>0,O17+R17*2,M17+R17*2)+P17*2+Q17*2 | U17: =+IF(O17>0,O17+R17*2,N17+R17*2)+P17*2+Q17*2 | W17: =IF(V17=1,T17+5,T17+(V17*4)) | X17: =IF(V17=1,U17+5,U17+(V17*4)) | Y17: 0 | Z17: =IF(Y17=1,ROUNDUP(W17*(1+VLOOKUP(E17,ARTICULOS!$D$10:$H$699,5)),0),W17) | AA17: =IF(Y17=1,ROUNDUP(X17*(1+VLOOKUP(E17,ARTICULOS!$D$10:$H$699,4)),0),X17) | AB17: 2 | AD17: =IF(AC17=1,J17*100&Z17,"") | AE17: =IF(AC17=1,VLOOKUP(AD17,EMPALME!$C$2:$F$33,4),"") | AG17: =IF(L17=3,IF(V17=1,CONFECCION!$C$18,CONFECCION!$C$18*2),IF(V17=1,HLOOKUP(AA17,CONFECCION!$C$17:$AD$33,VLOOKUP(Z17,CONFECCION!$A$18:$B$33,2)-16),2*HLOOKUP(AA17,CONFECCION!$C$17:$AD$33,VLOOKUP(Z17,CONFECCION!$A$18:$B$33,2)-16)))*IF(AC17=1,3,1) | AI17: =IF(AC17=1,AA17/100*K17+IF(AF17>0,K17*(VLOOKUP(AD17,EMPALME!$C$2:$D$33,2)/100)/AF17,K17*(VLOOKUP(AD17,EMPALME!$C$2:$D$33,2)/100)/VLOOKUP(AD17,EMPALME!$C$2:$F$33,4)),IF(AH17=2,ROUND((K17*(AA17/100)-(I17/10)*INT((AA17/100)/0.55)*INT((J17-(Z17/100)*INT(J17/(Z17/100)))/0.55))/INT(J17/(Z17/100)),2),ROUND(K17*(AA17/100)/INT(J17/(Z17/100)),2))) | AJ17: 2 | AK17: =ROUND(IF(AJ17=2,0,((Z17*2)+(AA17*2))*CONFECCION!$B$35/100),2) | AM17: 2 | AQ17: =IF(S17=0,"",S17) | AR17: =IF(A17=0,"",VLOOKUP(L17,ARTICULOS!$A$10:$B$19,2)) | AS17: =IF(A17=0,"",T17&" * "&U17)&IF(AM17=1," PR","") | AT17: =IF(A17=0,"",VLOOKUP(E17,ARTICULOS!$D$10:$F$699,3)) | AU17: =IF(A17=0,"","c/ "&D17&" "&VLOOKUP(H17,COLORES!$A$7:$G$4394,7)) | AV17: =IF(A17=0,"",IF(V17=1,"Dobl. Sencillo","Dobl. "&V17&" cm.")) | AW17: =+IF(Y17=1,"SI","") | AX17: =IF(A17=0,"",IF(AB17=2,Z17&" * "&AA17,IF(Z17=AA17,"Redondo "&Z17&" * "&AA17,"Ovalado "&Z17&" * "&AA17))) | AY17: =IF(A17=0,"",AG17+AI17+AK17) | AZ17: =IF(A17=0,"",A17) | BA17: =IF(A17=0,"",ROUND(AY17*AZ17,2))
A18: 0 | B18: 1 | D18: 1 | E18: =MATCH(C18,ARTICULOS!$F$10:$F$699,0) | F18: =+VLOOKUP(E18,ARTICULOS!$D$10:$I$699,6) | G18: =+F18&D18 | H18: =+MATCH(G18,COLORES!$E$7:$E$4394,0) | I18: =VLOOKUP(H18,COLORES!$A$7:$I$4394,8) | J18: =VLOOKUP(H18,COLORES!$A$7:$I$4394,9) | K18: =I18*(1+B18) | L18: 0 | M18: 0 | N18: 0 | O18: 0 | P18: 0 | Q18: 0 | S18: =IF(P18>0,IF(O18>0,"(/)"&O18&"*"&P18&IF(Q18>0,"+"&Q18,IF(Q18=0,"",Q18)),+M18&"*"&N18&"*"&P18&IF(Q18>0,"+"&Q18,IF(Q18=0,"",Q18))),"") | T18: =+IF(O18>0,O18+R18*2,M18+R18*2)+P18*2+Q18*2 | U18: =+IF(O18>0,O18+R18*2,N18+R18*2)+P18*2+Q18*2 | W18: =IF(V18=1,T18+5,T18+(V18*4)) | X18: =IF(V18=1,U18+5,U18+(V18*4)) | Y18: 0 | Z18: =IF(Y18=1,ROUNDUP(W18*(1+VLOOKUP(E18,ARTICULOS!$D$10:$H$699,5)),0),W18) | AA18: =IF(Y18=1,ROUNDUP(X18*(1+VLOOKUP(E18,ARTICULOS!$D$10:$H$699,4)),0),X18) | AB18: 2 | AD18: =IF(AC18=1,J18*100&Z18,"") | AE18: =IF(AC18=1,VLOOKUP(AD18,EMPALME!$C$2:$F$33,4),"") | AG18: =IF(L18=3,IF(V18=1,CONFECCION!$C$18,CONFECCION!$C$18*2),IF(V18=1,HLOOKUP(AA18,CONFECCION!$C$17:$AD$33,VLOOKUP(Z18,CONFECCION!$A$18:$B$33,2)-16),2*HLOOKUP(AA18,CONFECCION!$C$17:$AD$33,VLOOKUP(Z18,CONFECCION!$A$18:$B$33,2)-16)))*IF(AC18=1,3,1) | AI18: =IF(AC18=1,AA18/100*K18+IF(AF18>0,K18*(VLOOKUP(AD18,EMPALME!$C$2:$D$33,2)/100)/AF18,K18*(VLOOKUP(AD18,EMPALME!$C$2:$D$33,2)/100)/VLOOKUP(AD18,EMPALME!$C$2:$F$33,4)),IF(AH18=2,ROUND((K18*(AA18/100)-(I18/10)*INT((AA18/100)/0.55)*INT((J18-(Z18/100)*INT(J18/(Z18/100)))/0.55))/INT(J18/(Z18/100)),2),ROUND(K18*(AA18/100)/INT(J18/(Z18/100)),2))) | AJ18: 2 | AK18: =ROUND(IF(AJ18=2,0,((Z18*2)+(AA18*2))*CONFECCION!$B$35/100),2) | AM18: 2 | AQ18: =IF(S18=0,"",S18) | AR18: =IF(A18=0,"",VLOOKUP(L18,ARTICULOS!$A$10:$B$19,2)) | AS18: =IF(A18=0,"",T18&" * "&U18)&IF(AM18=1," PR","") | AT18: =IF(A18=0,"",VLOOKUP(E18,ARTICULOS!$D$10:$F$699,3)) | AU18: =IF(A18=0,"","c/ "&D18&" "&VLOOKUP(H18,COLORES!$A$7:$G$4394,7)) | AV18: =IF(A18=0,"",IF(V18=1,"Dobl. Sencillo","Dobl. "&V18&" cm.")) | AW18: =+IF(Y18=1,"SI","") | AX18: =IF(A18=0,"",IF(AB18=2,Z18&" * "&AA18,IF(Z18=AA18,"Redondo "&Z18&" * "&AA18,"Ovalado "&Z18&" * "&AA18))) | AY18: =IF(A18=0,"",AG18+AI18+AK18) | AZ18: =IF(A18=0,"",A18) | BA18: =IF(A18=0,"",ROUND(AY18*AZ18,2))
A19: 0 | B19: 1 | D19: 1 | E19: =MATCH(C19,ARTICULOS!$F$10:$F$699,0) | F19: =+VLOOKUP(E19,ARTICULOS!$D$10:$I$699,6) | G19: =+F19&D19 | H19: =+MATCH(G19,COLORES!$E$7:$E$4394,0) | I19: =VLOOKUP(H19,COLORES!$A$7:$I$4394,8) | J19: =VLOOKUP(H19,COLORES!$A$7:$I$4394,9) | K19: =I19*(1+B19) | L19: 0 | M19: 0 | N19: 0 | O19: 0 | P19: 0 | Q19: 0 | S19: =IF(P19>0,IF(O19>0,"(/)"&O19&"*"&P19&IF(Q19>0,"+"&Q19,IF(Q19=0,"",Q19)),+M19&"*"&N19&"*"&P19&IF(Q19>0,"+"&Q19,IF(Q19=0,"",Q19))),"") | T19: =+IF(O19>0,O19+R19*2,M19+R19*2)+P19*2+Q19*2 | U19: =+IF(O19>0,O19+R19*2,N19+R19*2)+P19*2+Q19*2 | W19: =IF(V19=1,T19+5,T19+(V19*4)) | X19: =IF(V19=1,U19+5,U19+(V19*4)) | Y19: 0 | Z19: =IF(Y19=1,ROUNDUP(W19*(1+VLOOKUP(E19,ARTICULOS!$D$10:$H$699,5)),0),W19) | AA19: =IF(Y19=1,ROUNDUP(X19*(1+VLOOKUP(E19,ARTICULOS!$D$10:$H$699,4)),0),X19) | AB19: 2 | AD19: =IF(AC19=1,J19*100&Z19,"") | AE19: =IF(AC19=1,VLOOKUP(AD19,EMPALME!$C$2:$F$33,4),"") | AG19: =IF(L19=3,IF(V19=1,CONFECCION!$C$18,CONFECCION!$C$18*2),IF(V19=1,HLOOKUP(AA19,CONFECCION!$C$17:$AD$33,VLOOKUP(Z19,CONFECCION!$A$18:$B$33,2)-16),2*HLOOKUP(AA19,CONFECCION!$C$17:$AD$33,VLOOKUP(Z19,CONFECCION!$A$18:$B$33,2)-16)))*IF(AC19=1,3,1) | AI19: =IF(AC19=1,AA19/100*K19+IF(AF19>0,K19*(VLOOKUP(AD19,EMPALME!$C$2:$D$33,2)/100)/AF19,K19*(VLOOKUP(AD19,EMPALME!$C$2:$D$33,2)/100)/VLOOKUP(AD19,EMPALME!$C$2:$F$33,4)),IF(AH19=2,ROUND((K19*(AA19/100)-(I19/10)*INT((AA19/100)/0.55)*INT((J19-(Z19/100)*INT(J19/(Z19/100)))/0.55))/INT(J19/(Z19/100)),2),ROUND(K19*(AA19/100)/INT(J19/(Z19/100)),2))) | AJ19: 2 | AK19: =ROUND(IF(AJ19=2,0,((Z19*2)+(AA19*2))*CONFECCION!$B$35/100),2) | AM19: 2 | AQ19: =IF(S19=0,"",S19) | AR19: =IF(A19=0,"",VLOOKUP(L19,ARTICULOS!$A$10:$B$19,2)) | AS19: =IF(A19=0,"",T19&" * "&U19)&IF(AM19=1," PR","") | AT19: =IF(A19=0,"",VLOOKUP(E19,ARTICULOS!$D$10:$F$699,3)) | AU19: =IF(A19=0,"","c/ "&D19&" "&VLOOKUP(H19,COLORES!$A$7:$G$4394,7)) | AV19: =IF(A19=0,"",IF(V19=1,"Dobl. Sencillo","Dobl. "&V19&" cm.")) | AW19: =+IF(Y19=1,"SI","") | AX19: =IF(A19=0,"",IF(AB19=2,Z19&" * "&AA19,IF(Z19=AA19,"Redondo "&Z19&" * "&AA19,"Ovalado "&Z19&" * "&AA19))) | AY19: =IF(A19=0,"",AG19+AI19+AK19) | AZ19: =IF(A19=0,"",A19) | BA19: =IF(A19=0,"",ROUND(AY19*AZ19,2))
A20: 0 | B20: 1 | D20: 1 | E20: =MATCH(C20,ARTICULOS!$F$10:$F$699,0) | F20: =+VLOOKUP(E20,ARTICULOS!$D$10:$I$699,6) | G20: =+F20&D20 | H20: =+MATCH(G20,COLORES!$E$7:$E$4394,0) | I20: =VLOOKUP(H20,COLORES!$A$7:$I$4394,8) | J20: =VLOOKUP(H20,COLORES!$A$7:$I$4394,9) | K20: =I20*(1+B20) | L20: 0 | M20: 0 | N20: 0 | O20: 0 | P20: 0 | Q20: 0 | S20: =IF(P20>0,IF(O20>0,"(/)"&O20&"*"&P20&IF(Q20>0,"+"&Q20,IF(Q20=0,"",Q20)),+M20&"*"&N20&"*"&P20&IF(Q20>0,"+"&Q20,IF(Q20=0,"",Q20))),"") | T20: =+IF(O20>0,O20+R20*2,M20+R20*2)+P20*2+Q20*2 | U20: =+IF(O20>0,O20+R20*2,N20+R20*2)+P20*2+Q20*2 | W20: =IF(V20=1,T20+5,T20+(V20*4)) | X20: =IF(V20=1,U20+5,U20+(V20*4)) | Y20: 0 | Z20: =IF(Y20=1,ROUNDUP(W20*(1+VLOOKUP(E20,ARTICULOS!$D$10:$H$699,5)),0),W20) | AA20: =IF(Y20=1,ROUNDUP(X20*(1+VLOOKUP(E20,ARTICULOS!$D$10:$H$699,4)),0),X20) | AB20: 2 | AD20: =IF(AC20=1,J20*100&Z20,"") | AE20: =IF(AC20=1,VLOOKUP(AD20,EMPALME!$C$2:$F$33,4),"") | AG20: =IF(L20=3,IF(V20=1,CONFECCION!$C$18,CONFECCION!$C$18*2),IF(V20=1,HLOOKUP(AA20,CONFECCION!$C$17:$AD$33,VLOOKUP(Z20,CONFECCION!$A$18:$B$33,2)-16),2*HLOOKUP(AA20,CONFECCION!$C$17:$AD$33,VLOOKUP(Z20,CONFECCION!$A$18:$B$33,2)-16)))*IF(AC20=1,3,1) | AI20: =IF(AC20=1,AA20/100*K20+IF(AF20>0,K20*(VLOOKUP(AD20,EMPALME!$C$2:$D$33,2)/100)/AF20,K20*(VLOOKUP(AD20,EMPALME!$C$2:$D$33,2)/100)/VLOOKUP(AD20,EMPALME!$C$2:$F$33,4)),IF(AH20=2,ROUND((K20*(AA20/100)-(I20/10)*INT((AA20/100)/0.55)*INT((J20-(Z20/100)*INT(J20/(Z20/100)))/0.55))/INT(J20/(Z20/100)),2),ROUND(K20*(AA20/100)/INT(J20/(Z20/100)),2))) | AJ20: 2 | AK20: =ROUND(IF(AJ20=2,0,((Z20*2)+(AA20*2))*CONFECCION!$B$35/100),2) | AM20: 2 | AQ20: =IF(S20=0,"",S20) | AR20: =IF(A20=0,"",VLOOKUP(L20,ARTICULOS!$A$10:$B$19,2)) | AS20: =IF(A20=0,"",T20&" * "&U20)&IF(AM20=1," PR","") | AT20: =IF(A20=0,"",VLOOKUP(E20,ARTICULOS!$D$10:$F$699,3)) | AU20: =IF(A20=0,"","c/ "&D20&" "&VLOOKUP(H20,COLORES!$A$7:$G$4394,7)) | AV20: =IF(A20=0,"",IF(V20=1,"Dobl. Sencillo","Dobl. "&V20&" cm.")) | AW20: =+IF(Y20=1,"SI","") | AX20: =IF(A20=0,"",IF(AB20=2,Z20&" * "&AA20,IF(Z20=AA20,"Redondo "&Z20&" * "&AA20,"Ovalado "&Z20&" * "&AA20))) | AY20: =IF(A20=0,"",AG20+AI20+AK20) | AZ20: =IF(A20=0,"",A20) | BA20: =IF(A20=0,"",ROUND(AY20*AZ20,2))
A21: 0 | B21: 1 | D21: 1 | E21: =MATCH(C21,ARTICULOS!$F$10:$F$699,0) | F21: =+VLOOKUP(E21,ARTICULOS!$D$10:$I$699,6) | G21: =+F21&D21 | H21: =+MATCH(G21,COLORES!$E$7:$E$4394,0) | I21: =VLOOKUP(H21,COLORES!$A$7:$I$4394,8) | J21: =VLOOKUP(H21,COLORES!$A$7:$I$4394,9) | K21: =I21*(1+B21) | L21: 0 | M21: 0 | N21: 0 | O21: 0 | P21: 0 | Q21: 0 | S21: =IF(P21>0,IF(O21>0,"(/)"&O21&"*"&P21&IF(Q21>0,"+"&Q21,IF(Q21=0,"",Q21)),+M21&"*"&N21&"*"&P21&IF(Q21>0,"+"&Q21,IF(Q21=0,"",Q21))),"") | T21: =+IF(O21>0,O21+R21*2,M21+R21*2)+P21*2+Q21*2 | U21: =+IF(O21>0,O21+R21*2,N21+R21*2)+P21*2+Q21*2 | W21: =IF(V21=1,T21+5,T21+(V21*4)) | X21: =IF(V21=1,U21+5,U21+(V21*4)) | Y21: 0 | Z21: =IF(Y21=1,ROUNDUP(W21*(1+VLOOKUP(E21,ARTICULOS!$D$10:$H$699,5)),0),W21) | AA21: =IF(Y21=1,ROUNDUP(X21*(1+VLOOKUP(E21,ARTICULOS!$D$10:$H$699,4)),0),X21) | AB21: 2 | AD21: =IF(AC21=1,J21*100&Z21,"") | AE21: =IF(AC21=1,VLOOKUP(AD21,EMPALME!$C$2:$F$33,4),"") | AG21: =IF(L21=3,IF(V21=1,CONFECCION!$C$18,CONFECCION!$C$18*2),IF(V21=1,HLOOKUP(AA21,CONFECCION!$C$17:$AD$33,VLOOKUP(Z21,CONFECCION!$A$18:$B$33,2)-16),2*HLOOKUP(AA21,CONFECCION!$C$17:$AD$33,VLOOKUP(Z21,CONFECCION!$A$18:$B$33,2)-16)))*IF(AC21=1,3,1) | AI21: =IF(AC21=1,AA21/100*K21+IF(AF21>0,K21*(VLOOKUP(AD21,EMPALME!$C$2:$D$33,2)/100)/AF21,K21*(VLOOKUP(AD21,EMPALME!$C$2:$D$33,2)/100)/VLOOKUP(AD21,EMPALME!$C$2:$F$33,4)),IF(AH21=2,ROUND((K21*(AA21/100)-(I21/10)*INT((AA21/100)/0.55)*INT((J21-(Z21/100)*INT(J21/(Z21/100)))/0.55))/INT(J21/(Z21/100)),2),ROUND(K21*(AA21/100)/INT(J21/(Z21/100)),2))) | AJ21: 2 | AK21: =ROUND(IF(AJ21=2,0,((Z21*2)+(AA21*2))*CONFECCION!$B$35/100),2) | AM21: 2 | AQ21: =IF(S21=0,"",S21) | AR21: =IF(A21=0,"",VLOOKUP(L21,ARTICULOS!$A$10:$B$19,2)) | AS21: =IF(A21=0,"",T21&" * "&U21)&IF(AM21=1," PR","") | AT21: =IF(A21=0,"",VLOOKUP(E21,ARTICULOS!$D$10:$F$699,3)) | AU21: =IF(A21=0,"","c/ "&D21&" "&VLOOKUP(H21,COLORES!$A$7:$G$4394,7)) | AV21: =IF(A21=0,"",IF(V21=1,"Dobl. Sencillo","Dobl. "&V21&" cm.")) | AW21: =+IF(Y21=1,"SI","") | AX21: =IF(A21=0,"",IF(AB21=2,Z21&" * "&AA21,IF(Z21=AA21,"Redondo "&Z21&" * "&AA21,"Ovalado "&Z21&" * "&AA21))) | AY21: =IF(A21=0,"",AG21+AI21+AK21) | AZ21: =IF(A21=0,"",A21) | BA21: =IF(A21=0,"",ROUND(AY21*AZ21,2))
... A32: 0 | B32: 1 | D32: 1 | E32: =MATCH(C32,ARTICULOS!$F$10:$F$699,0) | F32: =+VLOOKUP(E32,ARTICULOS!$D$10:$I$699,6) | G32: =+F32&D32 | H32: =+MATCH(G32,COLORES!$E$7:$E$4394,0) | I32: =VLOOKUP(H32,COLORES!$A$7:$I$4394,8) | J32: =VLOOKUP(H32,COLORES!$A$7:$I$4394,9) | K32: =I32*(1+B32) | L32: 0 | M32: 0 | N32: 0 | O32: 0 | P32: 0 | Q32: 0 | S32: =IF(P32>0,IF(O32>0,"(/)"&O32&"*"&P32&IF(Q32>0,"+"&Q32,IF(Q32=0,"",Q32)),+M32&"*"&N32&"*"&P32&IF(Q32>0,"+"&Q32,IF(Q32=0,"",Q32))),"") | T32: =+IF(O32>0,O32+R32*2,M32+R32*2)+P32*2+Q32*2 | U32: =+IF(O32>0,O32+R32*2,N32+R32*2)+P32*2+Q32*2 | W32: =IF(V32=1,T32+5,T32+(V32*4)) | X32: =IF(V32=1,U32+5,U32+(V32*4)) | Y32: 0 | Z32: =IF(Y32=1,ROUNDUP(W32*(1+VLOOKUP(E32,ARTICULOS!$D$10:$H$699,5)),0),W32) | AA32: =IF(Y32=1,ROUNDUP(X32*(1+VLOOKUP(E32,ARTICULOS!$D$10:$H$699,4)),0),X32) | AB32: 2 | AD32: =IF(AC32=1,J32*100&Z32,"") | AE32: =IF(AC32=1,VLOOKUP(AD32,EMPALME!$C$2:$F$33,4),"") | AG32: =IF(L32=3,IF(V32=1,CONFECCION!$C$18,CONFECCION!$C$18*2),IF(V32=1,HLOOKUP(AA32,CONFECCION!$C$17:$AD$33,VLOOKUP(Z32,CONFECCION!$A$18:$B$33,2)-16),2*HLOOKUP(AA32,CONFECCION!$C$17:$AD$33,VLOOKUP(Z32,CONFECCION!$A$18:$B$33,2)-16)))*IF(AC32=1,3,1) | AI32: =IF(AC32=1,AA32/100*K32+IF(AF32>0,K32*(VLOOKUP(AD32,EMPALME!$C$2:$D$33,2)/100)/AF32,K32*(VLOOKUP(AD32,EMPALME!$C$2:$D$33,2)/100)/VLOOKUP(AD32,EMPALME!$C$2:$F$33,4)),IF(AH32=2,ROUND((K32*(AA32/100)-(I32/10)*INT((AA32/100)/0.55)*INT((J32-(Z32/100)*INT(J32/(Z32/100)))/0.55))/INT(J32/(Z32/100)),2),ROUND(K32*(AA32/100)/INT(J32/(Z32/100)),2))) | AJ32: 2 | AK32: =ROUND(IF(AJ32=2,0,((Z32*2)+(AA32*2))*CONFECCION!$B$35/100),2) | AM32: 2 | AQ32: =IF(S32=0,"",S32) | AR32: =IF(A32=0,"",VLOOKUP(L32,ARTICULOS!$A$10:$B$19,2)) | AS32: =IF(A32=0,"",T32&" * "&U32)&IF(AM32=1," PR","") | AT32: =IF(A32=0,"",VLOOKUP(E32,ARTICULOS!$D$10:$F$699,3)) | AU32: =IF(A32=0,"","c/ "&D32&" "&VLOOKUP(H32,COLORES!$A$7:$G$4394,7)) | AV32: =IF(A32=0,"",IF(V32=1,"Dobl. Sencillo","Dobl. "&V32&" cm.")) | AW32: =+IF(Y32=1,"SI","") | AX32: =IF(A32=0,"",IF(AB32=2,Z32&" * "&AA32,IF(Z32=AA32,"Redondo "&Z32&" * "&AA32,"Ovalado "&Z32&" * "&AA32))) | AY32: =IF(A32=0,"",AG32+AI32+AK32) | AZ32: =IF(A32=0,"",A32) | BA32: =IF(A32=0,"",ROUND(AY32*AZ32,2))
A33: 0 | B33: 1 | D33: 1 | E33: =MATCH(C33,ARTICULOS!$F$10:$F$699,0) | F33: =+VLOOKUP(E33,ARTICULOS!$D$10:$I$699,6) | G33: =+F33&D33 | H33: =+MATCH(G33,COLORES!$E$7:$E$4394,0) | I33: =VLOOKUP(H33,COLORES!$A$7:$I$4394,8) | J33: =VLOOKUP(H33,COLORES!$A$7:$I$4394,9) | K33: =I33*(1+B33) | L33: 0 | M33: 0 | N33: 0 | O33: 0 | P33: 0 | Q33: 0 | S33: =IF(P33>0,IF(O33>0,"(/)"&O33&"*"&P33&IF(Q33>0,"+"&Q33,IF(Q33=0,"",Q33)),+M33&"*"&N33&"*"&P33&IF(Q33>0,"+"&Q33,IF(Q33=0,"",Q33))),"") | T33: =+IF(O33>0,O33+R33*2,M33+R33*2)+P33*2+Q33*2 | U33: =+IF(O33>0,O33+R33*2,N33+R33*2)+P33*2+Q33*2 | W33: =IF(V33=1,T33+5,T33+(V33*4)) | X33: =IF(V33=1,U33+5,U33+(V33*4)) | Y33: 0 | Z33: =IF(Y33=1,ROUNDUP(W33*(1+VLOOKUP(E33,ARTICULOS!$D$10:$H$699,5)),0),W33) | AA33: =IF(Y33=1,ROUNDUP(X33*(1+VLOOKUP(E33,ARTICULOS!$D$10:$H$699,4)),0),X33) | AB33: 2 | AD33: =IF(AC33=1,J33*100&Z33,"") | AE33: =IF(AC33=1,VLOOKUP(AD33,EMPALME!$C$2:$F$33,4),"") | AG33: =IF(L33=3,IF(V33=1,CONFECCION!$C$18,CONFECCION!$C$18*2),IF(V33=1,HLOOKUP(AA33,CONFECCION!$C$17:$AD$33,VLOOKUP(Z33,CONFECCION!$A$18:$B$33,2)-16),2*HLOOKUP(AA33,CONFECCION!$C$17:$AD$33,VLOOKUP(Z33,CONFECCION!$A$18:$B$33,2)-16)))*IF(AC33=1,3,1) | AI33: =IF(AC33=1,AA33/100*K33+IF(AF33>0,K33*(VLOOKUP(AD33,EMPALME!$C$2:$D$33,2)/100)/AF33,K33*(VLOOKUP(AD33,EMPALME!$C$2:$D$33,2)/100)/VLOOKUP(AD33,EMPALME!$C$2:$F$33,4)),IF(AH33=2,ROUND((K33*(AA33/100)-(I33/10)*INT((AA33/100)/0.55)*INT((J33-(Z33/100)*INT(J33/(Z33/100)))/0.55))/INT(J33/(Z33/100)),2),ROUND(K33*(AA33/100)/INT(J33/(Z33/100)),2))) | AJ33: 2 | AK33: =ROUND(IF(AJ33=2,0,((Z33*2)+(AA33*2))*CONFECCION!$B$35/100),2) | AM33: 2 | AP33: Todas las prendas, seran identificadas con etiquerta color, según medida. | AQ33: =IF(S33=0,"",S33) | AR33: =IF(A33=0,"",VLOOKUP(L33,ARTICULOS!$A$10:$B$19,2)) | AS33: =IF(A33=0,"",T33&" * "&U33)&IF(AM33=1," PR","") | AT33: =IF(A33=0,"",VLOOKUP(E33,ARTICULOS!$D$10:$F$699,3)) | AU33: =IF(A33=0,"","c/ "&D33&" "&VLOOKUP(H33,COLORES!$A$7:$G$4394,7)) | AV33: =IF(A33=0,"",IF(V33=1,"Dobl. Sencillo","Dobl. "&V33&" cm.")) | AW33: =+IF(Y33=1,"SI","") | AX33: =IF(A33=0,"",IF(AB33=2,Z33&" * "&AA33,IF(Z33=AA33,"Redondo "&Z33&" * "&AA33,"Ovalado "&Z33&" * "&AA33))) | AY33: =IF(A33=0,"",AG33+AI33+AK33) | AZ33: =IF(A33=0,"",A33) | BA33: =IF(A33=0,"",ROUND(AY33*AZ33,2))
A34: 0 | B34: 1 | D34: 1 | E34: =MATCH(C34,ARTICULOS!$F$10:$F$699,0) | F34: =+VLOOKUP(E34,ARTICULOS!$D$10:$I$699,6) | G34: =+F34&D34 | H34: =+MATCH(G34,COLORES!$E$7:$E$4394,0) | I34: =VLOOKUP(H34,COLORES!$A$7:$I$4394,8) | J34: =VLOOKUP(H34,COLORES!$A$7:$I$4394,9) | K34: =I34*(1+B34) | L34: 0 | M34: 0 | N34: 0 | O34: 0 | P34: 0 | Q34: 0 | S34: =IF(P34>0,IF(O34>0,"(/)"&O34&"*"&P34&IF(Q34>0,"+"&Q34,IF(Q34=0,"",Q34)),+M34&"*"&N34&"*"&P34&IF(Q34>0,"+"&Q34,IF(Q34=0,"",Q34))),"") | T34: =+IF(O34>0,O34+R34*2,M34+R34*2)+P34*2+Q34*2 | U34: =+IF(O34>0,O34+R34*2,N34+R34*2)+P34*2+Q34*2 | W34: =IF(V34=1,T34+5,T34+(V34*4)) | X34: =IF(V34=1,U34+5,U34+(V34*4)) | Y34: 0 | Z34: =IF(Y34=1,ROUNDUP(W34*(1+VLOOKUP(E34,ARTICULOS!$D$10:$H$699,5)),0),W34) | AA34: =IF(Y34=1,ROUNDUP(X34*(1+VLOOKUP(E34,ARTICULOS!$D$10:$H$699,4)),0),X34) | AB34: 2 | AD34: =IF(AC34=1,J34*100&Z34,"") | AE34: =IF(AC34=1,VLOOKUP(AD34,EMPALME!$C$2:$F$33,4),"") | AG34: =IF(L34=3,IF(V34=1,CONFECCION!$C$18,CONFECCION!$C$18*2),IF(V34=1,HLOOKUP(AA34,CONFECCION!$C$17:$AD$33,VLOOKUP(Z34,CONFECCION!$A$18:$B$33,2)-16),2*HLOOKUP(AA34,CONFECCION!$C$17:$AD$33,VLOOKUP(Z34,CONFECCION!$A$18:$B$33,2)-16)))*IF(AC34=1,3,1) | AI34: =IF(AC34=1,AA34/100*K34+IF(AF34>0,K34*(VLOOKUP(AD34,EMPALME!$C$2:$D$33,2)/100)/AF34,K34*(VLOOKUP(AD34,EMPALME!$C$2:$D$33,2)/100)/VLOOKUP(AD34,EMPALME!$C$2:$F$33,4)),IF(AH34=2,ROUND((K34*(AA34/100)-(I34/10)*INT((AA34/100)/0.55)*INT((J34-(Z34/100)*INT(J34/(Z34/100)))/0.55))/INT(J34/(Z34/100)),2),ROUND(K34*(AA34/100)/INT(J34/(Z34/100)),2))) | AJ34: 2 | AK34: =ROUND(IF(AJ34=2,0,((Z34*2)+(AA34*2))*CONFECCION!$B$35/100),2) | AM34: 2 | AP34: Estos precios no incluyen I.V.A. | AQ34: =IF(S34=0,"",S34) | AR34: =IF(A34=0,"",VLOOKUP(L34,ARTICULOS!$A$10:$B$19,2)) | AS34: =IF(A34=0,"",T34&" * "&U34)&IF(AM34=1," PR","") | AT34: =IF(A34=0,"",VLOOKUP(E34,ARTICULOS!$D$10:$F$699,3)) | AU34: =IF(A34=0,"","c/ "&D34&" "&VLOOKUP(H34,COLORES!$A$7:$G$4394,7)) | AV34: =IF(A34=0,"",IF(V34=1,"Dobl. Sencillo","Dobl. "&V34&" cm.")) | AW34: =+IF(Y34=1,"SI","") | AX34: =IF(A34=0,"",IF(AB34=2,Z34&" * "&AA34,IF(Z34=AA34,"Redondo "&Z34&" * "&AA34,"Ovalado "&Z34&" * "&AA34))) | AY34: =IF(A34=0,"",AG34+AI34+AK34) | AZ34: =IF(A34=0,"",A34) | BA34: =IF(A34=0,"",ROUND(AY34*AZ34,2))
A35: 0 | B35: 1 | D35: 1 | E35: =MATCH(C35,ARTICULOS!$F$10:$F$699,0) | F35: =+VLOOKUP(E35,ARTICULOS!$D$10:$I$699,6) | G35: =+F35&D35 | H35: =+MATCH(G35,COLORES!$E$7:$E$4394,0) | I35: =VLOOKUP(H35,COLORES!$A$7:$I$4394,8) | J35: =VLOOKUP(H35,COLORES!$A$7:$I$4394,9) | K35: =I35*(1+B35) | L35: 0 | M35: 0 | N35: 0 | O35: 0 | P35: 0 | Q35: 0 | S35: =IF(P35>0,IF(O35>0,"(/)"&O35&"*"&P35&IF(Q35>0,"+"&Q35,IF(Q35=0,"",Q35)),+M35&"*"&N35&"*"&P35&IF(Q35>0,"+"&Q35,IF(Q35=0,"",Q35))),"") | T35: =+IF(O35>0,O35+R35*2,M35+R35*2)+P35*2+Q35*2 | U35: =+IF(O35>0,O35+R35*2,N35+R35*2)+P35*2+Q35*2 | W35: =IF(V35=1,T35+5,T35+(V35*4)) | X35: =IF(V35=1,U35+5,U35+(V35*4)) | Y35: 0 | Z35: =IF(Y35=1,ROUNDUP(W35*(1+VLOOKUP(E35,ARTICULOS!$D$10:$H$699,5)),0),W35) | AA35: =IF(Y35=1,ROUNDUP(X35*(1+VLOOKUP(E35,ARTICULOS!$D$10:$H$699,4)),0),X35) | AB35: 2 | AD35: =IF(AC35=1,J35*100&Z35,"") | AE35: =IF(AC35=1,VLOOKUP(AD35,EMPALME!$C$2:$F$33,4),"") | AG35: =IF(L35=3,IF(V35=1,CONFECCION!$C$18,CONFECCION!$C$18*2),IF(V35=1,HLOOKUP(AA35,CONFECCION!$C$17:$AD$33,VLOOKUP(Z35,CONFECCION!$A$18:$B$33,2)-16),2*HLOOKUP(AA35,CONFECCION!$C$17:$AD$33,VLOOKUP(Z35,CONFECCION!$A$18:$B$33,2)-16)))*IF(AC35=1,3,1) | AI35: =IF(AC35=1,AA35/100*K35+IF(AF35>0,K35*(VLOOKUP(AD35,EMPALME!$C$2:$D$33,2)/100)/AF35,K35*(VLOOKUP(AD35,EMPALME!$C$2:$D$33,2)/100)/VLOOKUP(AD35,EMPALME!$C$2:$F$33,4)),IF(AH35=2,ROUND((K35*(AA35/100)-(I35/10)*INT((AA35/100)/0.55)*INT((J35-(Z35/100)*INT(J35/(Z35/100)))/0.55))/INT(J35/(Z35/100)),2),ROUND(K35*(AA35/100)/INT(J35/(Z35/100)),2))) | AJ35: 2 | AK35: =ROUND(IF(AJ35=2,0,((Z35*2)+(AA35*2))*CONFECCION!$B$35/100),2) | AM35: 2 | AP35: Considerado encogimiento. | AQ35: =IF(S35=0,"",S35) | AR35: =IF(A35=0,"",VLOOKUP(L35,ARTICULOS!$A$10:$B$19,2)) | AS35: =IF(A35=0,"",T35&" * "&U35)&IF(AM35=1," PR","") | AT35: =IF(A35=0,"",VLOOKUP(E35,ARTICULOS!$D$10:$F$699,3)) | AU35: =IF(A35=0,"","c/ "&D35&" "&VLOOKUP(H35,COLORES!$A$7:$G$4394,7)) | AV35: =IF(A35=0,"",IF(V35=1,"Dobl. Sencillo","Dobl. "&V35&" cm.")) | AW35: =+IF(Y35=1,"SI","") | AX35: =IF(A35=0,"",IF(AB35=2,Z35&" * "&AA35,IF(Z35=AA35,"Redondo "&Z35&" * "&AA35,"Ovalado "&Z35&" * "&AA35))) | AY35: =IF(A35=0,"",AG35+AI35+AK35) | AZ35: =IF(A35=0,"",A35) | BA35: =IF(A35=0,"",ROUND(AY35*AZ35,2))
A36: 0 | B36: 1 | D36: 1 | E36: =MATCH(C36,ARTICULOS!$F$10:$F$699,0) | F36: =+VLOOKUP(E36,ARTICULOS!$D$10:$I$699,6) | G36: =+F36&D36 | H36: =+MATCH(G36,COLORES!$E$7:$E$4394,0) | I36: =VLOOKUP(H36,COLORES!$A$7:$I$4394,8) | J36: =VLOOKUP(H36,COLORES!$A$7:$I$4394,9) | K36: =I36*(1+B36) | L36: 0 | M36: 0 | N36: 0 | O36: 0 | P36: 0 | Q36: 0 | S36: =IF(P36>0,IF(O36>0,"(/)"&O36&"*"&P36&IF(Q36>0,"+"&Q36,IF(Q36=0,"",Q36)),+M36&"*"&N36&"*"&P36&IF(Q36>0,"+"&Q36,IF(Q36=0,"",Q36))),"") | T36: =+IF(O36>0,O36+R36*2,M36+R36*2)+P36*2+Q36*2 | U36: =+IF(O36>0,O36+R36*2,N36+R36*2)+P36*2+Q36*2 | W36: =IF(V36=1,T36+5,T36+(V36*4)) | X36: =IF(V36=1,U36+5,U36+(V36*4)) | Y36: 0 | Z36: =IF(Y36=1,ROUNDUP(W36*(1+VLOOKUP(E36,ARTICULOS!$D$10:$H$699,5)),0),W36) | AA36: =IF(Y36=1,ROUNDUP(X36*(1+VLOOKUP(E36,ARTICULOS!$D$10:$H$699,4)),0),X36) | AB36: 2 | AD36: =IF(AC36=1,J36*100&Z36,"") | AE36: =IF(AC36=1,VLOOKUP(AD36,EMPALME!$C$2:$F$33,4),"") | AG36: =IF(L36=3,IF(V36=1,CONFECCION!$C$18,CONFECCION!$C$18*2),IF(V36=1,HLOOKUP(AA36,CONFECCION!$C$17:$AD$33,VLOOKUP(Z36,CONFECCION!$A$18:$B$33,2)-16),2*HLOOKUP(AA36,CONFECCION!$C$17:$AD$33,VLOOKUP(Z36,CONFECCION!$A$18:$B$33,2)-16)))*IF(AC36=1,3,1) | AI36: =IF(AC36=1,AA36/100*K36+IF(AF36>0,K36*(VLOOKUP(AD36,EMPALME!$C$2:$D$33,2)/100)/AF36,K36*(VLOOKUP(AD36,EMPALME!$C$2:$D$33,2)/100)/VLOOKUP(AD36,EMPALME!$C$2:$F$33,4)),IF(AH36=2,ROUND((K36*(AA36/100)-(I36/10)*INT((AA36/100)/0.55)*INT((J36-(Z36/100)*INT(J36/(Z36/100)))/0.55))/INT(J36/(Z36/100)),2),ROUND(K36*(AA36/100)/INT(J36/(Z36/100)),2))) | AJ36: 2 | AK36: =ROUND(IF(AJ36=2,0,((Z36*2)+(AA36*2))*CONFECCION!$B$35/100),2) | AM36: 2 | AP36: Confección a Capet | AQ36: =IF(S36=0,"",S36) | AR36: =IF(A36=0,"",VLOOKUP(L36,ARTICULOS!$A$10:$B$19,2)) | AS36: =IF(A36=0,"",T36&" * "&U36)&IF(AM36=1," PR","") | AT36: =IF(A36=0,"",VLOOKUP(E36,ARTICULOS!$D$10:$F$699,3)) | AU36: =IF(A36=0,"","c/ "&D36&" "&VLOOKUP(H36,COLORES!$A$7:$G$4394,7)) | AV36: =IF(A36=0,"",IF(V36=1,"Dobl. Sencillo","Dobl. "&V36&" cm.")) | AW36: =+IF(Y36=1,"SI","") | AX36: =IF(A36=0,"",IF(AB36=2,Z36&" * "&AA36,IF(Z36=AA36,"Redondo "&Z36&" * "&AA36,"Ovalado "&Z36&" * "&AA36))) | AY36: =IF(A36=0,"",AG36+AI36+AK36) | AZ36: =IF(A36=0,"",A36) | BA36: =IF(A36=0,"",ROUND(AY36*AZ36,2))
A37: 0 | B37: 1 | D37: 1 | E37: =MATCH(C37,ARTICULOS!$F$10:$F$699,0) | F37: =+VLOOKUP(E37,ARTICULOS!$D$10:$I$699,6) | G37: =+F37&D37 | H37: =+MATCH(G37,COLORES!$E$7:$E$4394,0) | I37: =VLOOKUP(H37,COLORES!$A$7:$I$4394,8) | J37: =VLOOKUP(H37,COLORES!$A$7:$I$4394,9) | K37: =I37*(1+B37) | L37: 0 | M37: 0 | N37: 0 | O37: 0 | P37: 0 | Q37: 0 | S37: =IF(P37>0,IF(O37>0,"(/)"&O37&"*"&P37&IF(Q37>0,"+"&Q37,IF(Q37=0,"",Q37)),+M37&"*"&N37&"*"&P37&IF(Q37>0,"+"&Q37,IF(Q37=0,"",Q37))),"") | T37: =+IF(O37>0,O37+R37*2,M37+R37*2)+P37*2+Q37*2 | U37: =+IF(O37>0,O37+R37*2,N37+R37*2)+P37*2+Q37*2 | W37: =IF(V37=1,T37+5,T37+(V37*4)) | X37: =IF(V37=1,U37+5,U37+(V37*4)) | Y37: 0 | Z37: =IF(Y37=1,ROUNDUP(W37*(1+VLOOKUP(E37,ARTICULOS!$D$10:$H$699,5)),0),W37) | AA37: =IF(Y37=1,ROUNDUP(X37*(1+VLOOKUP(E37,ARTICULOS!$D$10:$H$699,4)),0),X37) | AB37: 2 | AD37: =IF(AC37=1,J37*100&Z37,"") | AE37: =IF(AC37=1,VLOOKUP(AD37,EMPALME!$C$2:$F$33,4),"") | AG37: =IF(L37=3,IF(V37=1,CONFECCION!$C$18,CONFECCION!$C$18*2),IF(V37=1,HLOOKUP(AA37,CONFECCION!$C$17:$AD$33,VLOOKUP(Z37,CONFECCION!$A$18:$B$33,2)-16),2*HLOOKUP(AA37,CONFECCION!$C$17:$AD$33,VLOOKUP(Z37,CONFECCION!$A$18:$B$33,2)-16)))*IF(AC37=1,3,1) | AI37: =IF(AC37=1,AA37/100*K37+IF(AF37>0,K37*(VLOOKUP(AD37,EMPALME!$C$2:$D$33,2)/100)/AF37,K37*(VLOOKUP(AD37,EMPALME!$C$2:$D$33,2)/100)/VLOOKUP(AD37,EMPALME!$C$2:$F$33,4)),IF(AH37=2,ROUND((K37*(AA37/100)-(I37/10)*INT((AA37/100)/0.55)*INT((J37-(Z37/100)*INT(J37/(Z37/100)))/0.55))/INT(J37/(Z37/100)),2),ROUND(K37*(AA37/100)/INT(J37/(Z37/100)),2))) | AJ37: 2 | AK37: =ROUND(IF(AJ37=2,0,((Z37*2)+(AA37*2))*CONFECCION!$B$35/100),2) | AM37: 2 | AP37: F. Pago : 50% a la aceptacion de presupuesto. | AQ37: =IF(S37=0,"",S37) | AR37: =IF(A37=0,"",VLOOKUP(L37,ARTICULOS!$A$10:$B$19,2)) | AS37: =IF(A37=0,"",T37&" * "&U37)&IF(AM37=1," PR","") | AT37: =IF(A37=0,"",VLOOKUP(E37,ARTICULOS!$D$10:$F$699,3)) | AU37: =IF(A37=0,"","c/ "&D37&" "&VLOOKUP(H37,COLORES!$A$7:$G$4394,7)) | AV37: =IF(A37=0,"",IF(V37=1,"Dobl. Sencillo","Dobl. "&V37&" cm.")) | AW37: =+IF(Y37=1,"SI","") | AX37: =IF(A37=0,"",IF(AB37=2,Z37&" * "&AA37,IF(Z37=AA37,"Redondo "&Z37&" * "&AA37,"Ovalado "&Z37&" * "&AA37))) | AY37: =IF(A37=0,"",AG37+AI37+AK37) | AZ37: =IF(A37=0,"",A37) | BA37: =IF(A37=0,"",ROUND(AY37*AZ37,2))
A38: 0 | B38: 1 | D38: 1 | E38: =MATCH(C38,ARTICULOS!$F$10:$F$699,0) | F38: =+VLOOKUP(E38,ARTICULOS!$D$10:$I$699,6) | G38: =+F38&D38 | H38: =+MATCH(G38,COLORES!$E$7:$E$4394,0) | I38: =VLOOKUP(H38,COLORES!$A$7:$I$4394,8) | J38: =VLOOKUP(H38,COLORES!$A$7:$I$4394,9) | K38: =I38*(1+B38) | L38: 0 | M38: 0 | N38: 0 | O38: 0 | P38: 0 | Q38: 0 | S38: =IF(P38>0,IF(O38>0,"(/)"&O38&"*"&P38&IF(Q38>0,"+"&Q38,IF(Q38=0,"",Q38)),+M38&"*"&N38&"*"&P38&IF(Q38>0,"+"&Q38,IF(Q38=0,"",Q38))),"") | T38: =+IF(O38>0,O38+R38*2,M38+R38*2)+P38*2+Q38*2 | U38: =+IF(O38>0,O38+R38*2,N38+R38*2)+P38*2+Q38*2 | W38: =IF(V38=1,T38+5,T38+(V38*4)) | X38: =IF(V38=1,U38+5,U38+(V38*4)) | Y38: 0 | Z38: =IF(Y38=1,ROUNDUP(W38*(1+VLOOKUP(E38,ARTICULOS!$D$10:$H$699,5)),0),W38) | AA38: =IF(Y38=1,ROUNDUP(X38*(1+VLOOKUP(E38,ARTICULOS!$D$10:$H$699,4)),0),X38) | AB38: 2 | AD38: =IF(AC38=1,J38*100&Z38,"") | AE38: =IF(AC38=1,VLOOKUP(AD38,EMPALME!$C$2:$F$33,4),"") | AG38: =IF(L38=3,IF(V38=1,CONFECCION!$C$18,CONFECCION!$C$18*2),IF(V38=1,HLOOKUP(AA38,CONFECCION!$C$17:$AD$33,VLOOKUP(Z38,CONFECCION!$A$18:$B$33,2)-16),2*HLOOKUP(AA38,CONFECCION!$C$17:$AD$33,VLOOKUP(Z38,CONFECCION!$A$18:$B$33,2)-16)))*IF(AC38=1,3,1) | AI38: =IF(AC38=1,AA38/100*K38+IF(AF38>0,K38*(VLOOKUP(AD38,EMPALME!$C$2:$D$33,2)/100)/AF38,K38*(VLOOKUP(AD38,EMPALME!$C$2:$D$33,2)/100)/VLOOKUP(AD38,EMPALME!$C$2:$F$33,4)),IF(AH38=2,ROUND((K38*(AA38/100)-(I38/10)*INT((AA38/100)/0.55)*INT((J38-(Z38/100)*INT(J38/(Z38/100)))/0.55))/INT(J38/(Z38/100)),2),ROUND(K38*(AA38/100)/INT(J38/(Z38/100)),2))) | AJ38: 2 | AK38: =ROUND(IF(AJ38=2,0,((Z38*2)+(AA38*2))*CONFECCION!$B$35/100),2) | AM38: 2 | AP38: Resto a la entrega de mercancia | AQ38: =IF(S38=0,"",S38) | AR38: =IF(A38=0,"",VLOOKUP(L38,ARTICULOS!$A$10:$B$19,2)) | AS38: =IF(A38=0,"",T38&" * "&U38)&IF(AM38=1," PR","") | AT38: =IF(A38=0,"",VLOOKUP(E38,ARTICULOS!$D$10:$F$699,3)) | AU38: =IF(A38=0,"","c/ "&D38&" "&VLOOKUP(H38,COLORES!$A$7:$G$4394,7)) | AV38: =IF(A38=0,"",IF(V38=1,"Dobl. Sencillo","Dobl. "&V38&" cm.")) | AW38: =+IF(Y38=1,"SI","") | AX38: =IF(A38=0,"",IF(AB38=2,Z38&" * "&AA38,IF(Z38=AA38,"Redondo "&Z38&" * "&AA38,"Ovalado "&Z38&" * "&AA38))) | AY38: =IF(A38=0,"",AG38+AI38+AK38) | AZ38: =IF(A38=0,"",A38) | BA38: =IF(A38=0,"",ROUND(AY38*AZ38,2))
A39: 0 | B39: 1 | D39: 1 | E39: =MATCH(C39,ARTICULOS!$F$10:$F$699,0) | F39: =+VLOOKUP(E39,ARTICULOS!$D$10:$I$699,6) | G39: =+F39&D39 | H39: =+MATCH(G39,COLORES!$E$7:$E$4394,0) | I39: =VLOOKUP(H39,COLORES!$A$7:$I$4394,8) | J39: =VLOOKUP(H39,COLORES!$A$7:$I$4394,9) | K39: =I39*(1+B39) | L39: 0 | M39: 0 | N39: 0 | O39: 0 | P39: 0 | Q39: 0 | S39: =IF(P39>0,IF(O39>0,"(/)"&O39&"*"&P39&IF(Q39>0,"+"&Q39,IF(Q39=0,"",Q39)),+M39&"*"&N39&"*"&P39&IF(Q39>0,"+"&Q39,IF(Q39=0,"",Q39))),"") | T39: =+IF(O39>0,O39+R39*2,M39+R39*2)+P39*2+Q39*2 | U39: =+IF(O39>0,O39+R39*2,N39+R39*2)+P39*2+Q39*2 | W39: =IF(V39=1,T39+5,T39+(V39*4)) | X39: =IF(V39=1,U39+5,U39+(V39*4)) | Y39: 0 | Z39: =IF(Y39=1,ROUNDUP(W39*(1+VLOOKUP(E39,ARTICULOS!$D$10:$H$699,5)),0),W39) | AA39: =IF(Y39=1,ROUNDUP(X39*(1+VLOOKUP(E39,ARTICULOS!$D$10:$H$699,4)),0),X39) | AB39: 2 | AD39: =IF(AC39=1,J39*100&Z39,"") | AE39: =IF(AC39=1,VLOOKUP(AD39,EMPALME!$C$2:$F$33,4),"") | AG39: =IF(L39=3,IF(V39=1,CONFECCION!$C$18,CONFECCION!$C$18*2),IF(V39=1,HLOOKUP(AA39,CONFECCION!$C$17:$AD$33,VLOOKUP(Z39,CONFECCION!$A$18:$B$33,2)-16),2*HLOOKUP(AA39,CONFECCION!$C$17:$AD$33,VLOOKUP(Z39,CONFECCION!$A$18:$B$33,2)-16)))*IF(AC39=1,3,1) | AI39: =IF(AC39=1,AA39/100*K39+IF(AF39>0,K39*(VLOOKUP(AD39,EMPALME!$C$2:$D$33,2)/100)/AF39,K39*(VLOOKUP(AD39,EMPALME!$C$2:$D$33,2)/100)/VLOOKUP(AD39,EMPALME!$C$2:$F$33,4)),IF(AH39=2,ROUND((K39*(AA39/100)-(I39/10)*INT((AA39/100)/0.55)*INT((J39-(Z39/100)*INT(J39/(Z39/100)))/0.55))/INT(J39/(Z39/100)),2),ROUND(K39*(AA39/100)/INT(J39/(Z39/100)),2))) | AJ39: 2 | AK39: =ROUND(IF(AJ39=2,0,((Z39*2)+(AA39*2))*CONFECCION!$B$35/100),2) | AM39: 2 | AP39: La cantidad de prendas, puede variar en un + - 10% | AQ39: =IF(S39=0,"",S39) | AR39: =IF(A39=0,"",VLOOKUP(L39,ARTICULOS!$A$10:$B$19,2)) | AS39: =IF(A39=0,"",T39&" * "&U39)&IF(AM39=1," PR","") | AT39: =IF(A39=0,"",VLOOKUP(E39,ARTICULOS!$D$10:$F$699,3)) | AU39: =IF(A39=0,"","c/ "&D39&" "&VLOOKUP(H39,COLORES!$A$7:$G$4394,7)) | AV39: =IF(A39=0,"",IF(V39=1,"Dobl. Sencillo","Dobl. "&V39&" cm.")) | AW39: =+IF(Y39=1,"SI","") | AX39: =IF(A39=0,"",IF(AB39=2,Z39&" * "&AA39,IF(Z39=AA39,"Redondo "&Z39&" * "&AA39,"Ovalado "&Z39&" * "&AA39))) | AY39: =IF(A39=0,"",AG39+AI39+AK39) | AZ39: =IF(A39=0,"",A39) | BA39: =IF(A39=0,"",ROUND(AY39*AZ39,2))
A40: 0 | B40: 1 | D40: 1 | E40: =MATCH(C40,ARTICULOS!$F$10:$F$699,0) | F40: =+VLOOKUP(E40,ARTICULOS!$D$10:$I$699,6) | G40: =+F40&D40 | H40: =+MATCH(G40,COLORES!$E$7:$E$4394,0) | I40: =VLOOKUP(H40,COLORES!$A$7:$I$4394,8) | J40: =VLOOKUP(H40,COLORES!$A$7:$I$4394,9) | K40: =I40*(1+B40) | L40: 0 | M40: 0 | N40: 0 | O40: 0 | P40: 0 | Q40: 0 | S40: =IF(P40>0,IF(O40>0,"(/)"&O40&"*"&P40&IF(Q40>0,"+"&Q40,IF(Q40=0,"",Q40)),+M40&"*"&N40&"*"&P40&IF(Q40>0,"+"&Q40,IF(Q40=0,"",Q40))),"") | T40: =+IF(O40>0,O40+R40*2,M40+R40*2)+P40*2+Q40*2 | U40: =+IF(O40>0,O40+R40*2,N40+R40*2)+P40*2+Q40*2 | W40: =IF(V40=1,T40+5,T40+(V40*4)) | X40: =IF(V40=1,U40+5,U40+(V40*4)) | Y40: 0 | Z40: =IF(Y40=1,ROUNDUP(W40*(1+VLOOKUP(E40,ARTICULOS!$D$10:$H$699,5)),0),W40) | AA40: =IF(Y40=1,ROUNDUP(X40*(1+VLOOKUP(E40,ARTICULOS!$D$10:$H$699,4)),0),X40) | AB40: 2 | AD40: =IF(AC40=1,J40*100&Z40,"") | AE40: =IF(AC40=1,VLOOKUP(AD40,EMPALME!$C$2:$F$33,4),"") | AG40: =IF(L40=3,IF(V40=1,CONFECCION!$C$18,CONFECCION!$C$18*2),IF(V40=1,HLOOKUP(AA40,CONFECCION!$C$17:$AD$33,VLOOKUP(Z40,CONFECCION!$A$18:$B$33,2)-16),2*HLOOKUP(AA40,CONFECCION!$C$17:$AD$33,VLOOKUP(Z40,CONFECCION!$A$18:$B$33,2)-16)))*IF(AC40=1,3,1) | AI40: =IF(AC40=1,AA40/100*K40+IF(AF40>0,K40*(VLOOKUP(AD40,EMPALME!$C$2:$D$33,2)/100)/AF40,K40*(VLOOKUP(AD40,EMPALME!$C$2:$D$33,2)/100)/VLOOKUP(AD40,EMPALME!$C$2:$F$33,4)),IF(AH40=2,ROUND((K40*(AA40/100)-(I40/10)*INT((AA40/100)/0.55)*INT((J40-(Z40/100)*INT(J40/(Z40/100)))/0.55))/INT(J40/(Z40/100)),2),ROUND(K40*(AA40/100)/INT(J40/(Z40/100)),2))) | AJ40: 2 | AK40: =ROUND(IF(AJ40=2,0,((Z40*2)+(AA40*2))*CONFECCION!$B$35/100),2) | AM40: 2 | AQ40: =IF(S40=0,"",S40) | AR40: =IF(A40=0,"",VLOOKUP(L40,ARTICULOS!$A$10:$B$19,2)) | AS40: =IF(A40=0,"",T40&" * "&U40)&IF(AM40=1," PR","") | AT40: =IF(A40=0,"",VLOOKUP(E40,ARTICULOS!$D$10:$F$699,3)) | AU40: =IF(A40=0,"","c/ "&D40&" "&VLOOKUP(H40,COLORES!$A$7:$G$4394,7)) | AV40: =IF(A40=0,"",IF(V40=1,"Dobl. Sencillo","Dobl. "&V40&" cm.")) | AW40: =+IF(Y40=1,"SI","") | AX40: =IF(A40=0,"",IF(AB40=2,Z40&" * "&AA40,IF(Z40=AA40,"Redondo "&Z40&" * "&AA40,"Ovalado "&Z40&" * "&AA40))) | AY40: =IF(A40=0,"",AG40+AI40+AK40) | AZ40: =IF(A40=0,"",A40) | BA40: =IF(A40=0,"",ROUND(AY40*AZ40,2))
A41: 0 | B41: 1 | D41: 1 | E41: =MATCH(C41,ARTICULOS!$F$10:$F$699,0) | F41: =+VLOOKUP(E41,ARTICULOS!$D$10:$I$699,6) | G41: =+F41&D41 | H41: =+MATCH(G41,COLORES!$E$7:$E$4394,0) | I41: =VLOOKUP(H41,COLORES!$A$7:$I$4394,8) | J41: =VLOOKUP(H41,COLORES!$A$7:$I$4394,9) | K41: =I41*(1+B41) | L41: 0 | M41: 0 | N41: 0 | O41: 0 | P41: 0 | Q41: 0 | S41: =IF(P41>0,IF(O41>0,"(/)"&O41&"*"&P41&IF(Q41>0,"+"&Q41,IF(Q41=0,"",Q41)),+M41&"*"&N41&"*"&P41&IF(Q41>0,"+"&Q41,IF(Q41=0,"",Q41))),"") | T41: =+IF(O41>0,O41+R41*2,M41+R41*2)+P41*2+Q41*2 | U41: =+IF(O41>0,O41+R41*2,N41+R41*2)+P41*2+Q41*2 | W41: =IF(V41=1,T41+5,T41+(V41*4)) | X41: =IF(V41=1,U41+5,U41+(V41*4)) | Y41: 0 | Z41: =IF(Y41=1,ROUNDUP(W41*(1+VLOOKUP(E41,ARTICULOS!$D$10:$H$699,5)),0),W41) | AA41: =IF(Y41=1,ROUNDUP(X41*(1+VLOOKUP(E41,ARTICULOS!$D$10:$H$699,4)),0),X41) | AB41: 2 | AD41: =IF(AC41=1,J41*100&Z41,"") | AE41: =IF(AC41=1,VLOOKUP(AD41,EMPALME!$C$2:$F$33,4),"") | AG41: =IF(L41=3,IF(V41=1,CONFECCION!$C$18,CONFECCION!$C$18*2),IF(V41=1,HLOOKUP(AA41,CONFECCION!$C$17:$AD$33,VLOOKUP(Z41,CONFECCION!$A$18:$B$33,2)-16),2*HLOOKUP(AA41,CONFECCION!$C$17:$AD$33,VLOOKUP(Z41,CONFECCION!$A$18:$B$33,2)-16)))*IF(AC41=1,3,1) | AI41: =IF(AC41=1,AA41/100*K41+IF(AF41>0,K41*(VLOOKUP(AD41,EMPALME!$C$2:$D$33,2)/100)/AF41,K41*(VLOOKUP(AD41,EMPALME!$C$2:$D$33,2)/100)/VLOOKUP(AD41,EMPALME!$C$2:$F$33,4)),IF(AH41=2,ROUND((K41*(AA41/100)-(I41/10)*INT((AA41/100)/0.55)*INT((J41-(Z41/100)*INT(J41/(Z41/100)))/0.55))/INT(J41/(Z41/100)),2),ROUND(K41*(AA41/100)/INT(J41/(Z41/100)),2))) | AJ41: 2 | AK41: =ROUND(IF(AJ41=2,0,((Z41*2)+(AA41*2))*CONFECCION!$B$35/100),2) | AM41: 2 | AQ41: =IF(S41=0,"",S41) | AR41: =IF(A41=0,"",VLOOKUP(L41,ARTICULOS!$A$10:$B$19,2)) | AS41: =IF(A41=0,"",T41&" * "&U41)&IF(AM41=1," PR","") | AT41: =IF(A41=0,"",VLOOKUP(E41,ARTICULOS!$D$10:$F$699,3)) | AU41: =IF(A41=0,"","c/ "&D41&" "&VLOOKUP(H41,COLORES!$A$7:$G$4394,7)) | AV41: =IF(A41=0,"",IF(V41=1,"Dobl. Sencillo","Dobl. "&V41&" cm.")) | AW41: =+IF(Y41=1,"SI","") | AX41: =IF(A41=0,"",IF(AB41=2,Z41&" * "&AA41,IF(Z41=AA41,"Redondo "&Z41&" * "&AA41,"Ovalado "&Z41&" * "&AA41))) | AY41: =IF(A41=0,"",AG41+AI41+AK41) | AZ41: =IF(A41=0,"",A41) | BA41: =IF(A41=0,"",ROUND(AY41*AZ41,2))
A42: 0 | B42: 1 | D42: 1 | E42: =MATCH(C42,ARTICULOS!$F$10:$F$699,0) | F42: =+VLOOKUP(E42,ARTICULOS!$D$10:$I$699,6) | G42: =+F42&D42 | H42: =+MATCH(G42,COLORES!$E$7:$E$4394,0) | I42: =VLOOKUP(H42,COLORES!$A$7:$I$4394,8) | J42: =VLOOKUP(H42,COLORES!$A$7:$I$4394,9) | K42: =I42*(1+B42) | L42: 0 | M42: 0 | N42: 0 | O42: 0 | P42: 0 | Q42: 0 | S42: =IF(P42>0,IF(O42>0,"(/)"&O42&"*"&P42&IF(Q42>0,"+"&Q42,IF(Q42=0,"",Q42)),+M42&"*"&N42&"*"&P42&IF(Q42>0,"+"&Q42,IF(Q42=0,"",Q42))),"") | T42: =+IF(O42>0,O42+R42*2,M42+R42*2)+P42*2+Q42*2 | U42: =+IF(O42>0,O42+R42*2,N42+R42*2)+P42*2+Q42*2 | W42: =IF(V42=1,T42+5,T42+(V42*4)) | X42: =IF(V42=1,U42+5,U42+(V42*4)) | Y42: 0 | Z42: =IF(Y42=1,ROUNDUP(W42*(1+VLOOKUP(E42,ARTICULOS!$D$10:$H$699,5)),0),W42) | AA42: =IF(Y42=1,ROUNDUP(X42*(1+VLOOKUP(E42,ARTICULOS!$D$10:$H$699,4)),0),X42) | AB42: 2 | AD42: =IF(AC42=1,J42*100&Z42,"") | AE42: =IF(AC42=1,VLOOKUP(AD42,EMPALME!$C$2:$F$33,4),"") | AG42: =IF(L42=3,IF(V42=1,CONFECCION!$C$18,CONFECCION!$C$18*2),IF(V42=1,HLOOKUP(AA42,CONFECCION!$C$17:$AD$33,VLOOKUP(Z42,CONFECCION!$A$18:$B$33,2)-16),2*HLOOKUP(AA42,CONFECCION!$C$17:$AD$33,VLOOKUP(Z42,CONFECCION!$A$18:$B$33,2)-16)))*IF(AC42=1,3,1) | AI42: =IF(AC42=1,AA42/100*K42+IF(AF42>0,K42*(VLOOKUP(AD42,EMPALME!$C$2:$D$33,2)/100)/AF42,K42*(VLOOKUP(AD42,EMPALME!$C$2:$D$33,2)/100)/VLOOKUP(AD42,EMPALME!$C$2:$F$33,4)),IF(AH42=2,ROUND((K42*(AA42/100)-(I42/10)*INT((AA42/100)/0.55)*INT((J42-(Z42/100)*INT(J42/(Z42/100)))/0.55))/INT(J42/(Z42/100)),2),ROUND(K42*(AA42/100)/INT(J42/(Z42/100)),2))) | AJ42: 2 | AK42: =ROUND(IF(AJ42=2,0,((Z42*2)+(AA42*2))*CONFECCION!$B$35/100),2) | AM42: 2 | AQ42: =IF(S42=0,"",S42) | AR42: =IF(A42=0,"",VLOOKUP(L42,ARTICULOS!$A$10:$B$19,2)) | AS42: =IF(A42=0,"",T42&" * "&U42)&IF(AM42=1," PR","") | AT42: =IF(A42=0,"",VLOOKUP(E42,ARTICULOS!$D$10:$F$699,3)) | AU42: =IF(A42=0,"","c/ "&D42&" "&VLOOKUP(H42,COLORES!$A$7:$G$4394,7)) | AV42: =IF(A42=0,"",IF(V42=1,"Dobl. Sencillo","Dobl. "&V42&" cm.")) | AW42: =+IF(Y42=1,"SI","") | AX42: =IF(A42=0,"",IF(AB42=2,Z42&" * "&AA42,IF(Z42=AA42,"Redondo "&Z42&" * "&AA42,"Ovalado "&Z42&" * "&AA42))) | AY42: =IF(A42=0,"",AG42+AI42+AK42) | AZ42: =IF(A42=0,"",A42) | BA42: =IF(A42=0,"",ROUND(AY42*AZ42,2))
A43: 0 | B43: 1 | D43: 1 | E43: =MATCH(C43,ARTICULOS!$F$10:$F$699,0) | F43: =+VLOOKUP(E43,ARTICULOS!$D$10:$I$699,6) | G43: =+F43&D43 | H43: =+MATCH(G43,COLORES!$E$7:$E$4394,0) | I43: =VLOOKUP(H43,COLORES!$A$7:$I$4394,8) | J43: =VLOOKUP(H43,COLORES!$A$7:$I$4394,9) | K43: =I43*(1+B43) | L43: 0 | M43: 0 | N43: 0 | O43: 0 | P43: 0 | Q43: 0 | S43: =IF(P43>0,IF(O43>0,"(/)"&O43&"*"&P43&IF(Q43>0,"+"&Q43,IF(Q43=0,"",Q43)),+M43&"*"&N43&"*"&P43&IF(Q43>0,"+"&Q43,IF(Q43=0,"",Q43))),"") | T43: =+IF(O43>0,O43+R43*2,M43+R43*2)+P43*2+Q43*2 | U43: =+IF(O43>0,O43+R43*2,N43+R43*2)+P43*2+Q43*2 | W43: =IF(V43=1,T43+5,T43+(V43*4)) | X43: =IF(V43=1,U43+5,U43+(V43*4)) | Y43: 0 | Z43: =IF(Y43=1,ROUNDUP(W43*(1+VLOOKUP(E43,ARTICULOS!$D$10:$H$699,5)),0),W43) | AA43: =IF(Y43=1,ROUNDUP(X43*(1+VLOOKUP(E43,ARTICULOS!$D$10:$H$699,4)),0),X43) | AB43: 2 | AD43: =IF(AC43=1,J43*100&Z43,"") | AE43: =IF(AC43=1,VLOOKUP(AD43,EMPALME!$C$2:$F$33,4),"") | AG43: =IF(L43=3,IF(V43=1,CONFECCION!$C$18,CONFECCION!$C$18*2),IF(V43=1,HLOOKUP(AA43,CONFECCION!$C$17:$AD$33,VLOOKUP(Z43,CONFECCION!$A$18:$B$33,2)-16),2*HLOOKUP(AA43,CONFECCION!$C$17:$AD$33,VLOOKUP(Z43,CONFECCION!$A$18:$B$33,2)-16)))*IF(AC43=1,3,1) | AI43: =IF(AC43=1,AA43/100*K43+IF(AF43>0,K43*(VLOOKUP(AD43,EMPALME!$C$2:$D$33,2)/100)/AF43,K43*(VLOOKUP(AD43,EMPALME!$C$2:$D$33,2)/100)/VLOOKUP(AD43,EMPALME!$C$2:$F$33,4)),IF(AH43=2,ROUND((K43*(AA43/100)-(I43/10)*INT((AA43/100)/0.55)*INT((J43-(Z43/100)*INT(J43/(Z43/100)))/0.55))/INT(J43/(Z43/100)),2),ROUND(K43*(AA43/100)/INT(J43/(Z43/100)),2))) | AJ43: 2 | AK43: =ROUND(IF(AJ43=2,0,((Z43*2)+(AA43*2))*CONFECCION!$B$35/100),2) | AM43: 2 | AQ43: =IF(S43=0,"",S43) | AR43: =IF(A43=0,"",VLOOKUP(L43,ARTICULOS!$A$10:$B$19,2)) | AS43: =IF(A43=0,"",T43&" * "&U43)&IF(AM43=1," PR","") | AT43: =IF(A43=0,"",VLOOKUP(E43,ARTICULOS!$D$10:$F$699,3)) | AU43: =IF(A43=0,"","c/ "&D43&" "&VLOOKUP(H43,COLORES!$A$7:$G$4394,7)) | AV43: =IF(A43=0,"",IF(V43=1,"Dobl. Sencillo","Dobl. "&V43&" cm.")) | AW43: =+IF(Y43=1,"SI","") | AX43: =IF(A43=0,"",IF(AB43=2,Z43&" * "&AA43,IF(Z43=AA43,"Redondo "&Z43&" * "&AA43,"Ovalado "&Z43&" * "&AA43))) | AY43: =IF(A43=0,"",AG43+AI43+AK43) | AZ43: =IF(A43=0,"",A43) | BA43: =IF(A43=0,"",ROUND(AY43*AZ43,2))
A44: 0 | B44: 1 | D44: 1 | E44: =MATCH(C44,ARTICULOS!$F$10:$F$699,0) | F44: =+VLOOKUP(E44,ARTICULOS!$D$10:$I$699,6) | G44: =+F44&D44 | H44: =+MATCH(G44,COLORES!$E$7:$E$4394,0) | I44: =VLOOKUP(H44,COLORES!$A$7:$I$4394,8) | J44: =VLOOKUP(H44,COLORES!$A$7:$I$4394,9) | K44: =I44*(1+B44) | L44: 0 | M44: 0 | N44: 0 | O44: 0 | P44: 0 | Q44: 0 | S44: =IF(P44>0,IF(O44>0,"(/)"&O44&"*"&P44&IF(Q44>0,"+"&Q44,IF(Q44=0,"",Q44)),+M44&"*"&N44&"*"&P44&IF(Q44>0,"+"&Q44,IF(Q44=0,"",Q44))),"") | T44: =+IF(O44>0,O44+R44*2,M44+R44*2)+P44*2+Q44*2 | U44: =+IF(O44>0,O44+R44*2,N44+R44*2)+P44*2+Q44*2 | W44: =IF(V44=1,T44+5,T44+(V44*4)) | X44: =IF(V44=1,U44+5,U44+(V44*4)) | Y44: 0 | Z44: =IF(Y44=1,ROUNDUP(W44*(1+VLOOKUP(E44,ARTICULOS!$D$10:$H$699,5)),0),W44) | AA44: =IF(Y44=1,ROUNDUP(X44*(1+VLOOKUP(E44,ARTICULOS!$D$10:$H$699,4)),0),X44) | AB44: 2 | AD44: =IF(AC44=1,J44*100&Z44,"") | AE44: =IF(AC44=1,VLOOKUP(AD44,EMPALME!$C$2:$F$33,4),"") | AG44: =IF(L44=3,IF(V44=1,CONFECCION!$C$18,CONFECCION!$C$18*2),IF(V44=1,HLOOKUP(AA44,CONFECCION!$C$17:$AD$33,VLOOKUP(Z44,CONFECCION!$A$18:$B$33,2)-16),2*HLOOKUP(AA44,CONFECCION!$C$17:$AD$33,VLOOKUP(Z44,CONFECCION!$A$18:$B$33,2)-16)))*IF(AC44=1,3,1) | AI44: =IF(AC44=1,AA44/100*K44+IF(AF44>0,K44*(VLOOKUP(AD44,EMPALME!$C$2:$D$33,2)/100)/AF44,K44*(VLOOKUP(AD44,EMPALME!$C$2:$D$33,2)/100)/VLOOKUP(AD44,EMPALME!$C$2:$F$33,4)),IF(AH44=2,ROUND((K44*(AA44/100)-(I44/10)*INT((AA44/100)/0.55)*INT((J44-(Z44/100)*INT(J44/(Z44/100)))/0.55))/INT(J44/(Z44/100)),2),ROUND(K44*(AA44/100)/INT(J44/(Z44/100)),2))) | AJ44: 2 | AK44: =ROUND(IF(AJ44=2,0,((Z44*2)+(AA44*2))*CONFECCION!$B$35/100),2) | AM44: 2 | AQ44: =IF(S44=0,"",S44) | AR44: =IF(A44=0,"",VLOOKUP(L44,ARTICULOS!$A$10:$B$19,2)) | AS44: =IF(A44=0,"",T44&" * "&U44)&IF(AM44=1," PR","") | AT44: =IF(A44=0,"",VLOOKUP(E44,ARTICULOS!$D$10:$F$699,3)) | AU44: =IF(A44=0,"","c/ "&D44&" "&VLOOKUP(H44,COLORES!$A$7:$G$4394,7)) | AV44: =IF(A44=0,"",IF(V44=1,"Dobl. Sencillo","Dobl. "&V44&" cm.")) | AW44: =+IF(Y44=1,"SI","") | AX44: =IF(A44=0,"",IF(AB44=2,Z44&" * "&AA44,IF(Z44=AA44,"Redondo "&Z44&" * "&AA44,"Ovalado "&Z44&" * "&AA44))) | AY44: =IF(A44=0,"",AG44+AI44+AK44) | AZ44: =IF(A44=0,"",A44) | BA44: =IF(A44=0,"",ROUND(AY44*AZ44,2))
A45: 0 | B45: 1 | D45: 1 | E45: =MATCH(C45,ARTICULOS!$F$10:$F$699,0) | F45: =+VLOOKUP(E45,ARTICULOS!$D$10:$I$699,6) | G45: =+F45&D45 | H45: =+MATCH(G45,COLORES!$E$7:$E$4394,0) | I45: =VLOOKUP(H45,COLORES!$A$7:$I$4394,8) | J45: =VLOOKUP(H45,COLORES!$A$7:$I$4394,9) | K45: =I45*(1+B45) | L45: 0 | M45: 0 | N45: 0 | O45: 0 | P45: 0 | Q45: 0 | S45: =IF(P45>0,IF(O45>0,"(/)"&O45&"*"&P45&IF(Q45>0,"+"&Q45,IF(Q45=0,"",Q45)),+M45&"*"&N45&"*"&P45&IF(Q45>0,"+"&Q45,IF(Q45=0,"",Q45))),"") | T45: =+IF(O45>0,O45+R45*2,M45+R45*2)+P45*2+Q45*2 | U45: =+IF(O45>0,O45+R45*2,N45+R45*2)+P45*2+Q45*2 | W45: =IF(V45=1,T45+5,T45+(V45*4)) | X45: =IF(V45=1,U45+5,U45+(V45*4)) | Y45: 0 | Z45: =IF(Y45=1,ROUNDUP(W45*(1+VLOOKUP(E45,ARTICULOS!$D$10:$H$699,5)),0),W45) | AA45: =IF(Y45=1,ROUNDUP(X45*(1+VLOOKUP(E45,ARTICULOS!$D$10:$H$699,4)),0),X45) | AB45: 2 | AD45: =IF(AC45=1,J45*100&Z45,"") | AE45: =IF(AC45=1,VLOOKUP(AD45,EMPALME!$C$2:$F$33,4),"") | AG45: =IF(L45=3,IF(V45=1,CONFECCION!$C$18,CONFECCION!$C$18*2),IF(V45=1,HLOOKUP(AA45,CONFECCION!$C$17:$AD$33,VLOOKUP(Z45,CONFECCION!$A$18:$B$33,2)-16),2*HLOOKUP(AA45,CONFECCION!$C$17:$AD$33,VLOOKUP(Z45,CONFECCION!$A$18:$B$33,2)-16)))*IF(AC45=1,3,1) | AI45: =IF(AC45=1,AA45/100*K45+IF(AF45>0,K45*(VLOOKUP(AD45,EMPALME!$C$2:$D$33,2)/100)/AF45,K45*(VLOOKUP(AD45,EMPALME!$C$2:$D$33,2)/100)/VLOOKUP(AD45,EMPALME!$C$2:$F$33,4)),IF(AH45=2,ROUND((K45*(AA45/100)-(I45/10)*INT((AA45/100)/0.55)*INT((J45-(Z45/100)*INT(J45/(Z45/100)))/0.55))/INT(J45/(Z45/100)),2),ROUND(K45*(AA45/100)/INT(J45/(Z45/100)),2))) | AJ45: 2 | AK45: =ROUND(IF(AJ45=2,0,((Z45*2)+(AA45*2))*CONFECCION!$B$35/100),2) | AM45: 2 | AQ45: =IF(S45=0,"",S45) | AR45: =IF(A45=0,"",VLOOKUP(L45,ARTICULOS!$A$10:$B$19,2)) | AS45: =IF(A45=0,"",T45&" * "&U45)&IF(AM45=1," PR","") | AT45: =IF(A45=0,"",VLOOKUP(E45,ARTICULOS!$D$10:$F$699,3)) | AU45: =IF(A45=0,"","c/ "&D45&" "&VLOOKUP(H45,COLORES!$A$7:$G$4394,7)) | AV45: =IF(A45=0,"",IF(V45=1,"Dobl. Sencillo","Dobl. "&V45&" cm.")) | AW45: =+IF(Y45=1,"SI","") | AX45: =IF(A45=0,"",IF(AB45=2,Z45&" * "&AA45,IF(Z45=AA45,"Redondo "&Z45&" * "&AA45,"Ovalado "&Z45&" * "&AA45))) | AY45: =IF(A45=0,"",AG45+AI45+AK45) | AZ45: =IF(A45=0,"",A45) | BA45: =IF(A45=0,"",ROUND(AY45*AZ45,2))
